Workbook

Sheet HELIAN
C2: LENNOX
B6: REPORTE DE PIEZAS MAQUINAS INTEGRADORAS (HELIAN)
B8: CLIENTE | C8: DESTINO | D8: NÚMERO DE PARTE | E8: DIAMETRO | F8: CANTIDAD | I8: CLIENTE | J8: DESTINO | K8: NÚMERO DE PARTE | L8: DIAMETRO | M8: CANTIDAD
B9: LENNOX 1 | C9: SAIRA MORALES | D9: 625994-01 | E9: A - 3/8 | I9: LENNOX 1 | J9: SAIRA MORALES | K9: 626962-01 | L9: C - 3/4
B10: LENNOX 1 | C10: SAIRA MORALES | D10: 627512-01 | E10: A - 3/8 | I10: LENNOX 1 | J10: SAIRA MORALES | K10: 619770-01 | L10: C - 3/4
B11: LENNOX 1 | C11: SAIRA MORALES | D11: 625967-01 | E11: A - 3/8 | I11: LENNOX 1 | J11: SAIRA MORALES | K11: 618685-01 | L11: C - 3/4
B12: LENNOX 1 | C12: SAIRA MORALES | D12: 626309-01 | E12: A - 3/8 | I12: LENNOX 1 | J12: SAIRA MORALES | K12: 627106-01 | L12: C - 3/4
B13: LENNOX 1 | C13: SAIRA MORALES | D13: 625890-01 | E13: A - 3/8 | I13: LENNOX 1 | J13: SAIRA MORALES | K13: 626967-01 | L13: C - 3/4
B14: LENNOX 1 | C14: SAIRA MORALES | D14: 615991-01 | E14: A - 3/8 | I14: LENNOX 1 | J14: SAIRA MORALES | K14: 618927-01 | L14: C - 7/8
B15: LENNOX 1 | C15: SAIRA MORALES | D15: 626164-01 | E15: A - 3/8 | I15: LENNOX 1 | J15: SAIRA MORALES | K15: 624302-01 | L15: C - 7/8
I16: LENNOX 1 | J16: SAIRA MORALES | K16: 626978-01 | L16: C - 7/8
B17: LENNOX 1 | C17: SAIRA MORALES | D17: 626121-01 | E17: C - 3/8 | I17: LENNOX 1 | J17: SAIRA MORALES | K17: 618887-01 | L17: C - 7/8
B18: LENNOX 1 | C18: SAIRA MORALES | D18: 625995-01 | E18: C - 3/8 | I18: LENNOX 1 | J18: SAIRA MORALES | K18: 626998-01 | L18: C - 7/8
B19: LENNOX 1 | C19: SAIRA MORALES | D19: 615380-01 | E19: C - 3/8
B20: LENNOX 1 | C20: SAIRA MORALES | D20: 625922-01 | E20: C - 3/8 | I20: LENNOX 1 | J20: SAIRA MORALES | K20: 614166-01 | L20: SOLDADURA 3/4
B21: LENNOX 1 | C21: SAIRA MORALES | D21: 627511-01 | E21: C - 3/8 | I21: LENNOX 1 | J21: SAIRA MORALES | K21: 626798-01 | L21: SOLDADURA 3/4
B22: LENNOX 1 | C22: SAIRA MORALES | D22: 626308-01 | E22: C - 3/8 | I22: LENNOX 1 | J22: SAIRA MORALES | K22: 626430-01 | L22: SOLDADURA 3/4
I23: LENNOX 1 | J23: SAIRA MORALES | K23: 626581-01 | L23: SOLDADURA 3/4
B24: LENNOX 1 | C24: SAIRA MORALES | D24: 626467-01 | E24: C - 1/2 | I24: LENNOX 1 | J24: SAIRA MORALES | K24: 626798-02 | L24: SOLDADURA 3/4
B25: LENNOX 1 | C25: SAIRA MORALES | D25: 626473-01 | E25: C - 1/2 | I25: LENNOX 1 | J25: SAIRA MORALES | K25: 626581-04 | L25: SOLDADURA 3/4
B26: LENNOX 1 | C26: SAIRA MORALES | D26: 627051-01 | E26: C - 1/2 | I26: LENNOX 1 | J26: SAIRA MORALES | K26: 101777-01 | L26: SOLDADURA 3/4
B27: LENNOX 1 | C27: SAIRA MORALES | D27: 627186-01 | E27: C - 1/2 | I27: LENNOX 1 | J27: SAIRA MORALES | K27: 626581-02 | L27: SOLDADURA 3/4
B28: LENNOX 1 | C28: SAIRA MORALES | D28: 627041-01 | E28: C - 1/2 | I28: LENNOX 1 | J28: SAIRA MORALES | K28: 613781-01 | L28: SOLDADURA 3/4
B29: LENNOX 1 | C29: SAIRA MORALES | D29: 625151-01 | E29: C - 1/2 | I29: LENNOX 1 | J29: SAIRA MORALES | K29: 626798-03 | L29: SOLDADURA 3/4
B30: LENNOX 1 | C30: SAIRA MORALES | D30: 626794-01 | E30: C - 1/2 | I30: LENNOX 1 | J30: SAIRA MORALES | K30: 626581-05 | L30: SOLDADURA 7/8
B31: LENNOX 1 | C31: SAIRA MORALES | D31: 618748-01 | E31: C - 1/2 | I31: LENNOX 1 | J31: SAIRA MORALES | K31: 606820-03 | L31: SOLDADURA 7/8
B32: LENNOX 1 | C32: SAIRA MORALES | D32: 626532-01 | E32: C - 1/2 | I32: LENNOX 1 | J32: SAIRA MORALES | K32: 626432-01 | L32: SOLDADURA 7/8
B33: LENNOX 1 | C33: SAIRA MORALES | D33: 626391-01 | E33: C - 1/2 | I33: LENNOX 1 | J33: SAIRA MORALES | K33: 626581-08 | L33: SOLDADURA 7/8
B34: LENNOX 1 | C34: SAIRA MORALES | D34: 613544-01 | E34: C - 1/2 | I34: LENNOX 1 | J34: SAIRA MORALES | K34: 626581-11 | L34: SOLDADURA 7/8
B35: LENNOX 1 | C35: SAIRA MORALES | D35: 627101-01 | E35: C - 1/2 | I35: LENNOX 1 | J35: SAIRA MORALES | K35: 626434-01 | L35: SOLDADURA 7/8
... B39: LENNOX 1 | C39: SAIRA MORALES | D39: 627046-01 | E39: C - 1/2 | I39: LENNOX 1 | J39: SAIRA MORALES | K39: 626429-01 | L39: SOLDADURA 7/8
B40: LENNOX 1 | C40: SAIRA MORALES | D40: MXLB-112323 | E40: C - 1/2
B41: LENNOX 1 | C41: SAIRA MORALES | D41: 626471-01 | E41: C - 1/2
B42: LENNOX 1 | C42: SAIRA MORALES | D42: 626472-01 | E42: C - 1/2
B43: LENNOX 1 | C43: SAIRA MORALES | D43: 626433-01 | E43: C - 1/2
B44: LENNOX 1 | C44: SAIRA MORALES | D44: 627175-01 | E44: C - 1/2
B45: LENNOX 1 | C45: SAIRA MORALES | D45: 627021-01 | E45: C - 1/2
B46: LENNOX 1 | C46: SAIRA MORALES | D46: 613366-01 | E46: C - 1/2
B47: LENNOX 1 | C47: SAIRA MORALES | D47: 613569-01 | E47: C - 1/2
B48: LENNOX 1 | C48: SAIRA MORALES | D48: 626310-01 | E48: C - 1/2
...

Sheet SEMANA 29,30
B2: DÍA | C2: TURNO
B3: =TODAY() -> 46309 | C3: A | D3: X | H3: PROGRAMA
C4: B | H4: SEMANA | O4: 46209 | Q4: 46210 | S4: 46211 | U4: 46212 | W4: 46213 | Y4: 46216 | AA4: 46217 | AC4: 46218 | AE4: 46219 | AG4: 46220 | AI4: Ag1
B5: CLIENTE | C5: DESTINO | D5: NÚMERO DE PARTE | E5: DIAMETRO | F5: PARED | G5: PESO | H5: 29,30 | I5: S30 | J5: Ag2 | K5: Ag3 | L5: Ag4 | M5: Ag5 | N5: BALANCE | O5: A | P5: B | Q5: A | R5: B | S5: A | T5: B | U5: A | V5: B | W5: A | X5: B | Y5: A | Z5: B | AA5: A | AB5: B | AC5: A | AD5: B | AE5: A | AF5: B | AG5: A | AH5: B | AI5: AYB | AJ5: KG | AK5: STD. | AL5: SWITCH | AM5: SWITCH | AN5: BRACKET | AO5: BRACKET | AP5: PIJA | AQ5: VALVULA | AR5: CANT. VAL. | AS5: CAJA | AT5: HOJA COLOR | AV5: Row Labels | AW5: Sum of CANT. VAL.
B6: LENNOX 1 | C6: SAIRA MORALES | D6: 625994-01 | E6: A - 3/8 | F6: 0.42 | G6: 0.02 | H6: =VLOOKUP(D6,'[1]LENNOX WK 29'!$A$3:$E$76,5,0) -> 1300 | I6: 0 | J6: 0 | L6: =600+5000 -> 5600 | N6: =+H6+I6+J6+K6+L6+M6-SUM(O6:AI6) -> 5600 | O6: 0 | P6: 0 | Q6: 0 | R6: 0 | S6: 0 | T6: 0 | U6: 0 | V6: 0 | W6: 0 | X6: 0 | Y6: 0 | Z6: 1300 | AI6: 0 | AJ6: =+G6*SUM(H6:M6) -> 138 | AK6: 1000 | AL6: 0 | AM6: =+H6*AL6 -> 0 | AN6: 0 | AO6: =+H6*AN6 -> 0 | AP6: =+AO6*2 -> 0 | AQ6: 0 | AR6: 0 | AS6: CTD T.MÉXICO | AT6: BLANCO | AV6: 0 | AW6: 0
B7: LENNOX 1 | C7: SAIRA MORALES | D7: 627512-01 | E7: A - 3/8 | F7: 0.42 | G7: 0.031 | H7: =VLOOKUP(D7,'[1]LENNOX WK 29'!$A$3:$E$76,5,0) -> 5600 | I7: 0 | J7: 0 | L7: =2500+4000 -> 6500 | N7: =+H7+I7+J7+K7+L7+M7-SUM(O7:AI7) -> 4338 | O7: 0 | P7: 1200 | Q7: 0 | R7: 1630 | S7: 0 | T7: 650 | U7: 0 | V7: 0 | W7: 0 | X7: 0 | Y7: 0 | Z7: 0 | AB7: 1200 | AD7: 1600 | AF7: 1482 | AI7: 0 | AJ7: =+G7*SUM(H7:M7) -> 375.1 | AK7: 1000 | AL7: 0 | AM7: =+H7*AL7 -> 0 | AN7: 0 | AO7: =+H7*AN7 -> 0 | AP7: =+AO7*2 -> 0 | AQ7: 0 | AR7: 0 | AS7: CTD T.MÉXICO | AT7: BLANCO | AV7: 102831-10 | AW7: 128
B8: LENNOX 1 | C8: SAIRA MORALES | D8: 625967-01 | E8: A - 3/8 | F8: 0.42 | G8: 0.033 | H8: =VLOOKUP(D8,'[1]LENNOX WK 29'!$A$3:$E$76,5,0) -> 1200 | I8: 0 | J8: 0 | L8: =500+1200 -> 1700 | N8: =+H8+I8+J8+K8+L8+M8-SUM(O8:AI8) -> 1300 | O8: 0 | P8: 0 | Q8: 0 | R8: 0 | S8: 0 | T8: 400 | U8: 0 | V8: 800 | W8: 0 | X8: 0 | Y8: 0 | Z8: 0 | AF8: 400 | AI8: 0 | AJ8: =+G8*SUM(H8:M8) -> 95.7 | AK8: 1000 | AL8: 0 | AM8: =+H8*AL8 -> 0 | AN8: 0 | AO8: =+H8*AN8 -> 0 | AP8: =+AO8*2 -> 0 | AQ8: 0 | AR8: 0 | AS8: CTD T.MÉXICO | AT8: BLANCO | AV8: 102831-11 | AW8: 0
B9: LENNOX 1 | C9: SAIRA MORALES | D9: 626309-01 | E9: A - 3/8 | F9: 0.42 | G9: 0.019 | H9: =VLOOKUP(D9,'[1]LENNOX WK 29'!$A$3:$E$76,5,0) -> 1400 | I9: 0 | J9: 0 | L9: 0 | N9: =+H9+I9+J9+K9+L9+M9-SUM(O9:AI9) -> 0 | O9: 0 | P9: 0 | Q9: 0 | R9: 0 | S9: 0 | T9: 0 | U9: 0 | V9: 0 | W9: 0 | X9: 0 | Y9: 0 | Z9: 0 | AB9: 800 | AD9: 600 | AI9: 0 | AJ9: =+G9*SUM(H9:M9) -> 26.6 | AK9: 1000 | AL9: 0 | AM9: =+H9*AL9 -> 0 | AN9: 0 | AO9: =+H9*AN9 -> 0 | AP9: =+AO9*2 -> 0 | AQ9: 0 | AR9: 0 | AS9: CTD T.MÉXICO | AT9: BLANCO | AV9: 103881-02 | AW9: 864
B10: LENNOX 1 | C10: SAIRA MORALES | D10: 625890-01 | E10: A - 3/8 | F10: 0.42 | G10: 0.03 | H10: =VLOOKUP(D10,'[1]LENNOX WK 29'!$A$3:$E$76,5,0) -> 200 | I10: 0 | J10: 0 | L10: 1000 | N10: =+H10+I10+J10+K10+L10+M10-SUM(O10:AI10) -> 1000 | O10: 0 | P10: 0 | Q10: 0 | R10: 0 | S10: 0 | T10: 0 | U10: 0 | V10: 0 | W10: 0 | X10: 0 | Y10: 0 | Z10: 0 | AD10: 200 | AI10: 0 | AJ10: =+G10*SUM(H10:M10) -> 36 | AK10: 1000 | AL10: 0 | AM10: =+H10*AL10 -> 0 | AN10: 0 | AO10: =+H10*AN10 -> 0 | AP10: =+AO10*2 -> 0 | AQ10: 0 | AR10: 0 | AS10: CTD T.MÉXICO | AT10: BLANCO | AV10: 103881-03 | AW10: 0
B11: LENNOX 1 | C11: SAIRA MORALES | D11: 615991-01 | E11: A - 3/8 | F11: 0.42 | G11: 0.022 | H11: =VLOOKUP(D11,'[1]LENNOX WK 29'!$A$3:$E$76,5,0) -> 600 | I11: 0 | J11: 0 | L11: 2000 | N11: =+H11+I11+J11+K11+L11+M11-SUM(O11:AI11) -> 1707 | O11: 0 | P11: 0 | Q11: 0 | R11: 0 | S11: 0 | T11: 0 | U11: 0 | V11: 0 | W11: 0 | X11: 0 | Y11: 0 | Z11: 600 | AF11: 293 | AI11: 0 | AJ11: =+G11*SUM(H11:M11) -> 57.2 | AK11: 1000 | AL11: 0 | AM11: =+H11*AL11 -> 0 | AN11: 0 | AO11: =+H11*AN11 -> 0 | AP11: =+AO11*2 -> 0 | AQ11: 0 | AR11: 0 | AS11: CTD T.MÉXICO | AT11: BLANCO | AV11: 107892-03 | AW11: 7704
B12: LENNOX 1 | C12: SAIRA MORALES | D12: 626164-01 | E12: A - 3/8 | F12: 0.42 | G12: 0.023 | H12: =VLOOKUP(D12,'[1]LENNOX WK 29'!$A$3:$E$76,5,0) -> 0 | I12: 0 | J12: 0 | L12: 0 | N12: =+H12+I12+J12+K12+L12+M12-SUM(O12:AI12) -> 0 | O12: 0 | P12: 0 | Q12: 0 | R12: 0 | S12: 0 | T12: 0 | U12: 0 | V12: 0 | W12: 0 | X12: 0 | Y12: 0 | Z12: 0 | AI12: 0 | AJ12: =+G12*SUM(H12:M12) -> 0 | AK12: 1000 | AL12: 0 | AM12: =+H12*AL12 -> 0 | AN12: 0 | AO12: =+H12*AN12 -> 0 | AP12: =+AO12*2 -> 0 | AQ12: 0 | AR12: 0 | AS12: CTD T.MÉXICO | AT12: BLANCO | AV12: 107892-04 | AW12: 3840
B13: LENNOX 1 | C13: SAIRA MORALES | D13: 626121-01 | E13: C - 3/8 | F13: 0.028 | G13: 0.057 | H13: =VLOOKUP(D13,'[1]LENNOX WK 29'!$A$3:$E$76,5,0) -> 0 | I13: 0 | J13: 0 | L13: 0 | N13: =+H13+I13+J13+K13+L13+M13-SUM(O13:AI13) -> -3900 | O13: 0 | P13: 1200 | Q13: 0 | R13: 0 | S13: 0 | T13: 0 | U13: 0 | V13: 900 | W13: 700 | X13: 700 | Y13: 400 | Z13: 0 | AI13: 0 | AJ13: =+G13*SUM(H13:M13) -> 0 | AK13: 1000 | AL13: 0 | AM13: =+H13*AL13 -> 0 | AN13: 0 | AO13: =+H13*AN13 -> 0 | AP13: =+AO13*2 -> 0 | AQ13: 0 | AR13: 0 | AS13: CTD T.MÉXICO | AT13: BLANCO | AV13: 107905-06 | AW13: 1280
B14: LENNOX 1 | C14: SAIRA MORALES | D14: 625995-01 | E14: C - 3/8 | F14: 0.028 | G14: 0.044 | H14: =VLOOKUP(D14,'[1]LENNOX WK 29'!$A$3:$E$76,5,0) -> 0 | I14: 600 | J14: 0 | L14: 1500 | N14: =+H14+I14+J14+K14+L14+M14-SUM(O14:AI14) -> -2966 | O14: 1200 | P14: 0 | Q14: 566 | R14: 0 | S14: 0 | T14: 700 | U14: 600 | V14: 0 | W14: 500 | X14: 0 | Y14: 0 | Z14: 0 | AG14: 1500 | AI14: 0 | AJ14: =+G14*SUM(H14:M14) -> 92.4 | AK14: 1000 | AL14: 0 | AM14: =+H14*AL14 -> 0 | AN14: 0 | AO14: =+H14*AN14 -> 0 | AP14: =+AO14*2 -> 0 | AQ14: 0 | AR14: 0 | AS14: CTD T.MÉXICO | AT14: BLANCO | AV14: 107905-07 | AW14: 384
B15: LENNOX 1 | C15: SAIRA MORALES | D15: 615380-01 | E15: C - 3/8 | F15: 0.028 | G15: 0.015 | H15: =VLOOKUP(D15,'[1]LENNOX WK 29'!$A$3:$E$76,5,0) -> 1300 | I15: 0 | J15: 0 | L15: 4000 | N15: =+H15+I15+J15+K15+L15+M15-SUM(O15:AI15) -> 2400 | O15: 0 | P15: 0 | Q15: 1300 | R15: 0 | S15: 0 | T15: 400 | U15: 0 | V15: 0 | W15: 0 | X15: 0 | Y15: 0 | Z15: 0 | AH15: 1200 | AI15: 0 | AJ15: =+G15*SUM(H15:M15) -> 79.5 | AK15: 1000 | AL15: 0 | AM15: =+H15*AL15 -> 0 | AN15: 0 | AO15: =+H15*AN15 -> 0 | AP15: =+AO15*2 -> 0 | AQ15: 0 | AR15: 0 | AS15: CTD T.MÉXICO | AT15: BLANCO | AV15: Grand Total | AW15: 14200
B16: LENNOX 1 | C16: SAIRA MORALES | D16: 625922-01 | E16: C - 3/8 | F16: 0.028 | G16: 0.019 | H16: =VLOOKUP(D16,'[1]LENNOX WK 29'!$A$3:$E$76,5,0) -> 700 | I16: 300 | J16: 0 | L16: 400 | N16: =+H16+I16+J16+K16+L16+M16-SUM(O16:AI16) -> 400 | O16: 0 | P16: 0 | Q16: 0 | R16: 0 | S16: 700 | T16: 0 | U16: 300 | V16: 0 | W16: 0 | X16: 0 | Y16: 0 | Z16: 0 | AI16: 0 | AJ16: =+G16*SUM(H16:M16) -> 26.6 | AK16: 1000 | AL16: 0 | AM16: =+H16*AL16 -> 0 | AN16: 0 | AO16: =+H16*AN16 -> 0 | AP16: =+AO16*2 -> 0 | AQ16: 0 | AR16: 0 | AS16: CTD T.MÉXICO | AT16: BLANCO
B17: LENNOX 1 | C17: SAIRA MORALES | D17: 627511-01 | E17: C - 3/8 | F17: 0.028 | G17: 0.024 | H17: =VLOOKUP(D17,'[1]LENNOX WK 29'!$A$3:$E$76,5,0) -> 700 | I17: 700 | J17: 4500 | L17: 5000 | N17: =+H17+I17+J17+K17+L17+M17-SUM(O17:AI17) -> 3600 | O17: 0 | P17: 0 | Q17: 0 | R17: 700 | S17: 800 | T17: 0 | U17: 700 | V17: 0 | W17: 300 | X17: 0 | Y17: 0 | Z17: 0 | AC17: 1100 | AD17: 700 | AE17: 1600 | AF17: 1400 | AI17: 0 | AJ17: =+G17*SUM(H17:M17) -> 261.6 | AK17: 1000 | AL17: 0 | AM17: =+H17*AL17 -> 0 | AN17: 0 | AO17: =+H17*AN17 -> 0 | AP17: =+AO17*2 -> 0 | AQ17: 0 | AR17: 0 | AS17: CTD T.MÉXICO | AT17: BLANCO
B18: LENNOX 1 | C18: SAIRA MORALES | D18: 626308-01 | E18: C - 3/8 | F18: 0.028 | G18: 0.019 | H18: =VLOOKUP(D18,'[1]LENNOX WK 29'!$A$3:$E$76,5,0) -> 0 | I18: 0 | J18: 0 | L18: 0 | N18: =+H18+I18+J18+K18+L18+M18-SUM(O18:AI18) -> 0 | O18: 0 | P18: 0 | Q18: 0 | R18: 0 | S18: 0 | T18: 0 | U18: 0 | V18: 0 | W18: 0 | X18: 0 | Y18: 0 | Z18: 0 | AI18: 0 | AJ18: =+G18*SUM(H18:M18) -> 0 | AK18: 1000 | AL18: 0 | AM18: =+H18*AL18 -> 0 | AN18: 0 | AO18: =+H18*AN18 -> 0 | AP18: =+AO18*2 -> 0 | AQ18: 0 | AR18: 0 | AS18: CTD T.MÉXICO | AT18: BLANCO
B19: LENNOX 1 | C19: SAIRA MORALES | D19: 626467-01 | E19: C - 1/2 | F19: 0.028 | G19: 0.086 | H19: =VLOOKUP(D19,'[1]LENNOX WK 29'!$A$3:$E$76,5,0) -> 100 | I19: 0 | J19: 500 | L19: 0 | N19: =+H19+I19+J19+K19+L19+M19-SUM(O19:AI19) -> -55 | O19: 0 | P19: 0 | Q19: 0 | R19: 0 | S19: 0 | T19: 100 | U19: 0 | V19: 0 | W19: 0 | X19: 0 | Y19: 0 | Z19: 0 | AE19: 555 | AI19: 0 | AJ19: =+G19*SUM(H19:M19) -> 51.6 | AK19: 100 | AL19: 0 | AM19: =+H19*AL19 -> 0 | AN19: 0 | AO19: =+H19*AN19 -> 0 | AP19: =+AO19*2 -> 0 | AQ19: 0 | AR19: 0 | AS19: CTD T.MÉXICO | AT19: BLANCO
B20: LENNOX 1 | C20: SAIRA MORALES | D20: 626473-01 | E20: C - 1/2 | F20: 0.028 | G20: 0.117 | H20: =VLOOKUP(D20,'[1]LENNOX WK 29'!$A$3:$E$76,5,0) -> 0 | I20: 0 | J20: 0 | L20: 0 | N20: =+H20+I20+J20+K20+L20+M20-SUM(O20:AI20) -> 0 | O20: 0 | P20: 0 | Q20: 0 | R20: 0 | S20: 0 | T20: 0 | U20: 0 | V20: 0 | W20: 0 | X20: 0 | Y20: 0 | Z20: 0 | AI20: 0 | AJ20: =+G20*SUM(H20:M20) -> 0 | AK20: 100 | AL20: 0 | AM20: =+H20*AL20 -> 0 | AN20: 0 | AO20: =+H20*AN20 -> 0 | AP20: =+AO20*2 -> 0 | AQ20: 0 | AR20: 0 | AS20: CTD T.MÉXICO | AT20: BLANCO
B21: LENNOX 1 | C21: SAIRA MORALES | D21: 627051-01 | E21: C - 1/2 | F21: 0.028 | G21: 0.129 | H21: =VLOOKUP(D21,'[1]LENNOX WK 29'!$A$3:$E$76,5,0) -> 0 | I21: 300 | J21: 100 | L21: 300 | N21: =+H21+I21+J21+K21+L21+M21-SUM(O21:AI21) -> -25 | O21: 0 | P21: 0 | Q21: 0 | R21: 0 | S21: 0 | T21: 0 | U21: 0 | V21: 0 | W21: 0 | X21: 0 | Y21: 250 | Z21: 0 | AC21: 100 | AG21: 375 | AI21: 0 | AJ21: =+G21*SUM(H21:M21) -> 90.3 | AK21: 100 | AL21: 0 | AM21: =+H21*AL21 -> 0 | AN21: 0 | AO21: =+H21*AN21 -> 0 | AP21: =+AO21*2 -> 0 | AQ21: 0 | AR21: 0 | AS21: CTD T.MÉXICO | AT21: BLANCO
B22: LENNOX 1 | C22: SAIRA MORALES | D22: 627186-01 | E22: C - 1/2 | F22: 0.028 | G22: 0.119 | H22: =VLOOKUP(D22,'[1]LENNOX WK 29'!$A$3:$E$76,5,0) -> 0 | I22: 0 | J22: 0 | L22: 0 | N22: =+H22+I22+J22+K22+L22+M22-SUM(O22:AI22) -> -250 | O22: 0 | P22: 0 | Q22: 0 | R22: 0 | S22: 0 | T22: 0 | U22: 250 | V22: 0 | W22: 0 | X22: 0 | Y22: 0 | Z22: 0 | AI22: 0 | AJ22: =+G22*SUM(H22:M22) -> 0 | AK22: 100 | AL22: 0 | AM22: =+H22*AL22 -> 0 | AN22: 0 | AO22: =+H22*AN22 -> 0 | AP22: =+AO22*2 -> 0 | AQ22: 0 | AR22: 0 | AS22: CTD T.MÉXICO | AT22: BLANCO
B23: LENNOX 1 | C23: SAIRA MORALES | D23: 627041-01 | E23: C - 1/2 | F23: 0.028 | G23: 0.127 | H23: =VLOOKUP(D23,'[1]LENNOX WK 29'!$A$3:$E$76,5,0) -> 0 | I23: 0 | J23: 0 | L23: 900 | N23: =+H23+I23+J23+K23+L23+M23-SUM(O23:AI23) -> 0 | O23: 0 | P23: 0 | Q23: 0 | R23: 0 | S23: 0 | T23: 0 | U23: 0 | V23: 0 | W23: 0 | X23: 0 | Y23: 0 | Z23: 0 | AG23: 900 | AI23: 0 | AJ23: =+G23*SUM(H23:M23) -> 114.3 | AK23: 100 | AL23: 0 | AM23: =+H23*AL23 -> 0 | AN23: 0 | AO23: =+H23*AN23 -> 0 | AP23: =+AO23*2 -> 0 | AQ23: 0 | AR23: 0 | AS23: CTD T.MÉXICO | AT23: BLANCO
B24: LENNOX 1 | C24: SAIRA MORALES | D24: 625151-01 | E24: C - 1/2 | F24: 0.028 | G24: 0.114 | H24: =VLOOKUP(D24,'[1]LENNOX WK 29'!$A$3:$E$76,5,0) -> 0 | I24: 1000 | J24: 0 | L24: 0 | N24: =+H24+I24+J24+K24+L24+M24-SUM(O24:AI24) -> -55 | O24: 0 | P24: 0 | Q24: 0 | R24: 0 | S24: 0 | T24: 0 | U24: 315 | V24: 0 | W24: 640 | X24: 0 | Y24: 100 | Z24: 0 | AI24: 0 | AJ24: =+G24*SUM(H24:M24) -> 114 | AK24: 100 | AL24: 0 | AM24: =+H24*AL24 -> 0 | AN24: 0 | AO24: =+H24*AN24 -> 0 | AP24: =+AO24*2 -> 0 | AQ24: 0 | AR24: 0 | AS24: CTD T.MÉXICO | AT24: BLANCO
B25: LENNOX 1 | C25: SAIRA MORALES | D25: 626794-01 | E25: C - 1/2 | F25: 0.028 | G25: 0.069 | H25: =VLOOKUP(D25,'[1]LENNOX WK 29'!$A$3:$E$76,5,0) -> 0 | I25: 300 | J25: 0 | L25: 600 | N25: =+H25+I25+J25+K25+L25+M25-SUM(O25:AI25) -> -50 | O25: 0 | P25: 0 | Q25: 0 | R25: 0 | S25: 0 | T25: 0 | U25: 0 | V25: 0 | W25: 0 | X25: 350 | Y25: 0 | Z25: 0 | AH25: 600 | AI25: 0 | AJ25: =+G25*SUM(H25:M25) -> 62.1 | AK25: 100 | AL25: 0 | AM25: =+H25*AL25 -> 0 | AN25: 0 | AO25: =+H25*AN25 -> 0 | AP25: =+AO25*2 -> 0 | AQ25: 0 | AR25: 0 | AS25: CTD T.MÉXICO | AT25: BLANCO
B26: LENNOX 1 | C26: SAIRA MORALES | D26: 618748-01 | E26: C - 1/2 | F26: 0.028 | G26: 0.129 | H26: =VLOOKUP(D26,'[1]LENNOX WK 29'!$A$3:$E$76,5,0) -> 0 | I26: 0 | J26: 0 | L26: 0 | N26: =+H26+I26+J26+K26+L26+M26-SUM(O26:AI26) -> 0 | O26: 0 | P26: 0 | Q26: 0 | R26: 0 | S26: 0 | T26: 0 | U26: 0 | V26: 0 | W26: 0 | X26: 0 | Y26: 0 | Z26: 0 | AI26: 0 | AJ26: =+G26*SUM(H26:M26) -> 0 | AK26: 100 | AL26: 0 | AM26: =+H26*AL26 -> 0 | AN26: 0 | AO26: =+H26*AN26 -> 0 | AP26: =+AO26*2 -> 0 | AQ26: 0 | AR26: 0 | AS26: CTD T.MÉXICO | AT26: BLANCO
B27: LENNOX 1 | C27: SAIRA MORALES | D27: 626532-01 | E27: C - 1/2 | F27: 0.028 | G27: 0.078 | H27: =VLOOKUP(D27,'[1]LENNOX WK 29'!$A$3:$E$76,5,0) -> 200 | I27: 900 | J27: 200 | L27: 800 | N27: =+H27+I27+J27+K27+L27+M27-SUM(O27:AI27) -> 307 | O27: 0 | P27: 0 | Q27: 226 | R27: 0 | S27: 0 | T27: 0 | U27: 0 | V27: 580 | W27: 294 | X27: 0 | Y27: 0 | Z27: 0 | AE27: 209 | AH27: 484 | AI27: 0 | AJ27: =+G27*SUM(H27:M27) -> 163.8 | AK27: 100 | AL27: 0 | AM27: =+H27*AL27 -> 0 | AN27: 0 | AO27: =+H27*AN27 -> 0 | AP27: =+AO27*2 -> 0 | AQ27: 0 | AR27: 0 | AS27: CTD T.MÉXICO | AT27: BLANCO
B28: LENNOX 1 | C28: SAIRA MORALES | D28: 626391-01 | E28: C - 1/2 | F28: 0.028 | G28: 0.101 | H28: =VLOOKUP(D28,'[1]LENNOX WK 29'!$A$3:$E$76,5,0) -> 600 | I28: 1100 | J28: 200 | L28: 0 | N28: =+H28+I28+J28+K28+L28+M28-SUM(O28:AI28) -> -77 | O28: 0 | P28: 0 | Q28: 300 | R28: 320 | S28: 0 | T28: 634 | U28: 523 | V28: 0 | W28: 0 | X28: 0 | Y28: 0 | Z28: 0 | AC28: 200 | AI28: 0 | AJ28: =+G28*SUM(H28:M28) -> 191.9 | AK28: 100 | AL28: 0 | AM28: =+H28*AL28 -> 0 | AN28: 0 | AO28: =+H28*AN28 -> 0 | AP28: =+AO28*2 -> 0 | AQ28: 0 | AR28: 0 | AS28: CTD T.MÉXICO | AT28: BLANCO
B29: LENNOX 1 | C29: SAIRA MORALES | D29: 613544-01 | E29: C - 1/2 | F29: 0.028 | G29: 0.076 | H29: =VLOOKUP(D29,'[1]LENNOX WK 29'!$A$3:$E$76,5,0) -> 500 | I29: 0 | J29: 200 | L29: 300 | N29: =+H29+I29+J29+K29+L29+M29-SUM(O29:AI29) -> 300 | O29: 0 | P29: 0 | Q29: 0 | R29: 0 | S29: 500 | T29: 0 | U29: 0 | V29: 0 | W29: 0 | X29: 0 | Y29: 0 | Z29: 0 | AE29: 200 | AI29: 0 | AJ29: =+G29*SUM(H29:M29) -> 76 | AK29: 100 | AL29: 0 | AM29: =+H29*AL29 -> 0 | AN29: 0 | AO29: =+H29*AN29 -> 0 | AP29: =+AO29*2 -> 0 | AQ29: 0 | AR29: 0 | AS29: CTD T.MÉXICO | AT29: BLANCO
B30: LENNOX 1 | C30: SAIRA MORALES | D30: 627101-01 | E30: C - 1/2 | F30: 0.028 | G30: 0.042 | H30: =VLOOKUP(D30,'[1]LENNOX WK 29'!$A$3:$E$76,5,0) -> 0 | I30: 0 | J30: 0 | L30: 0 | N30: =+H30+I30+J30+K30+L30+M30-SUM(O30:AI30) -> -445 | O30: 0 | P30: 0 | Q30: 0 | R30: 0 | S30: 445 | T30: 0 | U30: 0 | V30: 0 | W30: 0 | X30: 0 | Y30: 0 | Z30: 0 | AI30: 0 | AJ30: =+G30*SUM(H30:M30) -> 0 | AK30: 100 | AL30: 0 | AM30: =+H30*AL30 -> 0 | AN30: 0 | AO30: =+H30*AN30 -> 0 | AP30: =+AO30*2 -> 0 | AQ30: 0 | AR30: 0 | AS30: CTD T.MÉXICO | AT30: BLANCO
B31: LENNOX 1 | C31: SAIRA MORALES | D31: 626469-01 | E31: C - 1/2 | F31: 0.028 | G31: 0.105 | H31: =VLOOKUP(D31,'[1]LENNOX WK 29'!$A$3:$E$76,5,0) -> 0 | I31: 500 | J31: 0 | L31: 300 | N31: =+H31+I31+J31+K31+L31+M31-SUM(O31:AI31) -> -83 | O31: 0 | P31: 0 | Q31: 0 | R31: 0 | S31: 0 | T31: 0 | U31: 0 | V31: 0 | W31: 180 | X31: 0 | Y31: 703 | Z31: 0 | AI31: 0 | AJ31: =+G31*SUM(H31:M31) -> 84 | AK31: 100 | AL31: 0 | AM31: =+H31*AL31 -> 0 | AN31: 0 | AO31: =+H31*AN31 -> 0 | AP31: =+AO31*2 -> 0 | AQ31: 0 | AR31: 0 | AS31: CTD T.MÉXICO | AT31: BLANCO
B32: LENNOX 1 | C32: SAIRA MORALES | D32: 619792-01 | E32: C - 1/2 | F32: 0.028 | G32: 0.143 | H32: =VLOOKUP(D32,'[1]LENNOX WK 29'!$A$3:$E$76,5,0) -> 0 | I32: 0 | J32: 0 | L32: 0 | N32: =+H32+I32+J32+K32+L32+M32-SUM(O32:AI32) -> 0 | O32: 0 | P32: 0 | Q32: 0 | R32: 0 | S32: 0 | T32: 0 | U32: 0 | V32: 0 | W32: 0 | X32: 0 | Y32: 0 | Z32: 0 | AI32: 0 | AJ32: =+G32*SUM(H32:M32) -> 0 | AK32: 100 | AL32: 0 | AM32: =+H32*AL32 -> 0 | AN32: 0 | AO32: =+H32*AN32 -> 0 | AP32: =+AO32*2 -> 0 | AQ32: 0 | AR32: 0 | AS32: CTD T.MÉXICO | AT32: BLANCO
B33: LENNOX 1 | C33: SAIRA MORALES | D33: 625022-01 | E33: C - 1/2 | F33: 0.028 | G33: 0.046 | H33: =VLOOKUP(D33,'[1]LENNOX WK 29'!$A$3:$E$76,5,0) -> 0 | I33: 0 | J33: 0 | L33: 300 | N33: =+H33+I33+J33+K33+L33+M33-SUM(O33:AI33) -> 300 | O33: 0 | P33: 0 | Q33: 0 | R33: 0 | S33: 0 | T33: 0 | U33: 0 | V33: 0 | W33: 0 | X33: 0 | Y33: 0 | Z33: 0 | AI33: 0 | AJ33: =+G33*SUM(H33:M33) -> 13.8 | AK33: 100 | AL33: 0 | AM33: =+H33*AL33 -> 0 | AN33: 0 | AO33: =+H33*AN33 -> 0 | AP33: =+AO33*2 -> 0 | AQ33: 0 | AR33: 0 | AS33: CTD T.MÉXICO | AT33: BLANCO
B34: LENNOX 1 | C34: SAIRA MORALES | D34: 627046-01 | E34: C - 1/2 | F34: 0.028 | G34: 0.129 | H34: =VLOOKUP(D34,'[1]LENNOX WK 29'!$A$3:$E$76,5,0) -> 600 | I34: 0 | J34: 100 | K34: 80 | L34: 400 | N34: =+H34+I34+J34+K34+L34+M34-SUM(O34:AI34) -> 500 | O34: 0 | P34: 0 | Q34: 0 | R34: 0 | S34: 580 | T34: 0 | U34: 0 | V34: 0 | W34: 0 | X34: 0 | Y34: 0 | Z34: 0 | AC34: 100 | AI34: 0 | AJ34: =+G34*SUM(H34:M34) -> 152.22 | AK34: 100 | AL34: 0 | AM34: =+H34*AL34 -> 0 | AN34: 0 | AO34: =+H34*AN34 -> 0 | AP34: =+AO34*2 -> 0 | AQ34: 0 | AR34: 0 | AS34: CTD T.MÉXICO | AT34: BLANCO
B35: LENNOX 1 | C35: SAIRA MORALES | D35: MXLB-112323 | E35: C - 1/2 | F35: 0.028 | G35: 0.134 | H35: =VLOOKUP(D35,'[1]LENNOX WK 29'!$A$3:$E$76,5,0) -> 0 | I35: 0 | J35: 0 | L35: 300 | N35: =+H35+I35+J35+K35+L35+M35-SUM(O35:AI35) -> 300 | O35: 0 | P35: 0 | Q35: 0 | R35: 0 | S35: 0 | T35: 0 | U35: 0 | V35: 0 | W35: 0 | X35: 0 | Y35: 0 | Z35: 0 | AI35: 0 | AJ35: =+G35*SUM(H35:M35) -> 40.2 | AK35: 100 | AL35: 0 | AM35: =+H35*AL35 -> 0 | AN35: 0 | AO35: =+H35*AN35 -> 0 | AP35: =+AO35*2 -> 0 | AQ35: 0 | AR35: 0 | AS35: CTD T.MÉXICO | AT35: BLANCO
B36: LENNOX 1 | C36: SAIRA MORALES | D36: 626471-01 | E36: C - 1/2 | F36: 0.028 | G36: 0.105 | H36: =VLOOKUP(D36,'[1]LENNOX WK 29'!$A$3:$E$76,5,0) -> 0 | I36: 0 | J36: 0 | L36: 0 | N36: =+H36+I36+J36+K36+L36+M36-SUM(O36:AI36) -> 0 | O36: 0 | P36: 0 | Q36: 0 | R36: 0 | S36: 0 | T36: 0 | U36: 0 | V36: 0 | W36: 0 | X36: 0 | Y36: 0 | Z36: 0 | AI36: 0 | AJ36: =+G36*SUM(H36:M36) -> 0 | AK36: 100 | AL36: 0 | AM36: =+H36*AL36 -> 0 | AN36: 0 | AO36: =+H36*AN36 -> 0 | AP36: =+AO36*2 -> 0 | AQ36: 0 | AR36: 0 | AS36: CTD T.MÉXICO | AT36: BLANCO
B37: LENNOX 1 | C37: SAIRA MORALES | D37: 626472-01 | E37: C - 1/2 | F37: 0.028 | G37: 0.099 | H37: =VLOOKUP(D37,'[1]LENNOX WK 29'!$A$3:$E$76,5,0) -> 0 | I37: 0 | J37: 0 | L37: 300 | N37: =+H37+I37+J37+K37+L37+M37-SUM(O37:AI37) -> 300 | O37: 0 | P37: 0 | Q37: 0 | R37: 0 | S37: 0 | T37: 0 | U37: 0 | V37: 0 | W37: 0 | X37: 0 | Y37: 0 | Z37: 0 | AI37: 0 | AJ37: =+G37*SUM(H37:M37) -> 29.7 | AK37: 100 | AL37: 0 | AM37: =+H37*AL37 -> 0 | AN37: 0 | AO37: =+H37*AN37 -> 0 | AP37: =+AO37*2 -> 0 | AQ37: 0 | AR37: 0 | AS37: CTD T.MÉXICO | AT37: BLANCO
B38: LENNOX 1 | C38: SAIRA MORALES | D38: 626433-01 | E38: C - 1/2 | F38: 0.028 | G38: 0.131 | H38: =VLOOKUP(D38,'[1]LENNOX WK 29'!$A$3:$E$76,5,0) -> 0 | I38: 0 | J38: 0 | L38: 0 | N38: =+H38+I38+J38+K38+L38+M38-SUM(O38:AI38) -> 0 | O38: 0 | P38: 0 | Q38: 0 | R38: 0 | S38: 0 | T38: 0 | U38: 0 | V38: 0 | W38: 0 | X38: 0 | Y38: 0 | Z38: 0 | AI38: 0 | AJ38: =+G38*SUM(H38:M38) -> 0 | AK38: 100 | AL38: 0 | AM38: =+H38*AL38 -> 0 | AN38: 0 | AO38: =+H38*AN38 -> 0 | AP38: =+AO38*2 -> 0 | AQ38: 0 | AR38: 0 | AS38: CTD T.MÉXICO | AT38: BLANCO
B39: LENNOX 1 | C39: SAIRA MORALES | D39: 627175-01 | E39: C - 1/2 | F39: 0.028 | G39: 0.094 | H39: =VLOOKUP(D39,'[1]LENNOX WK 29'!$A$3:$E$76,5,0) -> 0 | I39: 0 | J39: 0 | L39: 0 | N39: =+H39+I39+J39+K39+L39+M39-SUM(O39:AI39) -> 0 | O39: 0 | P39: 0 | Q39: 0 | R39: 0 | S39: 0 | T39: 0 | U39: 0 | V39: 0 | W39: 0 | X39: 0 | Y39: 0 | Z39: 0 | AI39: 0 | AJ39: =+G39*SUM(H39:M39) -> 0 | AK39: 100 | AL39: 0 | AM39: =+H39*AL39 -> 0 | AN39: 0 | AO39: =+H39*AN39 -> 0 | AP39: =+AO39*2 -> 0 | AQ39: 0 | AR39: 0 | AS39: CTD T.MÉXICO | AT39: BLANCO
B40: LENNOX 1 | C40: SAIRA MORALES | D40: 627021-01 | E40: C - 1/2 | F40: 0.028 | G40: 0.122 | H40: =VLOOKUP(D40,'[1]LENNOX WK 29'!$A$3:$E$76,5,0) -> 0 | I40: 0 | J40: 0 | L40: 0 | N40: =+H40+I40+J40+K40+L40+M40-SUM(O40:AI40) -> 0 | O40: 0 | P40: 0 | Q40: 0 | R40: 0 | S40: 0 | T40: 0 | U40: 0 | V40: 0 | W40: 0 | X40: 0 | Y40: 0 | Z40: 0 | AI40: 0 | AJ40: =+G40*SUM(H40:M40) -> 0 | AK40: 100 | AL40: 0 | AM40: =+H40*AL40 -> 0 | AN40: 0 | AO40: =+H40*AN40 -> 0 | AP40: =+AO40*2 -> 0 | AQ40: 0 | AR40: 0 | AS40: CTD T.MÉXICO | AT40: BLANCO
B41: LENNOX 1 | C41: SAIRA MORALES | D41: 613366-01 | E41: C - 1/2 | F41: 0.028 | G41: 0.101 | H41: =VLOOKUP(D41,'[1]LENNOX WK 29'!$A$3:$E$76,5,0) -> 0 | I41: 0 | J41: 0 | L41: 0 | N41: =+H41+I41+J41+K41+L41+M41-SUM(O41:AI41) -> 0 | O41: 0 | P41: 0 | Q41: 0 | R41: 0 | S41: 0 | T41: 0 | U41: 0 | V41: 0 | W41: 0 | X41: 0 | Y41: 0 | Z41: 0 | AI41: 0 | AJ41: =+G41*SUM(H41:M41) -> 0 | AK41: 100 | AL41: 0 | AM41: =+H41*AL41 -> 0 | AN41: 0 | AO41: =+H41*AN41 -> 0 | AP41: =+AO41*2 -> 0 | AQ41: 0 | AR41: 0 | AS41: CTD T.MÉXICO | AT41: BLANCO
...

Sheet SEMANA 30
B2: DÍA | C2: TURNO
B3: =TODAY() -> 46309 | C3: A | D3: X | H3: PROGRAMA
C4: B | H4: SEMANA | O4: 46223 | Q4: 46224 | S4: 46225 | U4: 46226 | W4: 46227 | Y4: Ag1
B5: CLIENTE | C5: DESTINO | D5: NÚMERO DE PARTE | E5: DIAMETRO | F5: PARED | G5: PESO | H5: 30 | I5: Ag1 | J5: Ag2 | K5: Ag3 | L5: Ag4 | M5: Ag5 | N5: BALANCE | O5: A | P5: B | Q5: A | R5: B | S5: A | T5: B | U5: A | V5: B | W5: A | X5: B | Y5: AYB | Z5: KG | AA5: STD. | AB5: SWITCH | AC5: SWITCH | AD5: BRACKET | AE5: BRACKET | AF5: PIJA | AG5: VALVULA | AH5: CANT. VAL. | AI5: CAJA | AJ5: HOJA COLOR | AL5: Row Labels | AM5: Sum of CANT. VAL.
B6: LENNOX 1 | C6: SAIRA MORALES | D6: 625994-01 | E6: A - 3/8 | F6: 0.42 | G6: 0.02 | H6: 5600 | I6: 0 | J6: 0 | N6: =+H6+I6+J6+K6+L6+M6-SUM(O6:Y6) -> 2350 | R6: 2250 | T6: 1000 | Z6: =+G6*SUM(H6:M6) -> 112 | AA6: 1000 | AB6: 0 | AC6: =+H6*AB6 -> 0 | AD6: 0 | AE6: =+H6*AD6 -> 0 | AF6: =+AE6*2 -> 0 | AG6: 0 | AH6: 0 | AI6: CTD T.MÉXICO | AJ6: BLANCO | AL6: 0 | AM6: 0 | AQ6: 5600
B7: LENNOX 1 | C7: SAIRA MORALES | D7: 627512-01 | E7: A - 3/8 | F7: 0.42 | G7: 0.031 | H7: 4338 | I7: 0 | J7: 1000 | N7: =+H7+I7+J7+K7+L7+M7-SUM(O7:Y7) -> 1668 | P7: 1800 | V7: 600 | X7: 1270 | Z7: =+G7*SUM(H7:M7) -> 165.478 | AA7: 1000 | AB7: 0 | AC7: =+H7*AB7 -> 0 | AD7: 0 | AE7: =+H7*AD7 -> 0 | AF7: =+AE7*2 -> 0 | AG7: 0 | AH7: 0 | AI7: CTD T.MÉXICO | AJ7: BLANCO | AL7: 102831-10 | AM7: 128 | AQ7: 4338
B8: LENNOX 1 | C8: SAIRA MORALES | D8: 625967-01 | E8: A - 3/8 | F8: 0.42 | G8: 0.033 | H8: 1300 | I8: 0 | J8: 0 | N8: =+H8+I8+J8+K8+L8+M8-SUM(O8:Y8) -> 100 | T8: 600 | V8: 600 | Z8: =+G8*SUM(H8:M8) -> 42.9 | AA8: 1000 | AB8: 0 | AC8: =+H8*AB8 -> 0 | AD8: 0 | AE8: =+H8*AD8 -> 0 | AF8: =+AE8*2 -> 0 | AG8: 0 | AH8: 0 | AI8: CTD T.MÉXICO | AJ8: BLANCO | AL8: 102831-11 | AM8: 0 | AQ8: 1300
B9: LENNOX 1 | C9: SAIRA MORALES | D9: 626309-01 | E9: A - 3/8 | F9: 0.42 | G9: 0.019 | H9: 0 | I9: 0 | J9: 0 | N9: =+H9+I9+J9+K9+L9+M9-SUM(O9:Y9) -> 0 | Z9: =+G9*SUM(H9:M9) -> 0 | AA9: 1000 | AB9: 0 | AC9: =+H9*AB9 -> 0 | AD9: 0 | AE9: =+H9*AD9 -> 0 | AF9: =+AE9*2 -> 0 | AG9: 0 | AH9: 0 | AI9: CTD T.MÉXICO | AJ9: BLANCO | AL9: 103881-02 | AM9: 864 | AQ9: 0
B10: LENNOX 1 | C10: SAIRA MORALES | D10: 625890-01 | E10: A - 3/8 | F10: 0.42 | G10: 0.03 | H10: 1000 | I10: 0 | J10: 0 | N10: =+H10+I10+J10+K10+L10+M10-SUM(O10:Y10) -> 1000 | Z10: =+G10*SUM(H10:M10) -> 30 | AA10: 1000 | AB10: 0 | AC10: =+H10*AB10 -> 0 | AD10: 0 | AE10: =+H10*AD10 -> 0 | AF10: =+AE10*2 -> 0 | AG10: 0 | AH10: 0 | AI10: CTD T.MÉXICO | AJ10: BLANCO | AL10: 103881-03 | AM10: 0 | AQ10: 1000
B11: LENNOX 1 | C11: SAIRA MORALES | D11: 615991-01 | E11: A - 3/8 | F11: 0.42 | G11: 0.022 | H11: 1707 | I11: 0 | J11: 0 | N11: =+H11+I11+J11+K11+L11+M11-SUM(O11:Y11) -> 1707 | Z11: =+G11*SUM(H11:M11) -> 37.554 | AA11: 1000 | AB11: 0 | AC11: =+H11*AB11 -> 0 | AD11: 0 | AE11: =+H11*AD11 -> 0 | AF11: =+AE11*2 -> 0 | AG11: 0 | AH11: 0 | AI11: CTD T.MÉXICO | AJ11: BLANCO | AL11: 107892-03 | AM11: 7704 | AQ11: 1707
B12: LENNOX 1 | C12: SAIRA MORALES | D12: 626164-01 | E12: A - 3/8 | F12: 0.42 | G12: 0.023 | H12: 0 | I12: 0 | J12: 0 | N12: =+H12+I12+J12+K12+L12+M12-SUM(O12:Y12) -> 0 | Z12: =+G12*SUM(H12:M12) -> 0 | AA12: 1000 | AB12: 0 | AC12: =+H12*AB12 -> 0 | AD12: 0 | AE12: =+H12*AD12 -> 0 | AF12: =+AE12*2 -> 0 | AG12: 0 | AH12: 0 | AI12: CTD T.MÉXICO | AJ12: BLANCO | AL12: 107892-04 | AM12: 3840 | AQ12: 0
B13: LENNOX 1 | C13: SAIRA MORALES | D13: 626121-01 | E13: C - 3/8 | F13: 0.028 | G13: 0.057 | H13: -3900 | I13: 0 | J13: 0 | N13: =+H13+I13+J13+K13+L13+M13-SUM(O13:Y13) -> -3900 | Z13: =+G13*SUM(H13:M13) -> -222.3 | AA13: 1000 | AB13: 0 | AC13: =+H13*AB13 -> 0 | AD13: 0 | AE13: =+H13*AD13 -> 0 | AF13: =+AE13*2 -> 0 | AG13: 0 | AH13: 0 | AI13: CTD T.MÉXICO | AJ13: BLANCO | AL13: 107905-06 | AM13: 1280 | AQ13: -3900
B14: LENNOX 1 | C14: SAIRA MORALES | D14: 625995-01 | E14: C - 3/8 | F14: 0.028 | G14: 0.044 | H14: -2966 | I14: 0 | J14: 0 | N14: =+H14+I14+J14+K14+L14+M14-SUM(O14:Y14) -> -4366 | P14: 400 | V14: 1000 | Z14: =+G14*SUM(H14:M14) -> -130.504 | AA14: 1000 | AB14: 0 | AC14: =+H14*AB14 -> 0 | AD14: 0 | AE14: =+H14*AD14 -> 0 | AF14: =+AE14*2 -> 0 | AG14: 0 | AH14: 0 | AI14: CTD T.MÉXICO | AJ14: BLANCO | AL14: 107905-07 | AM14: 384 | AQ14: -2966
B15: LENNOX 1 | C15: SAIRA MORALES | D15: 615380-01 | E15: C - 3/8 | F15: 0.028 | G15: 0.015 | H15: 2400 | I15: 0 | J15: 500 | N15: =+H15+I15+J15+K15+L15+M15-SUM(O15:Y15) -> -1200 | O15: 1900 | P15: 500 | S15: 500 | X15: 1200 | Z15: =+G15*SUM(H15:M15) -> 43.5 | AA15: 1000 | AB15: 0 | AC15: =+H15*AB15 -> 0 | AD15: 0 | AE15: =+H15*AD15 -> 0 | AF15: =+AE15*2 -> 0 | AG15: 0 | AH15: 0 | AI15: CTD T.MÉXICO | AJ15: BLANCO | AL15: Grand Total | AM15: 14200 | AQ15: 2400
B16: LENNOX 1 | C16: SAIRA MORALES | D16: 625922-01 | E16: C - 3/8 | F16: 0.028 | G16: 0.019 | H16: 400 | I16: 0 | J16: 0 | N16: =+H16+I16+J16+K16+L16+M16-SUM(O16:Y16) -> 0 | S16: 400 | Z16: =+G16*SUM(H16:M16) -> 7.6 | AA16: 1000 | AB16: 0 | AC16: =+H16*AB16 -> 0 | AD16: 0 | AE16: =+H16*AD16 -> 0 | AF16: =+AE16*2 -> 0 | AG16: 0 | AH16: 0 | AI16: CTD T.MÉXICO | AJ16: BLANCO | AQ16: 400
B17: LENNOX 1 | C17: SAIRA MORALES | D17: 627511-01 | E17: C - 3/8 | F17: 0.028 | G17: 0.024 | H17: 3600 | I17: 0 | J17: 0 | N17: =+H17+I17+J17+K17+L17+M17-SUM(O17:Y17) -> -300 | P17: 300 | Q17: 1900 | R17: 1300 | S17: 400 | Z17: =+G17*SUM(H17:M17) -> 86.4 | AA17: 1000 | AB17: 0 | AC17: =+H17*AB17 -> 0 | AD17: 0 | AE17: =+H17*AD17 -> 0 | AF17: =+AE17*2 -> 0 | AG17: 0 | AH17: 0 | AI17: CTD T.MÉXICO | AJ17: BLANCO | AQ17: 3600
B18: LENNOX 1 | C18: SAIRA MORALES | D18: 626308-01 | E18: C - 3/8 | F18: 0.028 | G18: 0.019 | H18: 0 | I18: 0 | J18: 0 | N18: =+H18+I18+J18+K18+L18+M18-SUM(O18:Y18) -> 0 | Z18: =+G18*SUM(H18:M18) -> 0 | AA18: 1000 | AB18: 0 | AC18: =+H18*AB18 -> 0 | AD18: 0 | AE18: =+H18*AD18 -> 0 | AF18: =+AE18*2 -> 0 | AG18: 0 | AH18: 0 | AI18: CTD T.MÉXICO | AJ18: BLANCO | AQ18: 0
B19: LENNOX 1 | C19: SAIRA MORALES | D19: 626467-01 | E19: C - 1/2 | F19: 0.028 | G19: 0.086 | H19: -55 | I19: 0 | J19: 0 | N19: =+H19+I19+J19+K19+L19+M19-SUM(O19:Y19) -> -55 | Z19: =+G19*SUM(H19:M19) -> -4.73 | AA19: 100 | AB19: 0 | AC19: =+H19*AB19 -> 0 | AD19: 0 | AE19: =+H19*AD19 -> 0 | AF19: =+AE19*2 -> 0 | AG19: 0 | AH19: 0 | AI19: CTD T.MÉXICO | AJ19: BLANCO | AQ19: -55
B20: LENNOX 1 | C20: SAIRA MORALES | D20: 626473-01 | E20: C - 1/2 | F20: 0.028 | G20: 0.117 | H20: 0 | I20: 0 | J20: 0 | N20: =+H20+I20+J20+K20+L20+M20-SUM(O20:Y20) -> 0 | Z20: =+G20*SUM(H20:M20) -> 0 | AA20: 100 | AB20: 0 | AC20: =+H20*AB20 -> 0 | AD20: 0 | AE20: =+H20*AD20 -> 0 | AF20: =+AE20*2 -> 0 | AG20: 0 | AH20: 0 | AI20: CTD T.MÉXICO | AJ20: BLANCO | AQ20: 0
B21: LENNOX 1 | C21: SAIRA MORALES | D21: 627051-01 | E21: C - 1/2 | F21: 0.028 | G21: 0.129 | H21: -25 | I21: 0 | J21: 0 | N21: =+H21+I21+J21+K21+L21+M21-SUM(O21:Y21) -> -370 | Q21: 345 | Z21: =+G21*SUM(H21:M21) -> -3.225 | AA21: 100 | AB21: 0 | AC21: =+H21*AB21 -> 0 | AD21: 0 | AE21: =+H21*AD21 -> 0 | AF21: =+AE21*2 -> 0 | AG21: 0 | AH21: 0 | AI21: CTD T.MÉXICO | AJ21: BLANCO | AQ21: -25
B22: LENNOX 1 | C22: SAIRA MORALES | D22: 627186-01 | E22: C - 1/2 | F22: 0.028 | G22: 0.119 | H22: -250 | I22: 0 | J22: 0 | N22: =+H22+I22+J22+K22+L22+M22-SUM(O22:Y22) -> -250 | Z22: =+G22*SUM(H22:M22) -> -29.75 | AA22: 100 | AB22: 0 | AC22: =+H22*AB22 -> 0 | AD22: 0 | AE22: =+H22*AD22 -> 0 | AF22: =+AE22*2 -> 0 | AG22: 0 | AH22: 0 | AI22: CTD T.MÉXICO | AJ22: BLANCO | AQ22: -250
B23: LENNOX 1 | C23: SAIRA MORALES | D23: 627041-01 | E23: C - 1/2 | F23: 0.028 | G23: 0.127 | H23: 0 | I23: 0 | J23: 0 | N23: =+H23+I23+J23+K23+L23+M23-SUM(O23:Y23) -> -945 | Q23: 645 | R23: 300 | Z23: =+G23*SUM(H23:M23) -> 0 | AA23: 100 | AB23: 0 | AC23: =+H23*AB23 -> 0 | AD23: 0 | AE23: =+H23*AD23 -> 0 | AF23: =+AE23*2 -> 0 | AG23: 0 | AH23: 0 | AI23: CTD T.MÉXICO | AJ23: BLANCO | AQ23: 0
B24: LENNOX 1 | C24: SAIRA MORALES | D24: 625151-01 | E24: C - 1/2 | F24: 0.028 | G24: 0.114 | H24: -55 | I24: 0 | J24: 0 | N24: =+H24+I24+J24+K24+L24+M24-SUM(O24:Y24) -> -1205 | X24: 1150 | Z24: =+G24*SUM(H24:M24) -> -6.27 | AA24: 100 | AB24: 0 | AC24: =+H24*AB24 -> 0 | AD24: 0 | AE24: =+H24*AD24 -> 0 | AF24: =+AE24*2 -> 0 | AG24: 0 | AH24: 0 | AI24: CTD T.MÉXICO | AJ24: BLANCO | AQ24: -55
B25: LENNOX 1 | C25: SAIRA MORALES | D25: 626794-01 | E25: C - 1/2 | F25: 0.028 | G25: 0.069 | H25: -50 | I25: 0 | J25: 0 | N25: =+H25+I25+J25+K25+L25+M25-SUM(O25:Y25) -> -574 | S25: 524 | Z25: =+G25*SUM(H25:M25) -> -3.45 | AA25: 100 | AB25: 0 | AC25: =+H25*AB25 -> 0 | AD25: 0 | AE25: =+H25*AD25 -> 0 | AF25: =+AE25*2 -> 0 | AG25: 0 | AH25: 0 | AI25: CTD T.MÉXICO | AJ25: BLANCO | AQ25: -50
B26: LENNOX 1 | C26: SAIRA MORALES | D26: 618748-01 | E26: C - 1/2 | F26: 0.028 | G26: 0.129 | H26: 0 | I26: 0 | J26: 0 | N26: =+H26+I26+J26+K26+L26+M26-SUM(O26:Y26) -> 0 | Z26: =+G26*SUM(H26:M26) -> 0 | AA26: 100 | AB26: 0 | AC26: =+H26*AB26 -> 0 | AD26: 0 | AE26: =+H26*AD26 -> 0 | AF26: =+AE26*2 -> 0 | AG26: 0 | AH26: 0 | AI26: CTD T.MÉXICO | AJ26: BLANCO | AQ26: 0
B27: LENNOX 1 | C27: SAIRA MORALES | D27: 626532-01 | E27: C - 1/2 | F27: 0.028 | G27: 0.078 | H27: 307 | I27: 0 | J27: 0 | N27: =+H27+I27+J27+K27+L27+M27-SUM(O27:Y27) -> -583 | O27: 270 | T27: 620 | Z27: =+G27*SUM(H27:M27) -> 23.946 | AA27: 100 | AB27: 0 | AC27: =+H27*AB27 -> 0 | AD27: 0 | AE27: =+H27*AD27 -> 0 | AF27: =+AE27*2 -> 0 | AG27: 0 | AH27: 0 | AI27: CTD T.MÉXICO | AJ27: BLANCO | AQ27: 307
B28: LENNOX 1 | C28: SAIRA MORALES | D28: 626391-01 | E28: C - 1/2 | F28: 0.028 | G28: 0.101 | H28: -77 | I28: 0 | J28: 900 | N28: =+H28+I28+J28+K28+L28+M28-SUM(O28:Y28) -> -257 | T28: 1080 | Z28: =+G28*SUM(H28:M28) -> 83.123 | AA28: 100 | AB28: 0 | AC28: =+H28*AB28 -> 0 | AD28: 0 | AE28: =+H28*AD28 -> 0 | AF28: =+AE28*2 -> 0 | AG28: 0 | AH28: 0 | AI28: CTD T.MÉXICO | AJ28: BLANCO | AQ28: -77
B29: LENNOX 1 | C29: SAIRA MORALES | D29: 613544-01 | E29: C - 1/2 | F29: 0.028 | G29: 0.076 | H29: 300 | I29: 0 | J29: 0 | N29: =+H29+I29+J29+K29+L29+M29-SUM(O29:Y29) -> -40 | O29: 260 | Q29: 80 | Z29: =+G29*SUM(H29:M29) -> 22.8 | AA29: 100 | AB29: 0 | AC29: =+H29*AB29 -> 0 | AD29: 0 | AE29: =+H29*AD29 -> 0 | AF29: =+AE29*2 -> 0 | AG29: 0 | AH29: 0 | AI29: CTD T.MÉXICO | AJ29: BLANCO | AQ29: 300
B30: LENNOX 1 | C30: SAIRA MORALES | D30: 627101-01 | E30: C - 1/2 | F30: 0.028 | G30: 0.042 | H30: -445 | I30: 0 | J30: 0 | N30: =+H30+I30+J30+K30+L30+M30-SUM(O30:Y30) -> -445 | Z30: =+G30*SUM(H30:M30) -> -18.69 | AA30: 100 | AB30: 0 | AC30: =+H30*AB30 -> 0 | AD30: 0 | AE30: =+H30*AD30 -> 0 | AF30: =+AE30*2 -> 0 | AG30: 0 | AH30: 0 | AI30: CTD T.MÉXICO | AJ30: BLANCO | AQ30: -445
B31: LENNOX 1 | C31: SAIRA MORALES | D31: 626469-01 | E31: C - 1/2 | F31: 0.028 | G31: 0.105 | H31: -83 | I31: 0 | J31: 0 | N31: =+H31+I31+J31+K31+L31+M31-SUM(O31:Y31) -> -393 | P31: 310 | Z31: =+G31*SUM(H31:M31) -> -8.715 | AA31: 100 | AB31: 0 | AC31: =+H31*AB31 -> 0 | AD31: 0 | AE31: =+H31*AD31 -> 0 | AF31: =+AE31*2 -> 0 | AG31: 0 | AH31: 0 | AI31: CTD T.MÉXICO | AJ31: BLANCO | AQ31: -83
B32: LENNOX 1 | C32: SAIRA MORALES | D32: 619792-01 | E32: C - 1/2 | F32: 0.028 | G32: 0.143 | H32: 0 | I32: 0 | J32: 0 | N32: =+H32+I32+J32+K32+L32+M32-SUM(O32:Y32) -> 0 | Z32: =+G32*SUM(H32:M32) -> 0 | AA32: 100 | AB32: 0 | AC32: =+H32*AB32 -> 0 | AD32: 0 | AE32: =+H32*AD32 -> 0 | AF32: =+AE32*2 -> 0 | AG32: 0 | AH32: 0 | AI32: CTD T.MÉXICO | AJ32: BLANCO | AQ32: 0
B33: LENNOX 1 | C33: SAIRA MORALES | D33: 625022-01 | E33: C - 1/2 | F33: 0.028 | G33: 0.046 | H33: 300 | I33: 0 | J33: 0 | N33: =+H33+I33+J33+K33+L33+M33-SUM(O33:Y33) -> -230 | O33: 300 | Q33: 230 | Z33: =+G33*SUM(H33:M33) -> 13.8 | AA33: 100 | AB33: 0 | AC33: =+H33*AB33 -> 0 | AD33: 0 | AE33: =+H33*AD33 -> 0 | AF33: =+AE33*2 -> 0 | AG33: 0 | AH33: 0 | AI33: CTD T.MÉXICO | AJ33: BLANCO | AQ33: 300
B34: LENNOX 1 | C34: SAIRA MORALES | D34: 627046-01 | E34: C - 1/2 | F34: 0.028 | G34: 0.129 | H34: 500 | I34: 0 | J34: 0 | N34: =+H34+I34+J34+K34+L34+M34-SUM(O34:Y34) -> 79 | R34: 421 | Z34: =+G34*SUM(H34:M34) -> 64.5 | AA34: 100 | AB34: 0 | AC34: =+H34*AB34 -> 0 | AD34: 0 | AE34: =+H34*AD34 -> 0 | AF34: =+AE34*2 -> 0 | AG34: 0 | AH34: 0 | AI34: CTD T.MÉXICO | AJ34: BLANCO | AQ34: 500
B35: LENNOX 1 | C35: SAIRA MORALES | D35: MXLB-112323 | E35: C - 1/2 | F35: 0.028 | G35: 0.134 | H35: 300 | I35: 0 | J35: 0 | N35: =+H35+I35+J35+K35+L35+M35-SUM(O35:Y35) -> -10 | S35: 310 | Z35: =+G35*SUM(H35:M35) -> 40.2 | AA35: 100 | AB35: 0 | AC35: =+H35*AB35 -> 0 | AD35: 0 | AE35: =+H35*AD35 -> 0 | AF35: =+AE35*2 -> 0 | AG35: 0 | AH35: 0 | AI35: CTD T.MÉXICO | AJ35: BLANCO | AQ35: 300
B36: LENNOX 1 | C36: SAIRA MORALES | D36: 626471-01 | E36: C - 1/2 | F36: 0.028 | G36: 0.105 | H36: 0 | I36: 0 | J36: 0 | N36: =+H36+I36+J36+K36+L36+M36-SUM(O36:Y36) -> 0 | Z36: =+G36*SUM(H36:M36) -> 0 | AA36: 100 | AB36: 0 | AC36: =+H36*AB36 -> 0 | AD36: 0 | AE36: =+H36*AD36 -> 0 | AF36: =+AE36*2 -> 0 | AG36: 0 | AH36: 0 | AI36: CTD T.MÉXICO | AJ36: BLANCO | AQ36: 0
B37: LENNOX 1 | C37: SAIRA MORALES | D37: 626472-01 | E37: C - 1/2 | F37: 0.028 | G37: 0.099 | H37: 300 | I37: 0 | J37: 0 | N37: =+H37+I37+J37+K37+L37+M37-SUM(O37:Y37) -> -55 | Q37: 355 | Z37: =+G37*SUM(H37:M37) -> 29.7 | AA37: 100 | AB37: 0 | AC37: =+H37*AB37 -> 0 | AD37: 0 | AE37: =+H37*AD37 -> 0 | AF37: =+AE37*2 -> 0 | AG37: 0 | AH37: 0 | AI37: CTD T.MÉXICO | AJ37: BLANCO | AQ37: 300
B38: LENNOX 1 | C38: SAIRA MORALES | D38: 626433-01 | E38: C - 1/2 | F38: 0.028 | G38: 0.131 | H38: 0 | I38: 0 | J38: 0 | N38: =+H38+I38+J38+K38+L38+M38-SUM(O38:Y38) -> 0 | Z38: =+G38*SUM(H38:M38) -> 0 | AA38: 100 | AB38: 0 | AC38: =+H38*AB38 -> 0 | AD38: 0 | AE38: =+H38*AD38 -> 0 | AF38: =+AE38*2 -> 0 | AG38: 0 | AH38: 0 | AI38: CTD T.MÉXICO | AJ38: BLANCO | AQ38: 0
B39: LENNOX 1 | C39: SAIRA MORALES | D39: 627175-01 | E39: C - 1/2 | F39: 0.028 | G39: 0.094 | H39: 0 | I39: 0 | J39: 0 | N39: =+H39+I39+J39+K39+L39+M39-SUM(O39:Y39) -> 0 | Z39: =+G39*SUM(H39:M39) -> 0 | AA39: 100 | AB39: 0 | AC39: =+H39*AB39 -> 0 | AD39: 0 | AE39: =+H39*AD39 -> 0 | AF39: =+AE39*2 -> 0 | AG39: 0 | AH39: 0 | AI39: CTD T.MÉXICO | AJ39: BLANCO | AQ39: 0
B40: LENNOX 1 | C40: SAIRA MORALES | D40: 627021-01 | E40: C - 1/2 | F40: 0.028 | G40: 0.122 | H40: 0 | I40: 0 | J40: 0 | N40: =+H40+I40+J40+K40+L40+M40-SUM(O40:Y40) -> 0 | Z40: =+G40*SUM(H40:M40) -> 0 | AA40: 100 | AB40: 0 | AC40: =+H40*AB40 -> 0 | AD40: 0 | AE40: =+H40*AD40 -> 0 | AF40: =+AE40*2 -> 0 | AG40: 0 | AH40: 0 | AI40: CTD T.MÉXICO | AJ40: BLANCO | AQ40: 0
B41: LENNOX 1 | C41: SAIRA MORALES | D41: 613366-01 | E41: C - 1/2 | F41: 0.028 | G41: 0.101 | H41: 0 | I41: 0 | J41: 0 | N41: =+H41+I41+J41+K41+L41+M41-SUM(O41:Y41) -> 0 | Z41: =+G41*SUM(H41:M41) -> 0 | AA41: 100 | AB41: 0 | AC41: =+H41*AB41 -> 0 | AD41: 0 | AE41: =+H41*AD41 -> 0 | AF41: =+AE41*2 -> 0 | AG41: 0 | AH41: 0 | AI41: CTD T.MÉXICO | AJ41: BLANCO | AQ41: 0
...

Sheet SEMANA 31
B2: DÍA | C2: TURNO
B3: =TODAY() -> 46309 | C3: A | D3: X | H3: PROGRAMA
C4: B | H4: SEMANA | I4: Convertirlo a horas | O4: 46230 | Q4: 46231 | S4: 46232 | U4: 46233 | W4: 46234 | Y4: Ag1
B5: CLIENTE | C5: DESTINO | D5: NÚMERO DE PARTE | E5: DIAMETRO | F5: PARED | G5: PESO | H5: 31 | I5: 31 AL | J5: Atraso S 30 | K5: Ag3 | L5: Ag4 | M5: Ag5 | N5: BALANCE | O5: A | P5: B | Q5: A | R5: B | S5: A | T5: B | U5: A | V5: B | W5: A | X5: B | Y5: Agregado | Z5: KG | AA5: STD. | AB5: SWITCH | AC5: SWITCH | AD5: BRACKET | AE5: BRACKET | AF5: PIJA | AG5: VALVULA | AH5: CANT. VAL. | AI5: CAJA | AJ5: HOJA COLOR | AL5: Row Labels | AM5: Sum of CANT. VAL.
B6: LENNOX 1 | C6: SAIRA MORALES | D6: 625994-01 | E6: A - 3/8 | F6: 0.42 | G6: 0.02 | H6: 0 | I6: 3700 | J6: 2350 | N6: =+H6+I6+J6+K6+L6+M6-SUM(O6:Y6) -> 3515 | R6: 2535 | Z6: =+G6*SUM(H6:M6) -> 121 | AA6: 1000 | AB6: 0 | AC6: =+H6*AB6 -> 0 | AD6: 0 | AE6: =+H6*AD6 -> 0 | AF6: =+AE6*2 -> 0 | AG6: 0 | AH6: 0 | AI6: CTD T.MÉXICO | AJ6: BLANCO | AL6: 0 | AM6: 0 | AQ6: 5600
B7: LENNOX 1 | C7: SAIRA MORALES | D7: 627512-01 | E7: A - 3/8 | F7: 0.42 | G7: 0.031 | H7: 0 | I7: 8900 | J7: 1668 | N7: =+H7+I7+J7+K7+L7+M7-SUM(O7:Y7) -> 6076 | P7: 1700 | R7: 1300 | T7: 492 | V7: 1000 | Z7: =+G7*SUM(H7:M7) -> 327.608 | AA7: 1000 | AB7: 0 | AC7: =+H7*AB7 -> 0 | AD7: 0 | AE7: =+H7*AD7 -> 0 | AF7: =+AE7*2 -> 0 | AG7: 0 | AH7: 0 | AI7: CTD T.MÉXICO | AJ7: BLANCO | AL7: 102831-10 | AM7: 128 | AQ7: 4338
B8: LENNOX 1 | C8: SAIRA MORALES | D8: 625967-01 | E8: A - 3/8 | F8: 0.42 | G8: 0.033 | H8: 0 | I8: 700 | J8: 100 | N8: =+H8+I8+J8+K8+L8+M8-SUM(O8:Y8) -> 672 | P8: 128 | Z8: =+G8*SUM(H8:M8) -> 26.4 | AA8: 1000 | AB8: 0 | AC8: =+H8*AB8 -> 0 | AD8: 0 | AE8: =+H8*AD8 -> 0 | AF8: =+AE8*2 -> 0 | AG8: 0 | AH8: 0 | AI8: CTD T.MÉXICO | AJ8: BLANCO | AL8: 102831-11 | AM8: 0 | AQ8: 1300
B9: LENNOX 1 | C9: SAIRA MORALES | D9: 626309-01 | E9: A - 3/8 | F9: 0.42 | G9: 0.019 | H9: 0 | I9: 700 | J9: 0 | N9: =+H9+I9+J9+K9+L9+M9-SUM(O9:Y9) -> -187 | T9: 887 | Z9: =+G9*SUM(H9:M9) -> 13.3 | AA9: 1000 | AB9: 0 | AC9: =+H9*AB9 -> 0 | AD9: 0 | AE9: =+H9*AD9 -> 0 | AF9: =+AE9*2 -> 0 | AG9: 0 | AH9: 0 | AI9: CTD T.MÉXICO | AJ9: BLANCO | AL9: 103881-02 | AM9: 864 | AQ9: 0
B10: LENNOX 1 | C10: SAIRA MORALES | D10: 625890-01 | E10: A - 3/8 | F10: 0.42 | G10: 0.03 | H10: 0 | I10: 0 | J10: 1000 | N10: =+H10+I10+J10+K10+L10+M10-SUM(O10:Y10) -> 200 | T10: 800 | Z10: =+G10*SUM(H10:M10) -> 30 | AA10: 1000 | AB10: 0 | AC10: =+H10*AB10 -> 0 | AD10: 0 | AE10: =+H10*AD10 -> 0 | AF10: =+AE10*2 -> 0 | AG10: 0 | AH10: 0 | AI10: CTD T.MÉXICO | AJ10: BLANCO | AL10: 103881-03 | AM10: 0 | AQ10: 1000
B11: LENNOX 1 | C11: SAIRA MORALES | D11: 615991-01 | E11: A - 3/8 | F11: 0.42 | G11: 0.022 | H11: 0 | I11: 800 | J11: 1707 | N11: =+H11+I11+J11+K11+L11+M11-SUM(O11:Y11) -> 1507 | V11: 1000 | Z11: =+G11*SUM(H11:M11) -> 55.154 | AA11: 1000 | AB11: 0 | AC11: =+H11*AB11 -> 0 | AD11: 0 | AE11: =+H11*AD11 -> 0 | AF11: =+AE11*2 -> 0 | AG11: 0 | AH11: 0 | AI11: CTD T.MÉXICO | AJ11: BLANCO | AL11: 107892-03 | AM11: 7704 | AQ11: 1707
B12: LENNOX 1 | C12: SAIRA MORALES | D12: 626164-01 | E12: A - 3/8 | F12: 0.42 | G12: 0.023 | H12: 0 | I12: 0 | J12: 0 | N12: =+H12+I12+J12+K12+L12+M12-SUM(O12:Y12) -> 0 | Z12: =+G12*SUM(H12:M12) -> 0 | AA12: 1000 | AB12: 0 | AC12: =+H12*AB12 -> 0 | AD12: 0 | AE12: =+H12*AD12 -> 0 | AF12: =+AE12*2 -> 0 | AG12: 0 | AH12: 0 | AI12: CTD T.MÉXICO | AJ12: BLANCO | AL12: 107892-04 | AM12: 3840 | AQ12: 0
B13: LENNOX 1 | C13: SAIRA MORALES | D13: 626121-01 | E13: C - 3/8 | F13: 0.028 | G13: 0.057 | H13: 0 | I13: 0 | J13: 0 | N13: =+H13+I13+J13+K13+L13+M13-SUM(O13:Y13) -> -3900 | Y13: 3900 | Z13: =+G13*SUM(H13:M13) -> 0 | AA13: 1000 | AB13: 0 | AC13: =+H13*AB13 -> 0 | AD13: 0 | AE13: =+H13*AD13 -> 0 | AF13: =+AE13*2 -> 0 | AG13: 0 | AH13: 0 | AI13: CTD T.MÉXICO | AJ13: BLANCO | AL13: 107905-06 | AM13: 1280 | AQ13: -3900
B14: LENNOX 1 | C14: SAIRA MORALES | D14: 625995-01 | E14: C - 3/8 | F14: 0.028 | G14: 0.044 | H14: 2600 | I14: 0 | J14: 0 | N14: =+H14+I14+J14+K14+L14+M14-SUM(O14:Y14) -> -1766 | Y14: 4366 | Z14: =+G14*SUM(H14:M14) -> 114.4 | AA14: 1000 | AB14: 0 | AC14: =+H14*AB14 -> 0 | AD14: 0 | AE14: =+H14*AD14 -> 0 | AF14: =+AE14*2 -> 0 | AG14: 0 | AH14: 0 | AI14: CTD T.MÉXICO | AJ14: BLANCO | AL14: 107905-07 | AM14: 384 | AQ14: -2966
B15: LENNOX 1 | C15: SAIRA MORALES | D15: 615380-01 | E15: C - 3/8 | F15: 0.028 | G15: 0.015 | H15: 2100 | I15: 0 | J15: 0 | N15: =+H15+I15+J15+K15+L15+M15-SUM(O15:Y15) -> -2700 | P15: 400 | Q15: 800 | W15: 1900 | X15: 500 | Y15: 1200 | Z15: =+G15*SUM(H15:M15) -> 31.5 | AA15: 1000 | AB15: 0 | AC15: =+H15*AB15 -> 0 | AD15: 0 | AE15: =+H15*AD15 -> 0 | AF15: =+AE15*2 -> 0 | AG15: 0 | AH15: 0 | AI15: CTD T.MÉXICO | AJ15: BLANCO | AL15: Grand Total | AM15: 14200 | AQ15: 2400
B16: LENNOX 1 | C16: SAIRA MORALES | D16: 625922-01 | E16: C - 3/8 | F16: 0.028 | G16: 0.019 | H16: 0 | I16: 0 | J16: 0 | N16: =+H16+I16+J16+K16+L16+M16-SUM(O16:Y16) -> 0 | Z16: =+G16*SUM(H16:M16) -> 0 | AA16: 1000 | AB16: 0 | AC16: =+H16*AB16 -> 0 | AD16: 0 | AE16: =+H16*AD16 -> 0 | AF16: =+AE16*2 -> 0 | AG16: 0 | AH16: 0 | AI16: CTD T.MÉXICO | AJ16: BLANCO | AQ16: 400
B17: LENNOX 1 | C17: SAIRA MORALES | D17: 627511-01 | E17: C - 3/8 | F17: 0.028 | G17: 0.024 | H17: 2900 | I17: 0 | J17: 0 | N17: =+H17+I17+J17+K17+L17+M17-SUM(O17:Y17) -> -4200 | O17: 1000 | P17: 800 | Q17: 700 | R17: 900 | T17: 800 | U17: 1700 | V17: 900 | Y17: 300 | Z17: =+G17*SUM(H17:M17) -> 69.6 | AA17: 1000 | AB17: 0 | AC17: =+H17*AB17 -> 0 | AD17: 0 | AE17: =+H17*AD17 -> 0 | AF17: =+AE17*2 -> 0 | AG17: 0 | AH17: 0 | AI17: CTD T.MÉXICO | AJ17: BLANCO | AQ17: 3600
B18: LENNOX 1 | C18: SAIRA MORALES | D18: 626308-01 | E18: C - 3/8 | F18: 0.028 | G18: 0.019 | H18: 300 | I18: 0 | J18: 0 | N18: =+H18+I18+J18+K18+L18+M18-SUM(O18:Y18) -> 0 | O18: 300 | Z18: =+G18*SUM(H18:M18) -> 5.7 | AA18: 1000 | AB18: 0 | AC18: =+H18*AB18 -> 0 | AD18: 0 | AE18: =+H18*AD18 -> 0 | AF18: =+AE18*2 -> 0 | AG18: 0 | AH18: 0 | AI18: CTD T.MÉXICO | AJ18: BLANCO | AQ18: 0
B19: LENNOX 1 | C19: SAIRA MORALES | D19: 626467-01 | E19: C - 1/2 | F19: 0.028 | G19: 0.086 | H19: 300 | I19: 0 | J19: 0 | N19: =+H19+I19+J19+K19+L19+M19-SUM(O19:Y19) -> -18 | O19: 318 | Z19: =+G19*SUM(H19:M19) -> 25.8 | AA19: 100 | AB19: 0 | AC19: =+H19*AB19 -> 0 | AD19: 0 | AE19: =+H19*AD19 -> 0 | AF19: =+AE19*2 -> 0 | AG19: 0 | AH19: 0 | AI19: CTD T.MÉXICO | AJ19: BLANCO | AQ19: -55
B20: LENNOX 1 | C20: SAIRA MORALES | D20: 626473-01 | E20: C - 1/2 | F20: 0.028 | G20: 0.117 | H20: 400 | I20: 0 | J20: 0 | N20: =+H20+I20+J20+K20+L20+M20-SUM(O20:Y20) -> -14 | O20: 414 | Z20: =+G20*SUM(H20:M20) -> 46.8 | AA20: 100 | AB20: 0 | AC20: =+H20*AB20 -> 0 | AD20: 0 | AE20: =+H20*AD20 -> 0 | AF20: =+AE20*2 -> 0 | AG20: 0 | AH20: 0 | AI20: CTD T.MÉXICO | AJ20: BLANCO | AQ20: 0
B21: LENNOX 1 | C21: SAIRA MORALES | D21: 627051-01 | E21: C - 1/2 | F21: 0.028 | G21: 0.129 | H21: 0 | I21: 0 | J21: 0 | N21: =+H21+I21+J21+K21+L21+M21-SUM(O21:Y21) -> -370 | Y21: 370 | Z21: =+G21*SUM(H21:M21) -> 0 | AA21: 100 | AB21: 0 | AC21: =+H21*AB21 -> 0 | AD21: 0 | AE21: =+H21*AD21 -> 0 | AF21: =+AE21*2 -> 0 | AG21: 0 | AH21: 0 | AI21: CTD T.MÉXICO | AJ21: BLANCO | AQ21: -25
B22: LENNOX 1 | C22: SAIRA MORALES | D22: 627186-01 | E22: C - 1/2 | F22: 0.028 | G22: 0.119 | H22: 0 | I22: 0 | J22: 0 | N22: =+H22+I22+J22+K22+L22+M22-SUM(O22:Y22) -> -755 | X22: 505 | Y22: 250 | Z22: =+G22*SUM(H22:M22) -> 0 | AA22: 100 | AB22: 0 | AC22: =+H22*AB22 -> 0 | AD22: 0 | AE22: =+H22*AD22 -> 0 | AF22: =+AE22*2 -> 0 | AG22: 0 | AH22: 0 | AI22: CTD T.MÉXICO | AJ22: BLANCO | AQ22: -250
B23: LENNOX 1 | C23: SAIRA MORALES | D23: 627041-01 | E23: C - 1/2 | F23: 0.028 | G23: 0.127 | H23: 0 | I23: 0 | J23: 0 | N23: =+H23+I23+J23+K23+L23+M23-SUM(O23:Y23) -> -945 | Y23: 945 | Z23: =+G23*SUM(H23:M23) -> 0 | AA23: 100 | AB23: 0 | AC23: =+H23*AB23 -> 0 | AD23: 0 | AE23: =+H23*AD23 -> 0 | AF23: =+AE23*2 -> 0 | AG23: 0 | AH23: 0 | AI23: CTD T.MÉXICO | AJ23: BLANCO | AQ23: 0
B24: LENNOX 1 | C24: SAIRA MORALES | D24: 625151-01 | E24: C - 1/2 | F24: 0.028 | G24: 0.114 | H24: 1200 | I24: 0 | J24: 0 | N24: =+H24+I24+J24+K24+L24+M24-SUM(O24:Y24) -> 0 | Y24: 1200 | Z24: =+G24*SUM(H24:M24) -> 136.8 | AA24: 100 | AB24: 0 | AC24: =+H24*AB24 -> 0 | AD24: 0 | AE24: =+H24*AD24 -> 0 | AF24: =+AE24*2 -> 0 | AG24: 0 | AH24: 0 | AI24: CTD T.MÉXICO | AJ24: BLANCO | AQ24: -55
B25: LENNOX 1 | C25: SAIRA MORALES | D25: 626794-01 | E25: C - 1/2 | F25: 0.028 | G25: 0.069 | H25: 0 | I25: 0 | J25: 0 | N25: =+H25+I25+J25+K25+L25+M25-SUM(O25:Y25) -> -1488 | X25: 914 | Y25: 574 | Z25: =+G25*SUM(H25:M25) -> 0 | AA25: 100 | AB25: 0 | AC25: =+H25*AB25 -> 0 | AD25: 0 | AE25: =+H25*AD25 -> 0 | AF25: =+AE25*2 -> 0 | AG25: 0 | AH25: 0 | AI25: CTD T.MÉXICO | AJ25: BLANCO | AQ25: -50
B26: LENNOX 1 | C26: SAIRA MORALES | D26: 618748-01 | E26: C - 1/2 | F26: 0.028 | G26: 0.129 | H26: 0 | I26: 0 | J26: 0 | N26: =+H26+I26+J26+K26+L26+M26-SUM(O26:Y26) -> 0 | Z26: =+G26*SUM(H26:M26) -> 0 | AA26: 100 | AB26: 0 | AC26: =+H26*AB26 -> 0 | AD26: 0 | AE26: =+H26*AD26 -> 0 | AF26: =+AE26*2 -> 0 | AG26: 0 | AH26: 0 | AI26: CTD T.MÉXICO | AJ26: BLANCO | AQ26: 0
B27: LENNOX 1 | C27: SAIRA MORALES | D27: 626532-01 | E27: C - 1/2 | F27: 0.028 | G27: 0.078 | H27: 700 | I27: 0 | J27: 0 | N27: =+H27+I27+J27+K27+L27+M27-SUM(O27:Y27) -> -1890 | O27: 587 | U27: 700 | V27: 720 | Y27: 583 | Z27: =+G27*SUM(H27:M27) -> 54.6 | AA27: 100 | AB27: 0 | AC27: =+H27*AB27 -> 0 | AD27: 0 | AE27: =+H27*AD27 -> 0 | AF27: =+AE27*2 -> 0 | AG27: 0 | AH27: 0 | AI27: CTD T.MÉXICO | AJ27: BLANCO | AQ27: 307
B28: LENNOX 1 | C28: SAIRA MORALES | D28: 626391-01 | E28: C - 1/2 | F28: 0.028 | G28: 0.101 | H28: 0 | I28: 0 | J28: 0 | N28: =+H28+I28+J28+K28+L28+M28-SUM(O28:Y28) -> -257 | Y28: 257 | Z28: =+G28*SUM(H28:M28) -> 0 | AA28: 100 | AB28: 0 | AC28: =+H28*AB28 -> 0 | AD28: 0 | AE28: =+H28*AD28 -> 0 | AF28: =+AE28*2 -> 0 | AG28: 0 | AH28: 0 | AI28: CTD T.MÉXICO | AJ28: BLANCO | AQ28: -77
B29: LENNOX 1 | C29: SAIRA MORALES | D29: 613544-01 | E29: C - 1/2 | F29: 0.028 | G29: 0.076 | H29: 100 | I29: 0 | J29: 0 | N29: =+H29+I29+J29+K29+L29+M29-SUM(O29:Y29) -> -9 | S29: 109 | Z29: =+G29*SUM(H29:M29) -> 7.6 | AA29: 100 | AB29: 0 | AC29: =+H29*AB29 -> 0 | AD29: 0 | AE29: =+H29*AD29 -> 0 | AF29: =+AE29*2 -> 0 | AG29: 0 | AH29: 0 | AI29: CTD T.MÉXICO | AJ29: BLANCO | AQ29: 300
B30: LENNOX 1 | C30: SAIRA MORALES | D30: 627101-01 | E30: C - 1/2 | F30: 0.028 | G30: 0.042 | H30: 0 | I30: 0 | J30: 0 | N30: =+H30+I30+J30+K30+L30+M30-SUM(O30:Y30) -> -2105 | V30: 760 | W30: 900 | Y30: 445 | Z30: =+G30*SUM(H30:M30) -> 0 | AA30: 100 | AB30: 0 | AC30: =+H30*AB30 -> 0 | AD30: 0 | AE30: =+H30*AD30 -> 0 | AF30: =+AE30*2 -> 0 | AG30: 0 | AH30: 0 | AI30: CTD T.MÉXICO | AJ30: BLANCO | AQ30: -445
B31: LENNOX 1 | C31: SAIRA MORALES | D31: 626469-01 | E31: C - 1/2 | F31: 0.028 | G31: 0.105 | H31: 1000 | I31: 0 | J31: 0 | N31: =+H31+I31+J31+K31+L31+M31-SUM(O31:Y31) -> -1078 | P31: 1000 | X31: 685 | Y31: 393 | Z31: =+G31*SUM(H31:M31) -> 105 | AA31: 100 | AB31: 0 | AC31: =+H31*AB31 -> 0 | AD31: 0 | AE31: =+H31*AD31 -> 0 | AF31: =+AE31*2 -> 0 | AG31: 0 | AH31: 0 | AI31: CTD T.MÉXICO | AJ31: BLANCO | AQ31: -83
B32: LENNOX 1 | C32: SAIRA MORALES | D32: 619792-01 | E32: C - 1/2 | F32: 0.028 | G32: 0.143 | H32: 0 | I32: 0 | J32: 0 | N32: =+H32+I32+J32+K32+L32+M32-SUM(O32:Y32) -> 0 | Z32: =+G32*SUM(H32:M32) -> 0 | AA32: 100 | AB32: 0 | AC32: =+H32*AB32 -> 0 | AD32: 0 | AE32: =+H32*AD32 -> 0 | AF32: =+AE32*2 -> 0 | AG32: 0 | AH32: 0 | AI32: CTD T.MÉXICO | AJ32: BLANCO | AQ32: 0
B33: LENNOX 1 | C33: SAIRA MORALES | D33: 625022-01 | E33: C - 1/2 | F33: 0.028 | G33: 0.046 | H33: 0 | I33: 0 | J33: 0 | N33: =+H33+I33+J33+K33+L33+M33-SUM(O33:Y33) -> -230 | Y33: 230 | Z33: =+G33*SUM(H33:M33) -> 0 | AA33: 100 | AB33: 0 | AC33: =+H33*AB33 -> 0 | AD33: 0 | AE33: =+H33*AD33 -> 0 | AF33: =+AE33*2 -> 0 | AG33: 0 | AH33: 0 | AI33: CTD T.MÉXICO | AJ33: BLANCO | AQ33: 300
B34: LENNOX 1 | C34: SAIRA MORALES | D34: 627046-01 | E34: C - 1/2 | F34: 0.028 | G34: 0.129 | H34: 300 | I34: 0 | J34: 79 | N34: =+H34+I34+J34+K34+L34+M34-SUM(O34:Y34) -> -38 | O34: 417 | Z34: =+G34*SUM(H34:M34) -> 48.891 | AA34: 100 | AB34: 0 | AC34: =+H34*AB34 -> 0 | AD34: 0 | AE34: =+H34*AD34 -> 0 | AF34: =+AE34*2 -> 0 | AG34: 0 | AH34: 0 | AI34: CTD T.MÉXICO | AJ34: BLANCO | AQ34: 500
B35: LENNOX 1 | C35: SAIRA MORALES | D35: MXLB-112323 | E35: C - 1/2 | F35: 0.028 | G35: 0.134 | H35: 400 | I35: 0 | J35: 0 | N35: =+H35+I35+J35+K35+L35+M35-SUM(O35:Y35) -> -3 | S35: 403 | Z35: =+G35*SUM(H35:M35) -> 53.6 | AA35: 100 | AB35: 0 | AC35: =+H35*AB35 -> 0 | AD35: 0 | AE35: =+H35*AD35 -> 0 | AF35: =+AE35*2 -> 0 | AG35: 0 | AH35: 0 | AI35: CTD T.MÉXICO | AJ35: BLANCO | AQ35: 300
B36: LENNOX 1 | C36: SAIRA MORALES | D36: 626471-01 | E36: C - 1/2 | F36: 0.028 | G36: 0.105 | H36: 0 | I36: 0 | J36: 0 | N36: =+H36+I36+J36+K36+L36+M36-SUM(O36:Y36) -> 0 | Z36: =+G36*SUM(H36:M36) -> 0 | AA36: 100 | AB36: 0 | AC36: =+H36*AB36 -> 0 | AD36: 0 | AE36: =+H36*AD36 -> 0 | AF36: =+AE36*2 -> 0 | AG36: 0 | AH36: 0 | AI36: CTD T.MÉXICO | AJ36: BLANCO | AQ36: 0
B37: LENNOX 1 | C37: SAIRA MORALES | D37: 626472-01 | E37: C - 1/2 | F37: 0.028 | G37: 0.099 | H37: 100 | I37: 0 | J37: 0 | N37: =+H37+I37+J37+K37+L37+M37-SUM(O37:Y37) -> 0 | Q37: 100 | Z37: =+G37*SUM(H37:M37) -> 9.9 | AA37: 100 | AB37: 0 | AC37: =+H37*AB37 -> 0 | AD37: 0 | AE37: =+H37*AD37 -> 0 | AF37: =+AE37*2 -> 0 | AG37: 0 | AH37: 0 | AI37: CTD T.MÉXICO | AJ37: BLANCO | AQ37: 300
B38: LENNOX 1 | C38: SAIRA MORALES | D38: 626433-01 | E38: C - 1/2 | F38: 0.028 | G38: 0.131 | H38: 0 | I38: 0 | J38: 0 | N38: =+H38+I38+J38+K38+L38+M38-SUM(O38:Y38) -> 0 | Z38: =+G38*SUM(H38:M38) -> 0 | AA38: 100 | AB38: 0 | AC38: =+H38*AB38 -> 0 | AD38: 0 | AE38: =+H38*AD38 -> 0 | AF38: =+AE38*2 -> 0 | AG38: 0 | AH38: 0 | AI38: CTD T.MÉXICO | AJ38: BLANCO | AQ38: 0
B39: LENNOX 1 | C39: SAIRA MORALES | D39: 627175-01 | E39: C - 1/2 | F39: 0.028 | G39: 0.094 | H39: 0 | I39: 0 | J39: 0 | N39: =+H39+I39+J39+K39+L39+M39-SUM(O39:Y39) -> 0 | Z39: =+G39*SUM(H39:M39) -> 0 | AA39: 100 | AB39: 0 | AC39: =+H39*AB39 -> 0 | AD39: 0 | AE39: =+H39*AD39 -> 0 | AF39: =+AE39*2 -> 0 | AG39: 0 | AH39: 0 | AI39: CTD T.MÉXICO | AJ39: BLANCO | AQ39: 0
B40: LENNOX 1 | C40: SAIRA MORALES | D40: 627021-01 | E40: C - 1/2 | F40: 0.028 | G40: 0.122 | H40: 0 | I40: 0 | J40: 0 | N40: =+H40+I40+J40+K40+L40+M40-SUM(O40:Y40) -> 0 | Z40: =+G40*SUM(H40:M40) -> 0 | AA40: 100 | AB40: 0 | AC40: =+H40*AB40 -> 0 | AD40: 0 | AE40: =+H40*AD40 -> 0 | AF40: =+AE40*2 -> 0 | AG40: 0 | AH40: 0 | AI40: CTD T.MÉXICO | AJ40: BLANCO | AQ40: 0
B41: LENNOX 1 | C41: SAIRA MORALES | D41: 613366-01 | E41: C - 1/2 | F41: 0.028 | G41: 0.101 | H41: 200 | I41: 0 | J41: 0 | N41: =+H41+I41+J41+K41+L41+M41-SUM(O41:Y41) -> -3 | S41: 203 | Z41: =+G41*SUM(H41:M41) -> 20.2 | AA41: 100 | AB41: 0 | AC41: =+H41*AB41 -> 0 | AD41: 0 | AE41: =+H41*AD41 -> 0 | AF41: =+AE41*2 -> 0 | AG41: 0 | AH41: 0 | AI41: CTD T.MÉXICO | AJ41: BLANCO | AQ41: 0
...

Sheet SEMANA 32
B2: DÍA | C2: TURNO
B3: =TODAY() -> 46309 | C3: A | D3: X | H3: PROGRAMA
C4: B | H4: SEMANA | I4: Convertirlo a horas | O4: 46237 | Q4: 46238 | S4: 46239 | U4: 46240 | W4: 46241 | Y4: Ag1
B5: CLIENTE | C5: DESTINO | D5: NÚMERO DE PARTE | E5: DIAMETRO | F5: PARED | G5: PESO | H5: 32 | I5: W31 | J5: W32 | K5: Ag3 | L5: Ag4 | N5: BALANCE | O5: A | P5: B | Q5: A | R5: B | S5: A | T5: B | U5: A | V5: B | W5: A | X5: B | Y5: AYB | Z5: KG | AA5: STD. | AB5: SWITCH | AC5: SWITCH | AD5: BRACKET | AE5: BRACKET | AF5: PIJA | AG5: VALVULA | AH5: CANT. VAL. | AI5: CAJA | AJ5: HOJA COLOR | AL5: Row Labels | AM5: Sum of CANT. VAL.
B6: LENNOX 1 | C6: SAIRA MORALES | D6: 625994-01 | E6: A - 3/8 | F6: 0.42 | G6: 0.42 | I6: 3515 | J6: 2600 | N6: =+H6+I6+J6+K6+L6+M6-SUM(O6:Y6) -> 3365 | P6: 1500 | T6: 500 | X6: 750 | Z6: =+G6*SUM(H6:M6) -> 2568.3 | AA6: 1000 | AB6: 0 | AC6: =+H6*AB6 -> 0 | AD6: 0 | AE6: =+H6*AD6 -> 0 | AF6: =+AE6*2 -> 0 | AG6: 0 | AH6: 0 | AI6: CTD T.MÉXICO | AJ6: BLANCO | AL6: 0 | AM6: 0 | AQ6: 5600
B7: LENNOX 1 | C7: SAIRA MORALES | D7: 627512-01 | E7: A - 3/8 | F7: 0.42 | G7: 0.42 | I7: 6076 | J7: 1200 | N7: =+H7+I7+J7+K7+L7+M7-SUM(O7:Y7) -> 3576 | P7: 800 | T7: 2700 | X7: 200 | Z7: =+G7*SUM(H7:M7) -> 3055.92 | AA7: 1000 | AB7: 0 | AC7: =+H7*AB7 -> 0 | AD7: 0 | AE7: =+H7*AD7 -> 0 | AF7: =+AE7*2 -> 0 | AG7: 0 | AH7: 0 | AI7: CTD T.MÉXICO | AJ7: BLANCO | AL7: 102831-10 | AM7: 128 | AQ7: 4338
B8: LENNOX 1 | C8: SAIRA MORALES | D8: 625967-01 | E8: A - 3/8 | F8: 0.42 | G8: 0.42 | I8: 672 | J8: 500 | N8: =+H8+I8+J8+K8+L8+M8-SUM(O8:Y8) -> 472 | X8: 700 | Z8: =+G8*SUM(H8:M8) -> 492.24 | AA8: 1000 | AB8: 0 | AC8: =+H8*AB8 -> 0 | AD8: 0 | AE8: =+H8*AD8 -> 0 | AF8: =+AE8*2 -> 0 | AG8: 0 | AH8: 0 | AI8: CTD T.MÉXICO | AJ8: BLANCO | AL8: 102831-11 | AM8: 0 | AQ8: 1300
B9: LENNOX 1 | C9: SAIRA MORALES | D9: 626309-01 | E9: A - 3/8 | F9: 0.42 | G9: 0.42 | I9: 0 | J9: 700 | N9: =+H9+I9+J9+K9+L9+M9-SUM(O9:Y9) -> 200 | T9: 500 | Z9: =+G9*SUM(H9:M9) -> 294 | AA9: 1000 | AB9: 0 | AC9: =+H9*AB9 -> 0 | AD9: 0 | AE9: =+H9*AD9 -> 0 | AF9: =+AE9*2 -> 0 | AG9: 0 | AH9: 0 | AI9: CTD T.MÉXICO | AJ9: BLANCO | AL9: 103881-02 | AM9: 864 | AQ9: 0
B10: LENNOX 1 | C10: SAIRA MORALES | D10: 625890-01 | E10: A - 3/8 | F10: 0.42 | G10: 0.42 | I10: 200 | J10: 500 | N10: =+H10+I10+J10+K10+L10+M10-SUM(O10:Y10) -> 700 | Z10: =+G10*SUM(H10:M10) -> 294 | AA10: 1000 | AB10: 0 | AC10: =+H10*AB10 -> 0 | AD10: 0 | AE10: =+H10*AD10 -> 0 | AF10: =+AE10*2 -> 0 | AG10: 0 | AH10: 0 | AI10: CTD T.MÉXICO | AJ10: BLANCO | AL10: 103881-03 | AM10: 0 | AQ10: 1000
B11: LENNOX 1 | C11: SAIRA MORALES | D11: 615991-01 | E11: A - 3/8 | F11: 0.42 | G11: 0.42 | I11: 1507 | J11: 600 | N11: =+H11+I11+J11+K11+L11+M11-SUM(O11:Y11) -> 573 | P11: 1534 | Z11: =+G11*SUM(H11:M11) -> 884.94 | AA11: 1000 | AB11: 0 | AC11: =+H11*AB11 -> 0 | AD11: 0 | AE11: =+H11*AD11 -> 0 | AF11: =+AE11*2 -> 0 | AG11: 0 | AH11: 0 | AI11: CTD T.MÉXICO | AJ11: BLANCO | AL11: 107892-03 | AM11: 7704 | AQ11: 1707
B12: LENNOX 1 | C12: SAIRA MORALES | D12: 626164-01 | E12: A - 3/8 | F12: 0.42 | G12: 0.42 | I12: 0 | J12: 0 | N12: =+H12+I12+J12+K12+L12+M12-SUM(O12:Y12) -> 0 | Z12: =+G12*SUM(H12:M12) -> 0 | AA12: 1000 | AB12: 0 | AC12: =+H12*AB12 -> 0 | AD12: 0 | AE12: =+H12*AD12 -> 0 | AF12: =+AE12*2 -> 0 | AG12: 0 | AH12: 0 | AI12: CTD T.MÉXICO | AJ12: BLANCO | AL12: 107892-04 | AM12: 3840 | AQ12: 0
B13: LENNOX 1 | C13: SAIRA MORALES | D13: 626121-01 | E13: C - 3/8 | F13: BUSCA | G13: 0.028 | H13: 2000 | I13: 0 | N13: =+H13+I13+J13+K13+L13+M13-SUM(O13:Y13) -> -200 | O13: 1000 | P13: 500 | Q13: 500 | R13: 200 | Z13: =+G13*SUM(H13:M13) -> 56 | AA13: 1000 | AB13: 0 | AC13: =+H13*AB13 -> 0 | AD13: 0 | AE13: =+H13*AD13 -> 0 | AF13: =+AE13*2 -> 0 | AG13: 0 | AH13: 0 | AI13: CTD T.MÉXICO | AJ13: BLANCO | AL13: 107905-06 | AM13: 1280 | AQ13: -3900
B14: LENNOX 1 | C14: SAIRA MORALES | D14: 625995-01 | E14: C - 3/8 | F14: 0.028 | G14: 0.028 | H14: 0 | I14: 0 | N14: =+H14+I14+J14+K14+L14+M14-SUM(O14:Y14) -> 0 | Z14: =+G14*SUM(H14:M14) -> 0 | AA14: 1000 | AB14: 0 | AC14: =+H14*AB14 -> 0 | AD14: 0 | AE14: =+H14*AD14 -> 0 | AF14: =+AE14*2 -> 0 | AG14: 0 | AH14: 0 | AI14: CTD T.MÉXICO | AJ14: BLANCO | AL14: 107905-07 | AM14: 384 | AQ14: -2966
B15: LENNOX 1 | C15: SAIRA MORALES | D15: 615380-01 | E15: C - 3/8 | F15: 0.028 | G15: 0.028 | H15: 2500 | I15: 0 | N15: =+H15+I15+J15+K15+L15+M15-SUM(O15:Y15) -> -500 | Q15: 300 | Y15: 2700 | Z15: =+G15*SUM(H15:M15) -> 70 | AA15: 1000 | AB15: 0 | AC15: =+H15*AB15 -> 0 | AD15: 0 | AE15: =+H15*AD15 -> 0 | AF15: =+AE15*2 -> 0 | AG15: 0 | AH15: 0 | AI15: CTD T.MÉXICO | AJ15: BLANCO | AL15: Grand Total | AM15: 14200 | AQ15: 2400
