Workbook

Sheet .
A1: P
C2: RHEEM
B6: REPORTE DE PIEZAS - MÁQUINAS INTEGRADORAS (HELIAN)
B8: CLIENTE | C8: DESTINO | D8: NÚMERO DE PARTE | E8: DIAMETRO | F8: CANTIDAD | H8: CLIENTE | I8: DESTINO | J8: NÚMERO DE PARTE | K8: DIAMETRO | L8: CANTIDAD | N8: CLIENTE | O8: DESTINO | P8: NÚMERO DE PARTE | Q8: DIAMETRO | R8: CANTIDAD
B9: RHEEM TRANSFERENCIA | C9: EZO / MIRIAM | D9: 82-104987-15 | E9: 0.25 | H9: RHEEM FALCON | I9: EZO / MIRIAM | J9: 82-109026-21 | K9: 0.25 | N9: RHEEM NIPLES | O9: EZO / MIRIAM | P9: 82-100351-02H3 | Q9: 0.3125
B10: RHEEM TRANSFERENCIA | C10: EZO / MIRIAM | D10: 82-104987-13 | E10: 0.25 | H10: RHEEM FALCON | I10: EZO / MIRIAM | J10: 82-109026-22 | K10: 0.25 | N10: RHEEM NIPLES | O10: EZO / MIRIAM | P10: 82-100351-02H4 | Q10: 0.3125
B11: RHEEM TRANSFERENCIA | C11: EZO / MIRIAM | D11: 82-104987-14 | E11: 0.25 | H11: RHEEM FALCON | I11: EZO / MIRIAM | J11: 82-110968-01 | K11: 0.25 | N11: RHEEM NIPLES | O11: EZO / MIRIAM | P11: 82-100351-03H3 | Q11: 0.3125
B12: RHEEM TRANSFERENCIA | C12: EZO / MIRIAM | D12: 82-104986-88 | E12: 0.375 | H12: RHEEM FALCON | I12: EZO / MIRIAM | J12: 82-105077-15 | K12: 0.375 | N12: RHEEM NIPLES | O12: EZO / MIRIAM | P12: 82-100351-03H4 | Q12: 0.3125
B13: RHEEM TRANSFERENCIA | C13: EZO / MIRIAM | D13: 82-104986-61 | E13: 0.375 | H13: RHEEM FALCON | I13: EZO / MIRIAM | J13: 82-105077-16 | K13: 0.375 | N13: RHEEM NIPLES | O13: EZO / MIRIAM | P13: 82-100351-04H3 | Q13: 0.3125
B14: RHEEM TRANSFERENCIA | C14: EZO / MIRIAM | D14: 82-104986-59 | E14: 0.375 | H14: RHEEM FALCON | I14: EZO / MIRIAM | J14: 82-105077-17 | K14: 0.375 | N14: RHEEM NIPLES | O14: EZO / MIRIAM | P14: 82-100351-04H4 | Q14: 0.3125
B15: RHEEM TRANSFERENCIA | C15: EZO / MIRIAM | D15: 82-104986-72 | E15: 0.375 | H15: RHEEM FALCON | I15: EZO / MIRIAM | J15: 82-105077-18 | K15: 0.375 | N15: RHEEM NIPLES | O15: EZO / MIRIAM | P15: 82-101183-02H3 | Q15: 0.3125
B16: RHEEM TRANSFERENCIA | C16: EZO / MIRIAM | D16: 82-104986-89 | E16: 0.375 | H16: RHEEM FALCON | I16: EZO / MIRIAM | J16: 82-104985-49 | K16: 0.5 | N16: RHEEM NIPLES | O16: EZO / MIRIAM | P16: 82-101183-02H4 | Q16: 0.3125
B17: RHEEM TRANSFERENCIA | C17: EZO / MIRIAM | D17: 82-104986-71 | E17: 0.375 | H17: RHEEM FALCON | I17: EZO / MIRIAM | J17: 82-104985-52 | K17: 0.5 | N17: RHEEM NIPLES | O17: EZO / MIRIAM | P17: 82-101183-02H5 | Q17: 0.3125
B18: RHEEM TRANSFERENCIA | C18: EZO / MIRIAM | D18: 82-104986-60 | E18: 0.375 | H18: RHEEM FALCON | I18: EZO / MIRIAM | J18: 82-104985-53 | K18: 0.5 | N18: RHEEM NIPLES | O18: EZO / MIRIAM | P18: 82-101183-02H6 | Q18: 0.3125
B19: RHEEM TRANSFERENCIA | C19: EZO / MIRIAM | D19: 82-104985-41 | E19: 0.5 | H19: RHEEM FALCON | I19: EZO / MIRIAM | J19: 82-104985-54 | K19: 0.5 | N19: RHEEM NIPLES | O19: EZO / MIRIAM | P19: 82-101183-02H7 | Q19: 0.3125
B20: RHEEM TRANSFERENCIA | C20: EZO / MIRIAM | D20: 82-104985-25 | E20: 0.5 | H20: RHEEM FALCON | I20: EZO / MIRIAM | J20: 82-104985-55 | K20: 0.5 | N20: RHEEM NIPLES | O20: EZO / MIRIAM | P20: 82-101183-02H8 | Q20: 0.3125
... B33: RHEEM TRANSFERENCIA | C33: EZO / MIRIAM | D33: 82-104895-07 | E33: 0.5 | H33: RHEEM FALCON | I33: EZO / MIRIAM | J33: 82-110951-01 | K33: 0.875 | N33: RHEEM NIPLES | O33: EZO / MIRIAM | P33: 82-101183-16H9 | Q33: 0.3125
B34: RHEEM TRANSFERENCIA | C34: EZO / MIRIAM | D34: 82-104895-17 | E34: 0.5 | N34: RHEEM NIPLES | O34: EZO / MIRIAM | P34: 82-101183-16H10 | Q34: 0.3125
B35: RHEEM TRANSFERENCIA | C35: EZO / MIRIAM | D35: 82-104894-13 | E35: 0.5 | H35: RHEEM CIP-3501 | I35: CLIENTE | J35: 82-111023-02 | K35: 0.375 | N35: RHEEM NIPLES | O35: EZO / MIRIAM | P35: 82-101183-16H11 | Q35: 0.3125
B36: RHEEM TRANSFERENCIA | C36: EZO / MIRIAM | D36: 82-104894-01 | E36: 0.5 | H36: RHEEM CIP-3501 | I36: CLIENTE | J36: 82-111023-04 | K36: 0.375
B37: RHEEM TRANSFERENCIA | C37: EZO / MIRIAM | D37: 82-104895-01 | E37: 0.5 | H37: RHEEM CIP-3501 | I37: CLIENTE | J37: 82-111023-10 | K37: 0.375
B38: RHEEM TRANSFERENCIA | C38: EZO / MIRIAM | D38: 82-104894-09 | E38: 0.5 | H38: RHEEM CIP-3501 | I38: CLIENTE | J38: 82-110915-01 | K38: 0.75
B39: RHEEM TRANSFERENCIA | C39: EZO / MIRIAM | D39: 82-104984-140 | E39: 0.625 | H39: RHEEM CIP-3501 | I39: CLIENTE | J39: 82-110915-02 | K39: 0.75
B40: RHEEM TRANSFERENCIA | C40: EZO / MIRIAM | D40: 82-104984-116 | E40: 0.625 | H40: RHEEM CIP-3501 | I40: CLIENTE | J40: 82-110915-06 | K40: 0.75
B41: RHEEM TRANSFERENCIA | C41: EZO / MIRIAM | D41: 82-104984-142 | E41: 0.625 | H41: RHEEM CIP-3501 | I41: CLIENTE | J41: 82-110915-09 | K41: 0.75
B42: RHEEM TRANSFERENCIA | C42: EZO / MIRIAM | D42: 82-104984-114 | E42: 0.75 | H42: RHEEM CIP-3501 | I42: CLIENTE | J42: 82-110915-11 | K42: 0.75
B43: RHEEM TRANSFERENCIA | C43: EZO / MIRIAM | D43: 82-104984-147 | E43: 0.75 | H43: RHEEM CIP-3501 | I43: CLIENTE | J43: 82-110915-13 | K43: 0.75
B44: RHEEM TRANSFERENCIA | C44: EZO / MIRIAM | D44: 82-104984-122 | E44: 0.75 | H44: RHEEM CIP-3501 | I44: CLIENTE | J44: 82-110915-16 | K44: 0.75
B45: RHEEM TRANSFERENCIA | C45: EZO / MIRIAM | D45: 82-104984-189 | E45: 0.75 | H45: RHEEM CIP-3501 | I45: CLIENTE | J45: 82-110915-04 | K45: 0.875
B46: RHEEM TRANSFERENCIA | C46: EZO / MIRIAM | D46: 82-104984-190 | E46: 0.75 | H46: RHEEM CIP-3501 | I46: CLIENTE | J46: 82-110915-10 | K46: 0.875
B47: RHEEM TRANSFERENCIA | C47: EZO / MIRIAM | D47: 82-104984-124 | E47: 0.75 | H47: RHEEM CIP-3501 | I47: CLIENTE | J47: 82-110915-20 | K47: 0.875
B48: RHEEM TRANSFERENCIA | C48: EZO / MIRIAM | D48: 82-104984-143 | E48: 0.75 | H48: RHEEM CIP-3501 | I48: CLIENTE | J48: 82-110915-22 | K48: 0.875
B49: RHEEM TRANSFERENCIA | C49: EZO / MIRIAM | D49: 82-100351-01 | E49: 0.75
B50: RHEEM TRANSFERENCIA | C50: EZO / MIRIAM | D50: 82-103227-15 | E50: 0.75
B51: RHEEM TRANSFERENCIA | C51: EZO / MIRIAM | D51: 82-100351-02 | E51: 0.75
B52: RHEEM TRANSFERENCIA | C52: EZO / MIRIAM | D52: 82-104982-06 | E52: 0.75
B53: RHEEM TRANSFERENCIA | C53: EZO / MIRIAM | D53: 82-100797-02 | E53: 0.75
B54: RHEEM TRANSFERENCIA | C54: EZO / MIRIAM | D54: 82-100797-01 | E54: 0.75
B55: RHEEM TRANSFERENCIA | C55: EZO / MIRIAM | D55: 82-100797-06 | E55: 0.75
B56: RHEEM TRANSFERENCIA | C56: EZO / MIRIAM | D56: 82-101183-03 | E56: 0.75
...

Sheet EMPAQUE
C2: RHEEM
B6: REPORTE DE PIEZAS ENTREGADAS (EMPAQUE)
B8: TRANSFERENCIA | H8: TRANSFERENCIA | N8: CIP
B9: CLIENTE | C9: DESTINO | D9: NÚMERO DE PARTE | E9: DIAMETRO | F9: CANTIDAD | H9: CLIENTE | I9: DESTINO | J9: NÚMERO DE PARTE | K9: DIAMETRO | L9: CANTIDAD | N9: CLIENTE | O9: DESTINO | P9: NÚMERO DE PARTE | Q9: DIAMETRO | R9: CANTIDAD
B10: RHEEM TRANSFERENCIA | C10: EZO / MIRIAM | D10: 82-104987-15 | E10: 0.25 | H10: RHEEM TRANSFERENCIA | I10: EZO / MIRIAM | J10: 82-104984-156 | K10: 0.875 | N10: RHEEM CIP-3501 | O10: CLIENTE | P10: 82-111023-02 | Q10: 0.375
B11: RHEEM TRANSFERENCIA | C11: EZO / MIRIAM | D11: 82-104987-13 | E11: 0.25 | H11: RHEEM TRANSFERENCIA | I11: EZO / MIRIAM | J11: 82-104984-126 | K11: 0.875 | N11: RHEEM CIP-3501 | O11: CLIENTE | P11: 82-111023-04 | Q11: 0.375
B12: RHEEM TRANSFERENCIA | C12: EZO / MIRIAM | D12: 82-104987-14 | E12: 0.25 | H12: RHEEM TRANSFERENCIA | I12: EZO / MIRIAM | J12: 82-104984-191 | K12: 0.875 | N12: RHEEM CIP-3501 | O12: CLIENTE | P12: 82-111023-10 | Q12: 0.375
B13: RHEEM TRANSFERENCIA | C13: EZO / MIRIAM | D13: 82-104986-88 | E13: 0.375 | H13: RHEEM TRANSFERENCIA | I13: EZO / MIRIAM | J13: 82-108426-01 | K13: 0.875 | N13: RHEEM CIP-3501 | O13: CLIENTE | P13: 82-110915-01 | Q13: 0.75
B14: RHEEM TRANSFERENCIA | C14: EZO / MIRIAM | D14: 82-104986-61 | E14: 0.375 | H14: RHEEM TRANSFERENCIA | I14: EZO / MIRIAM | J14: 82-100351-03 | K14: 0.875 | N14: RHEEM CIP-3501 | O14: CLIENTE | P14: 82-110915-02 | Q14: 0.75
B15: RHEEM TRANSFERENCIA | C15: EZO / MIRIAM | D15: 82-104986-59 | E15: 0.375 | H15: RHEEM TRANSFERENCIA | I15: EZO / MIRIAM | J15: 82-108451-01 | K15: 0.875 | N15: RHEEM CIP-3501 | O15: CLIENTE | P15: 82-110915-06 | Q15: 0.75
B16: RHEEM TRANSFERENCIA | C16: EZO / MIRIAM | D16: 82-104986-72 | E16: 0.375 | H16: RHEEM TRANSFERENCIA | I16: EZO / MIRIAM | J16: 82-108430-01 | K16: 0.875 | N16: RHEEM CIP-3501 | O16: CLIENTE | P16: 82-110915-09 | Q16: 0.75
B17: RHEEM TRANSFERENCIA | C17: EZO / MIRIAM | D17: 82-104986-89 | E17: 0.375 | H17: RHEEM TRANSFERENCIA | I17: EZO / MIRIAM | J17: 82-100797-04 | K17: 0.875 | N17: RHEEM CIP-3501 | O17: CLIENTE | P17: 82-110915-11 | Q17: 0.75
B18: RHEEM TRANSFERENCIA | C18: EZO / MIRIAM | D18: 82-104986-71 | E18: 0.375 | H18: RHEEM TRANSFERENCIA | I18: EZO / MIRIAM | J18: 82-100351-04 | K18: 0.875 | N18: RHEEM CIP-3501 | O18: CLIENTE | P18: 82-110915-13 | Q18: 0.75
B19: RHEEM TRANSFERENCIA | C19: EZO / MIRIAM | D19: 82-104986-60 | E19: 0.375 | H19: RHEEM TRANSFERENCIA | I19: EZO / MIRIAM | J19: 82-108430-03 | K19: 0.875 | N19: RHEEM CIP-3501 | O19: CLIENTE | P19: 82-110915-16 | Q19: 0.75
B20: RHEEM TRANSFERENCIA | C20: EZO / MIRIAM | D20: 82-104985-41 | E20: 0.5 | H20: RHEEM TRANSFERENCIA | I20: EZO / MIRIAM | J20: 82-104984-46 | K20: 0.875 | N20: RHEEM CIP-3501 | O20: CLIENTE | P20: 82-110915-04 | Q20: 0.875
B21: RHEEM TRANSFERENCIA | C21: EZO / MIRIAM | D21: 82-104985-25 | E21: 0.5 | H21: RHEEM TRANSFERENCIA | I21: EZO / MIRIAM | J21: 82-104984-216 | K21: 0.875 | N21: RHEEM CIP-3501 | O21: CLIENTE | P21: 82-110915-10 | Q21: 0.875
... B23: RHEEM TRANSFERENCIA | C23: EZO / MIRIAM | D23: 82-104985-39 | E23: 0.5 | H23: RHEEM TRANSFERENCIA | I23: EZO / MIRIAM | J23: 82-104982-04 | K23: 0.875 | N23: RHEEM CIP-3501 | O23: CLIENTE | P23: 82-110915-22 | Q23: 0.875
B24: RHEEM TRANSFERENCIA | C24: EZO / MIRIAM | D24: 82-108427-01 | E24: 0.5 | H24: RHEEM TRANSFERENCIA | I24: EZO / MIRIAM | J24: 82-104982-05 | K24: 0.875
B25: RHEEM TRANSFERENCIA | C25: EZO / MIRIAM | D25: 82-104748-69 | E25: 0.5 | H25: RHEEM TRANSFERENCIA | I25: EZO / MIRIAM | J25: 82-103015-09 | K25: 0.875
B26: RHEEM TRANSFERENCIA | C26: EZO / MIRIAM | D26: 82-104894-08 | E26: 0.5 | H26: RHEEM TRANSFERENCIA | I26: EZO / MIRIAM | J26: 82-106374-02 | K26: 0.875 | N26: NIPLES
B27: RHEEM TRANSFERENCIA | C27: EZO / MIRIAM | D27: 82-104894-02 | E27: 0.5 | H27: RHEEM TRANSFERENCIA | I27: EZO / MIRIAM | J27: 82-104982-08 | K27: 0.875 | N27: CLIENTE | O27: DESTINO | P27: NÚMERO DE PARTE | Q27: DIAMETRO | R27: CANTIDAD
B28: RHEEM TRANSFERENCIA | C28: EZO / MIRIAM | D28: 82-104895-02 | E28: 0.5 | H28: RHEEM TRANSFERENCIA | I28: EZO / MIRIAM | J28: 82-100797-05 | K28: 0.875 | N28: RHEEM NIPLES | O28: EZO / MIRIAM | P28: 82-100351-02H3 | Q28: 0.3125
B29: RHEEM TRANSFERENCIA | C29: EZO / MIRIAM | D29: 82-100797-16 | E29: 0.5 | H29: RHEEM TRANSFERENCIA | I29: EZO / MIRIAM | J29: 82-104982-03 | K29: 0.875 | N29: RHEEM NIPLES | O29: EZO / MIRIAM | P29: 82-100351-02H4 | Q29: 0.3125
B30: RHEEM TRANSFERENCIA | C30: EZO / MIRIAM | D30: 82-104895-06 | E30: 0.5 | H30: RHEEM TRANSFERENCIA | I30: EZO / MIRIAM | J30: 82-101183-16 | K30: 0.875 | N30: RHEEM NIPLES | O30: EZO / MIRIAM | P30: 82-100351-03H3 | Q30: 0.3125
B31: RHEEM TRANSFERENCIA | C31: EZO / MIRIAM | D31: 82-104894-07 | E31: 0.5 | H31: RHEEM TRANSFERENCIA | I31: EZO / MIRIAM | J31: 82-104895-09 | K31: 0.875 | N31: RHEEM NIPLES | O31: EZO / MIRIAM | P31: 82-100351-03H4 | Q31: 0.3125
B32: RHEEM TRANSFERENCIA | C32: EZO / MIRIAM | D32: 82-100797-23 | E32: 0.5 | H32: RHEEM TRANSFERENCIA | I32: EZO / MIRIAM | J32: 82-109836-01 | K32: 0.875 | N32: RHEEM NIPLES | O32: EZO / MIRIAM | P32: 82-100351-04H3 | Q32: 0.3125
B33: RHEEM TRANSFERENCIA | C33: EZO / MIRIAM | D33: 82-104894-10 | E33: 0.5 | N33: RHEEM NIPLES | O33: EZO / MIRIAM | P33: 82-100351-04H4 | Q33: 0.3125
B34: RHEEM TRANSFERENCIA | C34: EZO / MIRIAM | D34: 82-104895-07 | E34: 0.5 | H34: FALCON | N34: RHEEM NIPLES | O34: EZO / MIRIAM | P34: 82-101183-02H3 | Q34: 0.3125
B35: RHEEM TRANSFERENCIA | C35: EZO / MIRIAM | D35: 82-104895-17 | E35: 0.5 | H35: CLIENTE | I35: DESTINO | J35: NÚMERO DE PARTE | K35: DIAMETRO | L35: CANTIDAD | N35: RHEEM NIPLES | O35: EZO / MIRIAM | P35: 82-101183-02H4 | Q35: 0.3125
B36: RHEEM TRANSFERENCIA | C36: EZO / MIRIAM | D36: 82-104894-13 | E36: 0.5 | H36: RHEEM FALCON | I36: EZO / MIRIAM | J36: 82-109026-21 | K36: 0.25 | N36: RHEEM NIPLES | O36: EZO / MIRIAM | P36: 82-101183-02H5 | Q36: 0.3125
B37: RHEEM TRANSFERENCIA | C37: EZO / MIRIAM | D37: 82-104894-01 | E37: 0.5 | H37: RHEEM FALCON | I37: EZO / MIRIAM | J37: 82-109026-22 | K37: 0.25 | N37: RHEEM NIPLES | O37: EZO / MIRIAM | P37: 82-101183-02H6 | Q37: 0.3125
B38: RHEEM TRANSFERENCIA | C38: EZO / MIRIAM | D38: 82-104895-01 | E38: 0.5 | H38: RHEEM FALCON | I38: EZO / MIRIAM | J38: 82-110968-01 | K38: 0.25 | N38: RHEEM NIPLES | O38: EZO / MIRIAM | P38: 82-101183-02H7 | Q38: 0.3125
B39: RHEEM TRANSFERENCIA | C39: EZO / MIRIAM | D39: 82-104894-09 | E39: 0.5 | H39: RHEEM FALCON | I39: EZO / MIRIAM | J39: 82-105077-15 | K39: 0.375 | N39: RHEEM NIPLES | O39: EZO / MIRIAM | P39: 82-101183-02H8 | Q39: 0.3125
B40: RHEEM TRANSFERENCIA | C40: EZO / MIRIAM | D40: 82-104984-140 | E40: 0.625 | H40: RHEEM FALCON | I40: EZO / MIRIAM | J40: 82-105077-16 | K40: 0.375 | N40: RHEEM NIPLES | O40: EZO / MIRIAM | P40: 82-101183-03H3 | Q40: 0.3125
B41: RHEEM TRANSFERENCIA | C41: EZO / MIRIAM | D41: 82-104984-116 | E41: 0.625 | H41: RHEEM FALCON | I41: EZO / MIRIAM | J41: 82-105077-17 | K41: 0.375 | N41: RHEEM NIPLES | O41: EZO / MIRIAM | P41: 82-101183-03H4 | Q41: 0.3125
B42: RHEEM TRANSFERENCIA | C42: EZO / MIRIAM | D42: 82-104984-142 | E42: 0.625 | H42: RHEEM FALCON | I42: EZO / MIRIAM | J42: 82-105077-18 | K42: 0.375 | N42: RHEEM NIPLES | O42: EZO / MIRIAM | P42: 82-101183-03H5 | Q42: 0.3125
B43: RHEEM TRANSFERENCIA | C43: EZO / MIRIAM | D43: 82-104984-114 | E43: 0.75 | H43: RHEEM FALCON | I43: EZO / MIRIAM | J43: 82-104985-49 | K43: 0.5 | N43: RHEEM NIPLES | O43: EZO / MIRIAM | P43: 82-101183-03H6 | Q43: 0.3125
B44: RHEEM TRANSFERENCIA | C44: EZO / MIRIAM | D44: 82-104984-147 | E44: 0.75 | H44: RHEEM FALCON | I44: EZO / MIRIAM | J44: 82-104985-52 | K44: 0.5 | N44: RHEEM NIPLES | O44: EZO / MIRIAM | P44: 82-101183-03H7 | Q44: 0.3125
B45: RHEEM TRANSFERENCIA | C45: EZO / MIRIAM | D45: 82-104984-122 | E45: 0.75 | H45: RHEEM FALCON | I45: EZO / MIRIAM | J45: 82-104985-53 | K45: 0.5 | N45: RHEEM NIPLES | O45: EZO / MIRIAM | P45: 82-101183-03H8 | Q45: 0.3125
B46: RHEEM TRANSFERENCIA | C46: EZO / MIRIAM | D46: 82-104984-189 | E46: 0.75 | H46: RHEEM FALCON | I46: EZO / MIRIAM | J46: 82-104985-54 | K46: 0.5 | N46: RHEEM NIPLES | O46: EZO / MIRIAM | P46: 82-101183-16H3 | Q46: 0.3125
...

Sheet HELIAN 
C2: RHEEM
B6: REPORTE DE PIEZAS - MÁQUINAS INTEGRADORAS (HELIAN)
B8: TRANSFERENCIA | H8: TRANSFERENCIA | N8: CIP
B9: CLIENTE | C9: DESTINO | D9: NÚMERO DE PARTE | E9: DIAMETRO | F9: CANTIDAD | H9: CLIENTE | I9: DESTINO | J9: NÚMERO DE PARTE | K9: DIAMETRO | L9: CANTIDAD | N9: CLIENTE | O9: DESTINO | P9: NÚMERO DE PARTE | Q9: DIAMETRO | R9: CANTIDAD
B10: RHEEM TRANSFERENCIA | C10: EZO / MIRIAM | D10: 82-104987-15 | E10: 0.25 | H10: RHEEM TRANSFERENCIA | I10: EZO / MIRIAM | J10: 82-104984-156 | K10: 0.875 | N10: RHEEM CIP-3501 | O10: CLIENTE | P10: 82-111023-02 | Q10: 0.375
B11: RHEEM TRANSFERENCIA | C11: EZO / MIRIAM | D11: 82-104987-13 | E11: 0.25 | H11: RHEEM TRANSFERENCIA | I11: EZO / MIRIAM | J11: 82-104984-126 | K11: 0.875 | N11: RHEEM CIP-3501 | O11: CLIENTE | P11: 82-111023-04 | Q11: 0.375
B12: RHEEM TRANSFERENCIA | C12: EZO / MIRIAM | D12: 82-104987-14 | E12: 0.25 | H12: RHEEM TRANSFERENCIA | I12: EZO / MIRIAM | J12: 82-104984-191 | K12: 0.875 | N12: RHEEM CIP-3501 | O12: CLIENTE | P12: 82-111023-10 | Q12: 0.375
B13: RHEEM TRANSFERENCIA | C13: EZO / MIRIAM | D13: 82-104986-88 | E13: 0.375 | H13: RHEEM TRANSFERENCIA | I13: EZO / MIRIAM | J13: 82-108426-01 | K13: 0.875 | N13: RHEEM CIP-3501 | O13: CLIENTE | P13: 82-110915-01 | Q13: 0.75
B14: RHEEM TRANSFERENCIA | C14: EZO / MIRIAM | D14: 82-104986-61 | E14: 0.375 | H14: RHEEM TRANSFERENCIA | I14: EZO / MIRIAM | J14: 82-100351-03 | K14: 0.875 | N14: RHEEM CIP-3501 | O14: CLIENTE | P14: 82-110915-02 | Q14: 0.75
B15: RHEEM TRANSFERENCIA | C15: EZO / MIRIAM | D15: 82-104986-59 | E15: 0.375 | H15: RHEEM TRANSFERENCIA | I15: EZO / MIRIAM | J15: 82-108451-01 | K15: 0.875 | N15: RHEEM CIP-3501 | O15: CLIENTE | P15: 82-110915-06 | Q15: 0.75
B16: RHEEM TRANSFERENCIA | C16: EZO / MIRIAM | D16: 82-104986-72 | E16: 0.375 | H16: RHEEM TRANSFERENCIA | I16: EZO / MIRIAM | J16: 82-108430-01 | K16: 0.875 | N16: RHEEM CIP-3501 | O16: CLIENTE | P16: 82-110915-09 | Q16: 0.75
B17: RHEEM TRANSFERENCIA | C17: EZO / MIRIAM | D17: 82-104986-89 | E17: 0.375 | H17: RHEEM TRANSFERENCIA | I17: EZO / MIRIAM | J17: 82-100797-04 | K17: 0.875 | N17: RHEEM CIP-3501 | O17: CLIENTE | P17: 82-110915-11 | Q17: 0.75
B18: RHEEM TRANSFERENCIA | C18: EZO / MIRIAM | D18: 82-104986-71 | E18: 0.375 | H18: RHEEM TRANSFERENCIA | I18: EZO / MIRIAM | J18: 82-100351-04 | K18: 0.875 | N18: RHEEM CIP-3501 | O18: CLIENTE | P18: 82-110915-13 | Q18: 0.75
B19: RHEEM TRANSFERENCIA | C19: EZO / MIRIAM | D19: 82-104986-60 | E19: 0.375 | H19: RHEEM TRANSFERENCIA | I19: EZO / MIRIAM | J19: 82-108430-03 | K19: 0.875 | N19: RHEEM CIP-3501 | O19: CLIENTE | P19: 82-110915-16 | Q19: 0.75
B20: RHEEM TRANSFERENCIA | C20: EZO / MIRIAM | D20: 82-104985-41 | E20: 0.5 | H20: RHEEM TRANSFERENCIA | I20: EZO / MIRIAM | J20: 82-104984-46 | K20: 0.875 | N20: RHEEM CIP-3501 | O20: CLIENTE | P20: 82-110915-04 | Q20: 0.875
B21: RHEEM TRANSFERENCIA | C21: EZO / MIRIAM | D21: 82-104985-25 | E21: 0.5 | H21: RHEEM TRANSFERENCIA | I21: EZO / MIRIAM | J21: 82-104984-216 | K21: 0.875 | N21: RHEEM CIP-3501 | O21: CLIENTE | P21: 82-110915-10 | Q21: 0.875
... B23: RHEEM TRANSFERENCIA | C23: EZO / MIRIAM | D23: 82-104985-39 | E23: 0.5 | H23: RHEEM TRANSFERENCIA | I23: EZO / MIRIAM | J23: 82-104982-04 | K23: 0.875 | N23: RHEEM CIP-3501 | O23: CLIENTE | P23: 82-110915-22 | Q23: 0.875
B24: RHEEM TRANSFERENCIA | C24: EZO / MIRIAM | D24: 82-108427-01 | E24: 0.5 | H24: RHEEM TRANSFERENCIA | I24: EZO / MIRIAM | J24: 82-104982-05 | K24: 0.875
B25: RHEEM TRANSFERENCIA | C25: EZO / MIRIAM | D25: 82-104748-69 | E25: 0.5 | H25: RHEEM TRANSFERENCIA | I25: EZO / MIRIAM | J25: 82-103015-09 | K25: 0.875
B26: RHEEM TRANSFERENCIA | C26: EZO / MIRIAM | D26: 82-104894-08 | E26: 0.5 | H26: RHEEM TRANSFERENCIA | I26: EZO / MIRIAM | J26: 82-106374-02 | K26: 0.875 | N26: NIPLES
B27: RHEEM TRANSFERENCIA | C27: EZO / MIRIAM | D27: 82-104894-02 | E27: 0.5 | H27: RHEEM TRANSFERENCIA | I27: EZO / MIRIAM | J27: 82-104982-08 | K27: 0.875 | N27: CLIENTE | O27: DESTINO | P27: NÚMERO DE PARTE | Q27: DIAMETRO | R27: CANTIDAD
B28: RHEEM TRANSFERENCIA | C28: EZO / MIRIAM | D28: 82-104895-02 | E28: 0.5 | H28: RHEEM TRANSFERENCIA | I28: EZO / MIRIAM | J28: 82-100797-05 | K28: 0.875 | N28: RHEEM NIPLES | O28: EZO / MIRIAM | P28: 82-100351-02H3 | Q28: 0.3125
B29: RHEEM TRANSFERENCIA | C29: EZO / MIRIAM | D29: 82-100797-16 | E29: 0.5 | H29: RHEEM TRANSFERENCIA | I29: EZO / MIRIAM | J29: 82-104982-03 | K29: 0.875 | N29: RHEEM NIPLES | O29: EZO / MIRIAM | P29: 82-100351-02H4 | Q29: 0.3125
B30: RHEEM TRANSFERENCIA | C30: EZO / MIRIAM | D30: 82-104895-06 | E30: 0.5 | H30: RHEEM TRANSFERENCIA | I30: EZO / MIRIAM | J30: 82-101183-16 | K30: 0.875 | N30: RHEEM NIPLES | O30: EZO / MIRIAM | P30: 82-100351-03H3 | Q30: 0.3125
B31: RHEEM TRANSFERENCIA | C31: EZO / MIRIAM | D31: 82-104894-07 | E31: 0.5 | H31: RHEEM TRANSFERENCIA | I31: EZO / MIRIAM | J31: 82-104895-09 | K31: 0.875 | N31: RHEEM NIPLES | O31: EZO / MIRIAM | P31: 82-100351-03H4 | Q31: 0.3125
B32: RHEEM TRANSFERENCIA | C32: EZO / MIRIAM | D32: 82-100797-23 | E32: 0.5 | H32: RHEEM TRANSFERENCIA | I32: EZO / MIRIAM | J32: 82-109836-01 | K32: 0.875 | N32: RHEEM NIPLES | O32: EZO / MIRIAM | P32: 82-100351-04H3 | Q32: 0.3125
B33: RHEEM TRANSFERENCIA | C33: EZO / MIRIAM | D33: 82-104894-10 | E33: 0.5 | N33: RHEEM NIPLES | O33: EZO / MIRIAM | P33: 82-100351-04H4 | Q33: 0.3125
B34: RHEEM TRANSFERENCIA | C34: EZO / MIRIAM | D34: 82-104895-07 | E34: 0.5 | H34: FALCON | N34: RHEEM NIPLES | O34: EZO / MIRIAM | P34: 82-101183-02H3 | Q34: 0.3125
B35: RHEEM TRANSFERENCIA | C35: EZO / MIRIAM | D35: 82-104895-17 | E35: 0.5 | H35: CLIENTE | I35: DESTINO | J35: NÚMERO DE PARTE | K35: DIAMETRO | L35: CANTIDAD | N35: RHEEM NIPLES | O35: EZO / MIRIAM | P35: 82-101183-02H4 | Q35: 0.3125
B36: RHEEM TRANSFERENCIA | C36: EZO / MIRIAM | D36: 82-104894-13 | E36: 0.5 | H36: RHEEM FALCON | I36: EZO / MIRIAM | J36: 82-109026-21 | K36: 0.25 | N36: RHEEM NIPLES | O36: EZO / MIRIAM | P36: 82-101183-02H5 | Q36: 0.3125
B37: RHEEM TRANSFERENCIA | C37: EZO / MIRIAM | D37: 82-104894-01 | E37: 0.5 | H37: RHEEM FALCON | I37: EZO / MIRIAM | J37: 82-109026-22 | K37: 0.25 | N37: RHEEM NIPLES | O37: EZO / MIRIAM | P37: 82-101183-02H6 | Q37: 0.3125
B38: RHEEM TRANSFERENCIA | C38: EZO / MIRIAM | D38: 82-104895-01 | E38: 0.5 | H38: RHEEM FALCON | I38: EZO / MIRIAM | J38: 82-110968-01 | K38: 0.25 | N38: RHEEM NIPLES | O38: EZO / MIRIAM | P38: 82-101183-02H7 | Q38: 0.3125
B39: RHEEM TRANSFERENCIA | C39: EZO / MIRIAM | D39: 82-104894-09 | E39: 0.5 | H39: RHEEM FALCON | I39: EZO / MIRIAM | J39: 82-105077-15 | K39: 0.375 | N39: RHEEM NIPLES | O39: EZO / MIRIAM | P39: 82-101183-02H8 | Q39: 0.3125
B40: RHEEM TRANSFERENCIA | C40: EZO / MIRIAM | D40: 82-104984-140 | E40: 0.625 | H40: RHEEM FALCON | I40: EZO / MIRIAM | J40: 82-105077-16 | K40: 0.375 | N40: RHEEM NIPLES | O40: EZO / MIRIAM | P40: 82-101183-03H3 | Q40: 0.3125
B41: RHEEM TRANSFERENCIA | C41: EZO / MIRIAM | D41: 82-104984-116 | E41: 0.625 | H41: RHEEM FALCON | I41: EZO / MIRIAM | J41: 82-105077-17 | K41: 0.375 | N41: RHEEM NIPLES | O41: EZO / MIRIAM | P41: 82-101183-03H4 | Q41: 0.3125
B42: RHEEM TRANSFERENCIA | C42: EZO / MIRIAM | D42: 82-104984-142 | E42: 0.625 | H42: RHEEM FALCON | I42: EZO / MIRIAM | J42: 82-105077-18 | K42: 0.375 | N42: RHEEM NIPLES | O42: EZO / MIRIAM | P42: 82-101183-03H5 | Q42: 0.3125
B43: RHEEM TRANSFERENCIA | C43: EZO / MIRIAM | D43: 82-104984-114 | E43: 0.75 | H43: RHEEM FALCON | I43: EZO / MIRIAM | J43: 82-104985-49 | K43: 0.5 | N43: RHEEM NIPLES | O43: EZO / MIRIAM | P43: 82-101183-03H6 | Q43: 0.3125
B44: RHEEM TRANSFERENCIA | C44: EZO / MIRIAM | D44: 82-104984-147 | E44: 0.75 | H44: RHEEM FALCON | I44: EZO / MIRIAM | J44: 82-104985-52 | K44: 0.5 | N44: RHEEM NIPLES | O44: EZO / MIRIAM | P44: 82-101183-03H7 | Q44: 0.3125
B45: RHEEM TRANSFERENCIA | C45: EZO / MIRIAM | D45: 82-104984-122 | E45: 0.75 | H45: RHEEM FALCON | I45: EZO / MIRIAM | J45: 82-104985-53 | K45: 0.5 | N45: RHEEM NIPLES | O45: EZO / MIRIAM | P45: 82-101183-03H8 | Q45: 0.3125
B46: RHEEM TRANSFERENCIA | C46: EZO / MIRIAM | D46: 82-104984-189 | E46: 0.75 | H46: RHEEM FALCON | I46: EZO / MIRIAM | J46: 82-104985-54 | K46: 0.5 | N46: RHEEM NIPLES | O46: EZO / MIRIAM | P46: 82-101183-16H3 | Q46: 0.3125
...

Sheet SEMANA 28
B2: DÍA | C2: TURNO
B3: =TODAY() -> 46308 | C3: A | I3: PROGRAMA
C4: B | I4: SEMANA | P4: 46209 | R4: 46210 | T4: 46211 | V4: 46212 | X4: 46213 | Z4: 46216 | AB4: 46217 | AD4: 46218 | AF4: 46219 | AH4: 46220 | AJ4: Ag1
B5: CLIENTE | C5: DESTINO | D5: NÚMERO DE PARTE | E5: DIAMETRO | F5: PARED | G5: PESO | H5: PRECIO | I5: 28 | J5: 29 | K5: Ag2 | L5: Ag3 | M5: Ag4 | N5: EZO | O5: BALANCE | P5: A | Q5: B | R5: A | S5: B | T5: A | U5: B | V5: A | W5: B | X5: A | Y5: B | Z5: A | AA5: B | AB5: A | AC5: B | AD5: A | AE5: B | AF5: A | AG5: B | AH5: A | AI5: B | AJ5: AYB | AK5: KG | AL5: CAJA | AM5: CANT. X CAJA | AN5: HOJA COLOR | AO5: TOTAL CAJAS | AQ5: Row Labels | AR5: Sum of TOTAL CAJAS
A6: 1 | B6: RHEEM TRANSFERENCIA | C6: EZO / MIRIAM | D6: 82-104987-15 | E6: 0.25 | F6: 0.028 | I6: 0 | J6: 0 | K6: 0 | L6: 0 | N6: 0 | O6: =+I6+J6+K6+L6+M6+N6-SUM(P6:AJ6) -> 0 | AK6: =+G6*SUM(I6:N6) -> 0 | AL6: 12.5X12.5X12.5 | AM6: 150 | AN6: VERDE | AO6: =+SUM(I6:N6)/AM6 -> 0 | AQ6: 0 | AR6: 0
A7: 2 | B7: RHEEM TRANSFERENCIA | C7: EZO / MIRIAM | D7: 82-104987-13 | E7: 0.25 | F7: 0.028 | I7: 1400 | J7: 0 | K7: 0 | L7: 0 | N7: 0 | O7: =+I7+J7+K7+L7+M7+N7-SUM(P7:AJ7) -> 0 | T7: 1400 | AK7: =+G7*SUM(I7:N7) -> 0 | AL7: 12.5X12.5X12.5 | AM7: 200 | AN7: VERDE | AO7: =+SUM(I7:N7)/AM7 -> 7 | AQ7: 12.5X12.5X12.5 | AR7: 52
A8: 3 | B8: RHEEM TRANSFERENCIA | C8: EZO / MIRIAM | D8: 82-104987-14 | E8: 0.25 | F8: 0.028 | I8: 0 | J8: 0 | K8: 0 | L8: 0 | N8: 0 | O8: =+I8+J8+K8+L8+M8+N8-SUM(P8:AJ8) -> 0 | AK8: =+G8*SUM(I8:N8) -> 0 | AL8: 12.5X12.5X12.5 | AM8: 200 | AN8: VERDE | AO8: =+SUM(I8:N8)/AM8 -> 0 | AQ8: 25x20x12.5 | AR8: 0
A9: 4 | B9: RHEEM TRANSFERENCIA | C9: EZO / MIRIAM | D9: 82-104986-88 | E9: 0.375 | F9: 0.028 | I9: 0 | J9: 0 | K9: 0 | L9: 0 | N9: 0 | O9: =+I9+J9+K9+L9+M9+N9-SUM(P9:AJ9) -> 0 | AK9: =+G9*SUM(I9:N9) -> 0 | AL9: 12.5X12.5X12.5 | AM9: 100 | AN9: VERDE | AO9: =+SUM(I9:N9)/AM9 -> 0 | AQ9: 30X20X7 | AR9: 116
A10: 5 | B10: RHEEM TRANSFERENCIA | C10: EZO / MIRIAM | D10: 82-104986-61 | E10: 0.375 | F10: 0.028 | I10: 0 | J10: 0 | K10: 0 | L10: 0 | N10: 0 | O10: =+I10+J10+K10+L10+M10+N10-SUM(P10:AJ10) -> 0 | AK10: =+G10*SUM(I10:N10) -> 0 | AL10: 12.5X12.5X12.5 | AM10: 150 | AN10: VERDE | AO10: =+SUM(I10:N10)/AM10 -> 0 | AQ10: 42X45X20 | AR10: 2
A11: 6 | B11: RHEEM TRANSFERENCIA | C11: EZO / MIRIAM | D11: 82-104986-59 | E11: 0.375 | F11: 0.028 | I11: 0 | J11: 0 | K11: 0 | L11: 0 | N11: 0 | O11: =+I11+J11+K11+L11+M11+N11-SUM(P11:AJ11) -> 0 | AK11: =+G11*SUM(I11:N11) -> 0 | AL11: 12.5X12.5X12.5 | AM11: 150 | AN11: VERDE | AO11: =+SUM(I11:N11)/AM11 -> 0 | AQ11: 44x41x12 | AR11: 10
A12: 7 | B12: RHEEM TRANSFERENCIA | C12: EZO / MIRIAM | D12: 82-104986-72 | E12: 0.375 | F12: 0.028 | I12: 1100 | J12: 0 | K12: 0 | L12: 0 | N12: 0 | O12: =+I12+J12+K12+L12+M12+N12-SUM(P12:AJ12) -> -106 | T12: 127 | U12: 1079 | AK12: =+G12*SUM(I12:N12) -> 0 | AL12: 12.5X12.5X12.5 | AM12: 50 | AN12: VERDE | AO12: =+SUM(I12:N12)/AM12 -> 22 | AQ12: Grand Total | AR12: 180
A13: 8 | B13: RHEEM TRANSFERENCIA | C13: EZO / MIRIAM | D13: 82-104986-89 | E13: 0.375 | F13: 0.028 | I13: 0 | J13: 0 | K13: 0 | L13: 0 | N13: 0 | O13: =+I13+J13+K13+L13+M13+N13-SUM(P13:AJ13) -> 0 | AK13: =+G13*SUM(I13:N13) -> 0 | AL13: 12.5X12.5X12.5 | AM13: 100 | AN13: VERDE | AO13: =+SUM(I13:N13)/AM13 -> 0
A14: 9 | B14: RHEEM TRANSFERENCIA | C14: EZO / MIRIAM | D14: 82-104986-71 | E14: 0.375 | F14: 0.028 | I14: 0 | J14: 0 | K14: 0 | L14: 0 | N14: 0 | O14: =+I14+J14+K14+L14+M14+N14-SUM(P14:AJ14) -> 0 | AK14: =+G14*SUM(I14:N14) -> 0 | AL14: 12.5X12.5X12.5 | AM14: 50 | AN14: VERDE | AO14: =+SUM(I14:N14)/AM14 -> 0
A15: 10 | B15: RHEEM TRANSFERENCIA | C15: EZO / MIRIAM | D15: 82-104986-60 | E15: 0.375 | F15: 0.028 | I15: 0 | J15: 0 | K15: 0 | L15: 0 | N15: 0 | O15: =+I15+J15+K15+L15+M15+N15-SUM(P15:AJ15) -> 0 | AK15: =+G15*SUM(I15:N15) -> 0 | AL15: 30X20X7 | AM15: 60 | AN15: VERDE | AO15: =+SUM(I15:N15)/AM15 -> 0
A16: 11 | B16: RHEEM TRANSFERENCIA | C16: EZO / MIRIAM | D16: 82-104985-41 | E16: 0.5 | F16: 0.028 | I16: 0 | J16: 0 | K16: 0 | L16: 0 | N16: 0 | O16: =+I16+J16+K16+L16+M16+N16-SUM(P16:AJ16) -> 0 | AK16: =+G16*SUM(I16:N16) -> 0 | AL16: 12.5x12.5x12.5 | AM16: 100 | AN16: VERDE | AO16: =+SUM(I16:N16)/AM16 -> 0
A17: 12 | B17: RHEEM TRANSFERENCIA | C17: EZO / MIRIAM | D17: 82-104985-25 | E17: 0.5 | F17: 0.028 | I17: 0 | J17: 0 | K17: 0 | L17: 0 | N17: 0 | O17: =+I17+J17+K17+L17+M17+N17-SUM(P17:AJ17) -> 0 | AK17: =+G17*SUM(I17:N17) -> 0 | AL17: 44x41x12 | AM17: 100 | AN17: VERDE | AO17: =+SUM(I17:N17)/AM17 -> 0
A18: 13 | B18: RHEEM TRANSFERENCIA | C18: EZO / MIRIAM | D18: 82-104748-68 | E18: 0.5 | F18: 0.028 | I18: 400 | J18: 0 | K18: 0 | L18: 0 | N18: 0 | O18: =+I18+J18+K18+L18+M18+N18-SUM(P18:AJ18) -> 0 | T18: 400 | AK18: =+G18*SUM(I18:N18) -> 0 | AL18: 44x41x12 | AM18: 100 | AN18: VERDE | AO18: =+SUM(I18:N18)/AM18 -> 4
A19: 14 | B19: RHEEM TRANSFERENCIA | C19: EZO / MIRIAM | D19: 82-104985-39 | E19: 0.5 | F19: 0.028 | I19: 0 | J19: 0 | K19: 0 | L19: 0 | N19: 0 | O19: =+I19+J19+K19+L19+M19+N19-SUM(P19:AJ19) -> 0 | AK19: =+G19*SUM(I19:N19) -> 0 | AL19: 44x41x12 | AM19: 100 | AN19: VERDE | AO19: =+SUM(I19:N19)/AM19 -> 0
A20: 15 | B20: RHEEM TRANSFERENCIA | C20: EZO / MIRIAM | D20: 82-108427-01 | E20: 0.5 | F20: 0.028 | I20: 0 | J20: 0 | K20: 0 | L20: 0 | N20: 0 | O20: =+I20+J20+K20+L20+M20+N20-SUM(P20:AJ20) -> 0 | AK20: =+G20*SUM(I20:N20) -> 0 | AL20: 44x41x12 | AM20: 80 | AN20: VERDE | AO20: =+SUM(I20:N20)/AM20 -> 0
A21: 16 | B21: RHEEM TRANSFERENCIA | C21: EZO / MIRIAM | D21: 82-104748-69 | E21: 0.5 | F21: 0.028 | I21: 0 | J21: 0 | K21: 0 | L21: 0 | N21: 0 | O21: =+I21+J21+K21+L21+M21+N21-SUM(P21:AJ21) -> 0 | AK21: =+G21*SUM(I21:N21) -> 0 | AL21: 44x41x12 | AM21: 100 | AN21: VERDE | AO21: =+SUM(I21:N21)/AM21 -> 0
A22: 17 | B22: RHEEM TRANSFERENCIA | C22: EZO / MIRIAM | D22: 82-104894-08 | E22: 0.5 | F22: 0.028 | I22: 0 | J22: 0 | K22: 0 | L22: 0 | N22: 0 | O22: =+I22+J22+K22+L22+M22+N22-SUM(P22:AJ22) -> 0 | AK22: =+G22*SUM(I22:N22) -> 0 | AL22: 0 | AM22: 0 | AN22: VERDE | AO22: 0
A23: 18 | B23: RHEEM TRANSFERENCIA | C23: EZO / MIRIAM | D23: 82-104894-02 | E23: 0.5 | F23: 0.028 | I23: 0 | J23: 0 | K23: 0 | L23: 0 | N23: 0 | O23: =+I23+J23+K23+L23+M23+N23-SUM(P23:AJ23) -> 0 | AK23: =+G23*SUM(I23:N23) -> 0 | AL23: 0 | AM23: 0 | AN23: VERDE | AO23: 0
A24: 19 | B24: RHEEM TRANSFERENCIA | C24: EZO / MIRIAM | D24: 82-104895-02 | E24: 0.5 | F24: 0.028 | I24: 0 | J24: 0 | K24: 0 | L24: 0 | N24: 0 | O24: =+I24+J24+K24+L24+M24+N24-SUM(P24:AJ24) -> 0 | AK24: =+G24*SUM(I24:N24) -> 0 | AL24: 0 | AM24: 0 | AN24: VERDE | AO24: 0
A25: 20 | B25: RHEEM TRANSFERENCIA | C25: EZO / MIRIAM | D25: 82-100797-16 | E25: 0.5 | F25: 0.028 | I25: 0 | J25: 0 | K25: 0 | L25: 0 | N25: 0 | O25: =+I25+J25+K25+L25+M25+N25-SUM(P25:AJ25) -> 0 | AK25: =+G25*SUM(I25:N25) -> 0 | AL25: 0 | AM25: 0 | AN25: VERDE | AO25: 0
A26: 21 | B26: RHEEM TRANSFERENCIA | C26: EZO / MIRIAM | D26: 82-104895-06 | E26: 0.5 | F26: 0.028 | I26: 0 | J26: 0 | K26: 0 | L26: 0 | N26: 0 | O26: =+I26+J26+K26+L26+M26+N26-SUM(P26:AJ26) -> 0 | AK26: =+G26*SUM(I26:N26) -> 0 | AL26: 0 | AM26: 0 | AN26: VERDE | AO26: 0
A27: 22 | B27: RHEEM TRANSFERENCIA | C27: EZO / MIRIAM | D27: 82-104894-07 | E27: 0.5 | F27: 0.028 | I27: 0 | J27: 0 | K27: 0 | L27: 0 | N27: 0 | O27: =+I27+J27+K27+L27+M27+N27-SUM(P27:AJ27) -> 0 | AK27: =+G27*SUM(I27:N27) -> 0 | AL27: 0 | AM27: 0 | AN27: VERDE | AO27: 0
A28: 23 | B28: RHEEM TRANSFERENCIA | C28: EZO / MIRIAM | D28: 82-100797-23 | E28: 0.5 | F28: 0.028 | I28: 0 | J28: 0 | K28: 0 | L28: 0 | N28: 0 | O28: =+I28+J28+K28+L28+M28+N28-SUM(P28:AJ28) -> 0 | AK28: =+G28*SUM(I28:N28) -> 0 | AL28: 0 | AM28: 0 | AN28: VERDE | AO28: 0
A29: 24 | B29: RHEEM TRANSFERENCIA | C29: EZO / MIRIAM | D29: 82-104894-10 | E29: 0.5 | F29: 0.028 | I29: 0 | J29: 0 | K29: 0 | L29: 0 | N29: 0 | O29: =+I29+J29+K29+L29+M29+N29-SUM(P29:AJ29) -> 0 | AK29: =+G29*SUM(I29:N29) -> 0 | AL29: 0 | AM29: 0 | AN29: VERDE | AO29: 0
A30: 25 | B30: RHEEM TRANSFERENCIA | C30: EZO / MIRIAM | D30: 82-104895-07 | E30: 0.5 | F30: 0.028 | I30: 0 | J30: 0 | K30: 0 | L30: 0 | N30: 0 | O30: =+I30+J30+K30+L30+M30+N30-SUM(P30:AJ30) -> 0 | AK30: =+G30*SUM(I30:N30) -> 0 | AL30: 0 | AM30: 0 | AN30: VERDE | AO30: 0
A31: 26 | B31: RHEEM TRANSFERENCIA | C31: EZO / MIRIAM | D31: 82-104895-17 | E31: 0.5 | F31: 0.028 | I31: 0 | J31: 0 | K31: 0 | L31: 0 | N31: 0 | O31: =+I31+J31+K31+L31+M31+N31-SUM(P31:AJ31) -> 0 | AK31: =+G31*SUM(I31:N31) -> 0 | AL31: 0 | AM31: 0 | AN31: VERDE | AO31: 0
A32: 27 | B32: RHEEM TRANSFERENCIA | C32: EZO / MIRIAM | D32: 82-104894-13 | E32: 0.5 | F32: 0.028 | I32: 0 | J32: 0 | K32: 0 | L32: 0 | N32: 0 | O32: =+I32+J32+K32+L32+M32+N32-SUM(P32:AJ32) -> 0 | AK32: =+G32*SUM(I32:N32) -> 0 | AL32: 0 | AM32: 0 | AN32: VERDE | AO32: 0
A33: 28 | B33: RHEEM TRANSFERENCIA | C33: EZO / MIRIAM | D33: 82-104894-01 | E33: 0.5 | F33: 0.028 | I33: 0 | J33: 0 | K33: 0 | L33: 0 | N33: 0 | O33: =+I33+J33+K33+L33+M33+N33-SUM(P33:AJ33) -> 0 | AK33: =+G33*SUM(I33:N33) -> 0 | AL33: 0 | AM33: 0 | AN33: VERDE | AO33: 0
... A35: 30 | B35: RHEEM TRANSFERENCIA | C35: EZO / MIRIAM | D35: 82-104894-09 | E35: 0.5 | F35: 0.028 | I35: 0 | J35: 0 | K35: 0 | L35: 0 | N35: 0 | O35: =+I35+J35+K35+L35+M35+N35-SUM(P35:AJ35) -> 0 | AK35: =+G35*SUM(I35:N35) -> 0 | AL35: 0 | AM35: 0 | AN35: VERDE | AO35: 0
A36: 31 | B36: RHEEM TRANSFERENCIA | C36: EZO / MIRIAM | D36: 82-104984-140 | E36: 0.625 | F36: 0.035 | I36: 0 | J36: 0 | K36: 0 | L36: 0 | N36: 0 | O36: =+I36+J36+K36+L36+M36+N36-SUM(P36:AJ36) -> 0 | AK36: =+G36*SUM(I36:N36) -> 0 | AL36: 44x41x12 | AM36: 200 | AN36: VERDE | AO36: =+SUM(I36:N36)/AM36 -> 0
A37: 32 | B37: RHEEM TRANSFERENCIA | C37: EZO / MIRIAM | D37: 82-104984-116 | E37: 0.625 | F37: 0.035 | I37: 600 | J37: 0 | K37: 0 | L37: 0 | N37: 0 | O37: =+I37+J37+K37+L37+M37+N37-SUM(P37:AJ37) -> -181 | X37: 181 | Y37: 600 | AK37: =+G37*SUM(I37:N37) -> 0 | AL37: 44x41x12 | AM37: 100 | AN37: VERDE | AO37: =+SUM(I37:N37)/AM37 -> 6
A38: 33 | B38: RHEEM TRANSFERENCIA | C38: EZO / MIRIAM | D38: 82-104984-142 | E38: 0.625 | F38: 0.035 | I38: 0 | J38: 0 | K38: 0 | L38: 0 | N38: 0 | O38: =+I38+J38+K38+L38+M38+N38-SUM(P38:AJ38) -> 0 | AK38: =+G38*SUM(I38:N38) -> 0 | AL38: 44x41x12 | AM38: 100 | AN38: VERDE | AO38: =+SUM(I38:N38)/AM38 -> 0
A39: 34 | B39: RHEEM TRANSFERENCIA | C39: EZO / MIRIAM | D39: 82-104984-114 | E39: 0.75 | F39: 0.035 | I39: 2000 | J39: 0 | K39: 0 | L39: 0 | N39: 0 | O39: =+I39+J39+K39+L39+M39+N39-SUM(P39:AJ39) -> -960 | U39: 960 | V39: 2000 | AK39: =+G39*SUM(I39:N39) -> 0 | AL39: 42X45X20 | AM39: 2000 | AN39: VERDE | AO39: =+SUM(I39:N39)/AM39 -> 1
A40: 35 | B40: RHEEM TRANSFERENCIA | C40: EZO / MIRIAM | D40: 82-104984-147 | E40: 0.75 | F40: 0.035 | I40: 0 | J40: 0 | K40: 0 | L40: 0 | N40: 0 | O40: =+I40+J40+K40+L40+M40+N40-SUM(P40:AJ40) -> 0 | AK40: =+G40*SUM(I40:N40) -> 0 | AL40: 42X45X20 | AM40: 500 | AN40: VERDE | AO40: =+SUM(I40:N40)/AM40 -> 0
A41: 36 | B41: RHEEM TRANSFERENCIA | C41: EZO / MIRIAM | D41: 82-104984-122 | E41: 0.75 | F41: 0.035 | I41: 0 | J41: 0 | K41: 0 | L41: 0 | N41: 0 | O41: =+I41+J41+K41+L41+M41+N41-SUM(P41:AJ41) -> 0 | AK41: =+G41*SUM(I41:N41) -> 0 | AL41: 42X45X20 | AM41: 250 | AN41: VERDE | AO41: =+SUM(I41:N41)/AM41 -> 0
A42: 37 | B42: RHEEM TRANSFERENCIA | C42: EZO / MIRIAM | D42: 82-104984-189 | E42: 0.75 | F42: 0.035 | I42: 0 | J42: 0 | K42: 0 | L42: 0 | N42: 0 | O42: =+I42+J42+K42+L42+M42+N42-SUM(P42:AJ42) -> 0 | AK42: =+G42*SUM(I42:N42) -> 0 | AL42: 42X45X20 | AM42: 300 | AN42: VERDE | AO42: =+SUM(I42:N42)/AM42 -> 0
...

Sheet SEMANA 30
B2: DÍA | C2: TURNO
B3: =TODAY() -> 46308 | C3: A | D3: X | I3: PROGRAMA
C4: B | I4: SEMANA | J4: Convertirlo a horas | P4: 46223 | R4: 46224 | T4: 46225 | V4: 46226 | X4: 46227 | Z4: 46230 | AB4: 46231 | AD4: 46232 | AF4: 46233 | AH4: 46234 | AJ4: Ag1
B5: CLIENTE | C5: DESTINO | D5: NÚMERO DE PARTE | E5: DIAMETRO | F5: PARED | G5: PESO | H5: PRECIO | I5: 30 | J5: 30 | K5: 30 | L5: 30 | M5: 30 | N5: Ag5 | O5: BALANCE | P5: A | Q5: B | R5: A | S5: B | T5: A | U5: B | V5: A | W5: B | X5: A | Y5: B | Z5: A | AA5: B | AB5: A | AC5: B | AD5: A | AE5: B | AF5: A | AG5: B | AH5: A | AI5: B | AJ5: AYB | AK5: KG | AL5: CAJA | AM5: CANT. X CAJA | AN5: HOJA COLOR | AO5: TOTAL CAJAS | AQ5: Row Labels | AR5: Sum of TOTAL CAJAS
A6: 1 | B6: RHEEM TRANSFERENCIA | C6: EZO / MIRIAM | D6: 82-104987-15 | E6: 0.25 | F6: 0.028 | I6: 0 | J6: 0 | K6: 0 | L6: 0 | M6: 0 | O6: =+I6+J6+K6+L6+M6+N6-SUM(P6:AJ6) -> 0 | AK6: =+G6*SUM(I6:N6) -> 0 | AL6: 12.5X12.5X12.5 | AM6: 150 | AN6: VERDE | AO6: =+SUM(I6:N6)/AM6 -> 0 | AQ6: 0 | AR6: 0
A7: 2 | B7: RHEEM TRANSFERENCIA | C7: EZO / MIRIAM | D7: 82-104987-13 | E7: 0.25 | F7: 0.028 | I7: 0 | J7: 0 | K7: 0 | L7: 0 | M7: 0 | O7: =+I7+J7+K7+L7+M7+N7-SUM(P7:AJ7) -> 0 | AK7: =+G7*SUM(I7:N7) -> 0 | AL7: 12.5X12.5X12.5 | AM7: 200 | AN7: VERDE | AO7: =+SUM(I7:N7)/AM7 -> 0 | AQ7: 12.5X12.5X12.5 | AR7: 52
A8: 3 | B8: RHEEM TRANSFERENCIA | C8: EZO / MIRIAM | D8: 82-104987-14 | E8: 0.25 | F8: 0.028 | I8: 0 | J8: 0 | K8: 0 | L8: 0 | M8: 0 | O8: =+I8+J8+K8+L8+M8+N8-SUM(P8:AJ8) -> 0 | AK8: =+G8*SUM(I8:N8) -> 0 | AL8: 12.5X12.5X12.5 | AM8: 200 | AN8: VERDE | AO8: =+SUM(I8:N8)/AM8 -> 0 | AQ8: 25x20x12.5 | AR8: 0
A9: 4 | B9: RHEEM TRANSFERENCIA | C9: EZO / MIRIAM | D9: 82-104986-88 | E9: 0.375 | F9: 0.028 | I9: 0 | J9: 0 | K9: 0 | L9: 0 | M9: 0 | O9: =+I9+J9+K9+L9+M9+N9-SUM(P9:AJ9) -> 0 | AK9: =+G9*SUM(I9:N9) -> 0 | AL9: 12.5X12.5X12.5 | AM9: 100 | AN9: VERDE | AO9: =+SUM(I9:N9)/AM9 -> 0 | AQ9: 30X20X7 | AR9: 116
A10: 5 | B10: RHEEM TRANSFERENCIA | C10: EZO / MIRIAM | D10: 82-104986-61 | E10: 0.375 | F10: 0.028 | I10: 0 | J10: 0 | K10: 0 | L10: 0 | M10: 0 | O10: =+I10+J10+K10+L10+M10+N10-SUM(P10:AJ10) -> 0 | AK10: =+G10*SUM(I10:N10) -> 0 | AL10: 12.5X12.5X12.5 | AM10: 150 | AN10: VERDE | AO10: =+SUM(I10:N10)/AM10 -> 0 | AQ10: 42X45X20 | AR10: 2
A11: 6 | B11: RHEEM TRANSFERENCIA | C11: EZO / MIRIAM | D11: 82-104986-59 | E11: 0.375 | F11: 0.028 | I11: 0 | J11: 1200 | K11: 0 | L11: 0 | M11: 0 | O11: =+I11+J11+K11+L11+M11+N11-SUM(P11:AJ11) -> -700 | T11: 700 | V11: 1200 | AK11: =+G11*SUM(I11:N11) -> 0 | AL11: 12.5X12.5X12.5 | AM11: 150 | AN11: VERDE | AO11: =+SUM(I11:N11)/AM11 -> 8 | AQ11: 44x41x12 | AR11: 10
A12: 7 | B12: RHEEM TRANSFERENCIA | C12: EZO / MIRIAM | D12: 82-104986-72 | E12: 0.375 | F12: 0.028 | I12: -106 | J12: 0 | K12: 0 | L12: 0 | M12: 0 | O12: =+I12+J12+K12+L12+M12+N12-SUM(P12:AJ12) -> -106 | AK12: =+G12*SUM(I12:N12) -> 0 | AL12: 12.5X12.5X12.5 | AM12: 50 | AN12: VERDE | AO12: =+SUM(I12:N12)/AM12 -> -2.12 | AQ12: Grand Total | AR12: 180
A13: 8 | B13: RHEEM TRANSFERENCIA | C13: EZO / MIRIAM | D13: 82-104986-89 | E13: 0.375 | F13: 0.028 | I13: 0 | J13: 0 | K13: 0 | L13: 0 | M13: 0 | O13: =+I13+J13+K13+L13+M13+N13-SUM(P13:AJ13) -> 0 | AK13: =+G13*SUM(I13:N13) -> 0 | AL13: 12.5X12.5X12.5 | AM13: 100 | AN13: VERDE | AO13: =+SUM(I13:N13)/AM13 -> 0
A14: 9 | B14: RHEEM TRANSFERENCIA | C14: EZO / MIRIAM | D14: 82-104986-71 | E14: 0.375 | F14: 0.028 | I14: 0 | J14: 0 | K14: 0 | L14: 0 | M14: 0 | O14: =+I14+J14+K14+L14+M14+N14-SUM(P14:AJ14) -> 0 | AK14: =+G14*SUM(I14:N14) -> 0 | AL14: 12.5X12.5X12.5 | AM14: 50 | AN14: VERDE | AO14: =+SUM(I14:N14)/AM14 -> 0
A15: 10 | B15: RHEEM TRANSFERENCIA | C15: EZO / MIRIAM | D15: 82-104986-60 | E15: 0.375 | F15: 0.028 | I15: 0 | J15: 0 | K15: 0 | L15: 0 | M15: 0 | O15: =+I15+J15+K15+L15+M15+N15-SUM(P15:AJ15) -> 0 | AK15: =+G15*SUM(I15:N15) -> 0 | AL15: 30X20X7 | AM15: 60 | AN15: VERDE | AO15: =+SUM(I15:N15)/AM15 -> 0
A16: 11 | B16: RHEEM TRANSFERENCIA | C16: EZO / MIRIAM | D16: 82-104985-41 | E16: 0.5 | F16: 0.028 | I16: 0 | J16: 0 | K16: 0 | L16: 0 | M16: 0 | O16: =+I16+J16+K16+L16+M16+N16-SUM(P16:AJ16) -> 0 | AK16: =+G16*SUM(I16:N16) -> 0 | AL16: 12.5x12.5x12.5 | AM16: 100 | AN16: VERDE | AO16: =+SUM(I16:N16)/AM16 -> 0
A17: 12 | B17: RHEEM TRANSFERENCIA | C17: EZO / MIRIAM | D17: 82-104985-25 | E17: 0.5 | F17: 0.028 | I17: 0 | J17: 0 | K17: 0 | L17: 0 | M17: 0 | O17: =+I17+J17+K17+L17+M17+N17-SUM(P17:AJ17) -> 0 | AK17: =+G17*SUM(I17:N17) -> 0 | AL17: 44x41x12 | AM17: 100 | AN17: VERDE | AO17: =+SUM(I17:N17)/AM17 -> 0
A18: 13 | B18: RHEEM TRANSFERENCIA | C18: EZO / MIRIAM | D18: 82-104748-68 | E18: 0.5 | F18: 0.028 | I18: 0 | J18: 0 | K18: 0 | L18: 0 | M18: 0 | O18: =+I18+J18+K18+L18+M18+N18-SUM(P18:AJ18) -> 0 | AK18: =+G18*SUM(I18:N18) -> 0 | AL18: 44x41x12 | AM18: 100 | AN18: VERDE | AO18: =+SUM(I18:N18)/AM18 -> 0
A19: 14 | B19: RHEEM TRANSFERENCIA | C19: EZO / MIRIAM | D19: 82-104985-39 | E19: 0.5 | F19: 0.028 | I19: 0 | J19: 700 | K19: 0 | L19: 0 | M19: 0 | O19: =+I19+J19+K19+L19+M19+N19-SUM(P19:AJ19) -> 0 | V19: 700 | AK19: =+G19*SUM(I19:N19) -> 0 | AL19: 44x41x12 | AM19: 100 | AN19: VERDE | AO19: =+SUM(I19:N19)/AM19 -> 7
A20: 15 | B20: RHEEM TRANSFERENCIA | C20: EZO / MIRIAM | D20: 82-108427-01 | E20: 0.5 | F20: 0.028 | I20: 0 | J20: 0 | K20: 0 | L20: 0 | M20: 0 | O20: =+I20+J20+K20+L20+M20+N20-SUM(P20:AJ20) -> 0 | AK20: =+G20*SUM(I20:N20) -> 0 | AL20: 44x41x12 | AM20: 80 | AN20: VERDE | AO20: =+SUM(I20:N20)/AM20 -> 0
A21: 16 | B21: RHEEM TRANSFERENCIA | C21: EZO / MIRIAM | D21: 82-104748-69 | E21: 0.5 | F21: 0.028 | I21: 0 | J21: 500 | K21: 0 | L21: 0 | M21: 0 | O21: =+I21+J21+K21+L21+M21+N21-SUM(P21:AJ21) -> 500 | AK21: =+G21*SUM(I21:N21) -> 0 | AL21: 44x41x12 | AM21: 100 | AN21: VERDE | AO21: =+SUM(I21:N21)/AM21 -> 5
A22: 17 | B22: RHEEM TRANSFERENCIA | C22: EZO / MIRIAM | D22: 82-104894-08 | E22: 0.5 | F22: 0.028 | I22: 0 | J22: 0 | K22: 0 | L22: 0 | M22: 0 | O22: =+I22+J22+K22+L22+M22+N22-SUM(P22:AJ22) -> 0 | AK22: =+G22*SUM(I22:N22) -> 0 | AL22: 0 | AM22: 0 | AN22: VERDE | AO22: 0
A23: 18 | B23: RHEEM TRANSFERENCIA | C23: EZO / MIRIAM | D23: 82-104894-02 | E23: 0.5 | F23: 0.028 | I23: 0 | J23: 0 | K23: 0 | L23: 0 | M23: 0 | O23: =+I23+J23+K23+L23+M23+N23-SUM(P23:AJ23) -> 0 | AK23: =+G23*SUM(I23:N23) -> 0 | AL23: 0 | AM23: 0 | AN23: VERDE | AO23: 0
A24: 19 | B24: RHEEM TRANSFERENCIA | C24: EZO / MIRIAM | D24: 82-104895-02 | E24: 0.5 | F24: 0.028 | I24: 0 | J24: 0 | K24: 0 | L24: 0 | M24: 0 | O24: =+I24+J24+K24+L24+M24+N24-SUM(P24:AJ24) -> 0 | AK24: =+G24*SUM(I24:N24) -> 0 | AL24: 0 | AM24: 0 | AN24: VERDE | AO24: 0
A25: 20 | B25: RHEEM TRANSFERENCIA | C25: EZO / MIRIAM | D25: 82-100797-16 | E25: 0.5 | F25: 0.028 | I25: 0 | J25: 0 | K25: 0 | L25: 0 | M25: 0 | O25: =+I25+J25+K25+L25+M25+N25-SUM(P25:AJ25) -> 0 | AK25: =+G25*SUM(I25:N25) -> 0 | AL25: 0 | AM25: 0 | AN25: VERDE | AO25: 0
A26: 21 | B26: RHEEM TRANSFERENCIA | C26: EZO / MIRIAM | D26: 82-104895-06 | E26: 0.5 | F26: 0.028 | I26: 0 | J26: 0 | K26: 0 | L26: 0 | M26: 0 | O26: =+I26+J26+K26+L26+M26+N26-SUM(P26:AJ26) -> 0 | AK26: =+G26*SUM(I26:N26) -> 0 | AL26: 0 | AM26: 0 | AN26: VERDE | AO26: 0
A27: 22 | B27: RHEEM TRANSFERENCIA | C27: EZO / MIRIAM | D27: 82-104894-07 | E27: 0.5 | F27: 0.028 | I27: 0 | J27: 0 | K27: 0 | L27: 0 | M27: 0 | O27: =+I27+J27+K27+L27+M27+N27-SUM(P27:AJ27) -> 0 | AK27: =+G27*SUM(I27:N27) -> 0 | AL27: 0 | AM27: 0 | AN27: VERDE | AO27: 0
A28: 23 | B28: RHEEM TRANSFERENCIA | C28: EZO / MIRIAM | D28: 82-100797-23 | E28: 0.5 | F28: 0.028 | I28: 0 | J28: 0 | K28: 0 | L28: 0 | M28: 0 | O28: =+I28+J28+K28+L28+M28+N28-SUM(P28:AJ28) -> 0 | AK28: =+G28*SUM(I28:N28) -> 0 | AL28: 0 | AM28: 0 | AN28: VERDE | AO28: 0
A29: 24 | B29: RHEEM TRANSFERENCIA | C29: EZO / MIRIAM | D29: 82-104894-10 | E29: 0.5 | F29: 0.028 | I29: 0 | J29: 0 | K29: 0 | L29: 0 | M29: 0 | O29: =+I29+J29+K29+L29+M29+N29-SUM(P29:AJ29) -> 0 | AK29: =+G29*SUM(I29:N29) -> 0 | AL29: 0 | AM29: 0 | AN29: VERDE | AO29: 0
A30: 25 | B30: RHEEM TRANSFERENCIA | C30: EZO / MIRIAM | D30: 82-104895-07 | E30: 0.5 | F30: 0.028 | I30: 0 | J30: 0 | K30: 0 | L30: 0 | M30: 0 | O30: =+I30+J30+K30+L30+M30+N30-SUM(P30:AJ30) -> 0 | AK30: =+G30*SUM(I30:N30) -> 0 | AL30: 0 | AM30: 0 | AN30: VERDE | AO30: 0
A31: 26 | B31: RHEEM TRANSFERENCIA | C31: EZO / MIRIAM | D31: 82-104895-17 | E31: 0.5 | F31: 0.028 | I31: 0 | J31: 0 | K31: 0 | L31: 0 | M31: 0 | O31: =+I31+J31+K31+L31+M31+N31-SUM(P31:AJ31) -> 0 | AK31: =+G31*SUM(I31:N31) -> 0 | AL31: 0 | AM31: 0 | AN31: VERDE | AO31: 0
A32: 27 | B32: RHEEM TRANSFERENCIA | C32: EZO / MIRIAM | D32: 82-104894-13 | E32: 0.5 | F32: 0.028 | I32: 0 | J32: 0 | K32: 0 | L32: 0 | M32: 0 | O32: =+I32+J32+K32+L32+M32+N32-SUM(P32:AJ32) -> 0 | AK32: =+G32*SUM(I32:N32) -> 0 | AL32: 0 | AM32: 0 | AN32: VERDE | AO32: 0
A33: 28 | B33: RHEEM TRANSFERENCIA | C33: EZO / MIRIAM | D33: 82-104894-01 | E33: 0.5 | F33: 0.028 | I33: 0 | J33: 0 | K33: 0 | L33: 0 | M33: 0 | O33: =+I33+J33+K33+L33+M33+N33-SUM(P33:AJ33) -> 0 | AK33: =+G33*SUM(I33:N33) -> 0 | AL33: 0 | AM33: 0 | AN33: VERDE | AO33: 0
... A35: 30 | B35: RHEEM TRANSFERENCIA | C35: EZO / MIRIAM | D35: 82-104894-09 | E35: 0.5 | F35: 0.028 | I35: 0 | J35: 0 | K35: 0 | L35: 0 | M35: 0 | O35: =+I35+J35+K35+L35+M35+N35-SUM(P35:AJ35) -> 0 | AK35: =+G35*SUM(I35:N35) -> 0 | AL35: 0 | AM35: 0 | AN35: VERDE | AO35: 0
A36: 31 | B36: RHEEM TRANSFERENCIA | C36: EZO / MIRIAM | D36: 82-104984-140 | E36: 0.625 | F36: 0.035 | I36: 0 | J36: 800 | K36: 0 | L36: 0 | M36: 0 | O36: =+I36+J36+K36+L36+M36+N36-SUM(P36:AJ36) -> 0 | W36: 800 | AK36: =+G36*SUM(I36:N36) -> 0 | AL36: 44x41x12 | AM36: 200 | AN36: VERDE | AO36: =+SUM(I36:N36)/AM36 -> 4
A37: 32 | B37: RHEEM TRANSFERENCIA | C37: EZO / MIRIAM | D37: 82-104984-116 | E37: 0.625 | F37: 0.035 | I37: -181 | J37: 0 | K37: 0 | L37: 0 | M37: 0 | O37: =+I37+J37+K37+L37+M37+N37-SUM(P37:AJ37) -> -181 | AK37: =+G37*SUM(I37:N37) -> 0 | AL37: 44x41x12 | AM37: 100 | AN37: VERDE | AO37: =+SUM(I37:N37)/AM37 -> -1.81
A38: 33 | B38: RHEEM TRANSFERENCIA | C38: EZO / MIRIAM | D38: 82-104984-142 | E38: 0.625 | F38: 0.035 | I38: 0 | J38: 0 | K38: 0 | L38: 0 | M38: 0 | O38: =+I38+J38+K38+L38+M38+N38-SUM(P38:AJ38) -> 0 | AK38: =+G38*SUM(I38:N38) -> 0 | AL38: 44x41x12 | AM38: 100 | AN38: VERDE | AO38: =+SUM(I38:N38)/AM38 -> 0
A39: 34 | B39: RHEEM TRANSFERENCIA | C39: EZO / MIRIAM | D39: 82-104984-114 | E39: 0.75 | F39: 0.035 | I39: -960 | J39: 0 | K39: 0 | L39: 0 | M39: 0 | O39: =+I39+J39+K39+L39+M39+N39-SUM(P39:AJ39) -> -960 | AK39: =+G39*SUM(I39:N39) -> 0 | AL39: 42X45X20 | AM39: 2000 | AN39: VERDE | AO39: =+SUM(I39:N39)/AM39 -> -0.48
A40: 35 | B40: RHEEM TRANSFERENCIA | C40: EZO / MIRIAM | D40: 82-104984-147 | E40: 0.75 | F40: 0.035 | I40: 0 | J40: 0 | K40: 0 | L40: 0 | M40: 0 | O40: =+I40+J40+K40+L40+M40+N40-SUM(P40:AJ40) -> 0 | AK40: =+G40*SUM(I40:N40) -> 0 | AL40: 42X45X20 | AM40: 500 | AN40: VERDE | AO40: =+SUM(I40:N40)/AM40 -> 0
A41: 36 | B41: RHEEM TRANSFERENCIA | C41: EZO / MIRIAM | D41: 82-104984-122 | E41: 0.75 | F41: 0.035 | I41: 0 | J41: 0 | K41: 0 | L41: 0 | M41: 0 | O41: =+I41+J41+K41+L41+M41+N41-SUM(P41:AJ41) -> 0 | AK41: =+G41*SUM(I41:N41) -> 0 | AL41: 42X45X20 | AM41: 250 | AN41: VERDE | AO41: =+SUM(I41:N41)/AM41 -> 0
A42: 37 | B42: RHEEM TRANSFERENCIA | C42: EZO / MIRIAM | D42: 82-104984-189 | E42: 0.75 | F42: 0.035 | I42: 0 | J42: 0 | K42: 0 | L42: 0 | M42: 0 | O42: =+I42+J42+K42+L42+M42+N42-SUM(P42:AJ42) -> 0 | AK42: =+G42*SUM(I42:N42) -> 0 | AL42: 42X45X20 | AM42: 300 | AN42: VERDE | AO42: =+SUM(I42:N42)/AM42 -> 0
...

Sheet SEMANA 31
C2: DÍA | D2: TURNO
C3: =TODAY() -> 46308 | D3: A | E3: X | J3: PROGRAMA
D4: B | J4: SEMANA | K4: Convertirlo a horas | Q4: 46230 | S4: 46231 | U4: 46232 | W4: 46233 | Y4: 46234 | AA4: Ag1
C5: CLIENTE | D5: DESTINO | E5: NÚMERO DE PARTE | F5: DIAMETRO | G5: PARED | H5: PESO | I5: PRECIO | J5: 31 | K5: Ag1 | L5: Ag2 | M5: Ag3 | N5: Ag4 | O5: Ag5 | P5: BALANCE | Q5: A | R5: B | S5: A | T5: B | U5: A | V5: B | W5: A | X5: B | Y5: A | Z5: B | AA5: AYB | AB5: KG | AC5: CAJA | AD5: CANT. X CAJA | AE5: HOJA COLOR | AF5: TOTAL CAJAS | AH5: Row Labels | AI5: Sum of TOTAL CAJAS
B6: 1 | C6: RHEEM TRANSFERENCIA | D6: EZO / MIRIAM | E6: 82-104987-15 | F6: 0.25 | G6: 0.028 | J6: 0 | L6: 0 | P6: =+J6+K6+L6+M6+N6+O6-SUM(Q6:AA6) -> 0 | AB6: =+H6*SUM(J6:O6) -> 0 | AC6: 12.5X12.5X12.5 | AD6: 150 | AE6: VERDE | AF6: =+SUM(J6:O6)/AD6 -> 0 | AH6: 0 | AI6: 0
B7: 2 | C7: RHEEM TRANSFERENCIA | D7: EZO / MIRIAM | E7: 82-104987-13 | F7: 0.25 | G7: 0.028 | J7: 0 | L7: 0 | P7: =+J7+K7+L7+M7+N7+O7-SUM(Q7:AA7) -> 0 | AB7: =+H7*SUM(J7:O7) -> 0 | AC7: 12.5X12.5X12.5 | AD7: 200 | AE7: VERDE | AF7: =+SUM(J7:O7)/AD7 -> 0 | AH7: 12.5X12.5X12.5 | AI7: 52
B8: 3 | C8: RHEEM TRANSFERENCIA | D8: EZO / MIRIAM | E8: 82-104987-14 | F8: 0.25 | G8: 0.028 | J8: 0 | L8: 0 | P8: =+J8+K8+L8+M8+N8+O8-SUM(Q8:AA8) -> 0 | AB8: =+H8*SUM(J8:O8) -> 0 | AC8: 12.5X12.5X12.5 | AD8: 200 | AE8: VERDE | AF8: =+SUM(J8:O8)/AD8 -> 0 | AH8: 25x20x12.5 | AI8: 0
B9: 4 | C9: RHEEM TRANSFERENCIA | D9: EZO / MIRIAM | E9: 82-104986-88 | F9: 0.375 | G9: 0.028 | J9: 0 | L9: 0 | P9: =+J9+K9+L9+M9+N9+O9-SUM(Q9:AA9) -> 0 | AB9: =+H9*SUM(J9:O9) -> 0 | AC9: 12.5X12.5X12.5 | AD9: 100 | AE9: VERDE | AF9: =+SUM(J9:O9)/AD9 -> 0 | AH9: 30X20X7 | AI9: 116
B10: 5 | C10: RHEEM TRANSFERENCIA | D10: EZO / MIRIAM | E10: 82-104986-61 | F10: 0.375 | G10: 0.028 | J10: 0 | L10: 0 | P10: =+J10+K10+L10+M10+N10+O10-SUM(Q10:AA10) -> 0 | AB10: =+H10*SUM(J10:O10) -> 0 | AC10: 12.5X12.5X12.5 | AD10: 150 | AE10: VERDE | AF10: =+SUM(J10:O10)/AD10 -> 0 | AH10: 42X45X20 | AI10: 2
B11: 6 | C11: RHEEM TRANSFERENCIA | D11: EZO / MIRIAM | E11: 82-104986-59 | F11: 0.375 | G11: 0.028 | J11: 0 | K11: 100 | L11: 0 | P11: =+J11+K11+L11+M11+N11+O11-SUM(Q11:AA11) -> 0 | Q11: 100 | AB11: =+H11*SUM(J11:O11) -> 0 | AC11: 12.5X12.5X12.5 | AD11: 150 | AE11: VERDE | AF11: =+SUM(J11:O11)/AD11 -> 0.66666667 | AH11: 44x41x12 | AI11: 10
B12: 7 | C12: RHEEM TRANSFERENCIA | D12: EZO / MIRIAM | E12: 82-104986-72 | F12: 0.375 | G12: 0.028 | J12: 0 | L12: 0 | P12: =+J12+K12+L12+M12+N12+O12-SUM(Q12:AA12) -> 0 | AB12: =+H12*SUM(J12:O12) -> 0 | AC12: 12.5X12.5X12.5 | AD12: 50 | AE12: VERDE | AF12: =+SUM(J12:O12)/AD12 -> 0 | AH12: Grand Total | AI12: 180
B13: 8 | C13: RHEEM TRANSFERENCIA | D13: EZO / MIRIAM | E13: 82-104986-89 | F13: 0.375 | G13: 0.028 | J13: 0 | L13: 0 | P13: =+J13+K13+L13+M13+N13+O13-SUM(Q13:AA13) -> 0 | AB13: =+H13*SUM(J13:O13) -> 0 | AC13: 12.5X12.5X12.5 | AD13: 100 | AE13: VERDE | AF13: =+SUM(J13:O13)/AD13 -> 0
B14: 9 | C14: RHEEM TRANSFERENCIA | D14: EZO / MIRIAM | E14: 82-104986-71 | F14: 0.375 | G14: 0.028 | J14: 0 | L14: 0 | P14: =+J14+K14+L14+M14+N14+O14-SUM(Q14:AA14) -> 0 | AB14: =+H14*SUM(J14:O14) -> 0 | AC14: 12.5X12.5X12.5 | AD14: 50 | AE14: VERDE | AF14: =+SUM(J14:O14)/AD14 -> 0
B15: 10 | C15: RHEEM TRANSFERENCIA | D15: EZO / MIRIAM | E15: 82-104986-60 | F15: 0.375 | G15: 0.028 | J15: 0 | L15: 0 | P15: =+J15+K15+L15+M15+N15+O15-SUM(Q15:AA15) -> 0 | AB15: =+H15*SUM(J15:O15) -> 0 | AC15: 30X20X7 | AD15: 60 | AE15: VERDE | AF15: =+SUM(J15:O15)/AD15 -> 0
B16: 11 | C16: RHEEM TRANSFERENCIA | D16: EZO / MIRIAM | E16: 82-104985-41 | F16: 0.5 | G16: 0.028 | J16: 0 | L16: 0 | P16: =+J16+K16+L16+M16+N16+O16-SUM(Q16:AA16) -> 0 | AB16: =+H16*SUM(J16:O16) -> 0 | AC16: 12.5x12.5x12.5 | AD16: 100 | AE16: VERDE | AF16: =+SUM(J16:O16)/AD16 -> 0
B17: 12 | C17: RHEEM TRANSFERENCIA | D17: EZO / MIRIAM | E17: 82-104985-25 | F17: 0.5 | G17: 0.028 | J17: 0 | L17: 0 | P17: =+J17+K17+L17+M17+N17+O17-SUM(Q17:AA17) -> -756 | W17: 756 | AB17: =+H17*SUM(J17:O17) -> 0 | AC17: 44x41x12 | AD17: 100 | AE17: VERDE | AF17: =+SUM(J17:O17)/AD17 -> 0
B18: 13 | C18: RHEEM TRANSFERENCIA | D18: EZO / MIRIAM | E18: 82-104748-68 | F18: 0.5 | G18: 0.028 | J18: 0 | L18: 0 | P18: =+J18+K18+L18+M18+N18+O18-SUM(Q18:AA18) -> 0 | AB18: =+H18*SUM(J18:O18) -> 0 | AC18: 44x41x12 | AD18: 100 | AE18: VERDE | AF18: =+SUM(J18:O18)/AD18 -> 0
B19: 14 | C19: RHEEM TRANSFERENCIA | D19: EZO / MIRIAM | E19: 82-104985-39 | F19: 0.5 | G19: 0.028 | J19: 0 | L19: 0 | P19: =+J19+K19+L19+M19+N19+O19-SUM(Q19:AA19) -> 0 | AB19: =+H19*SUM(J19:O19) -> 0 | AC19: 44x41x12 | AD19: 100 | AE19: VERDE | AF19: =+SUM(J19:O19)/AD19 -> 0
B20: 15 | C20: RHEEM TRANSFERENCIA | D20: EZO / MIRIAM | E20: 82-108427-01 | F20: 0.5 | G20: 0.028 | J20: 0 | L20: 0 | P20: =+J20+K20+L20+M20+N20+O20-SUM(Q20:AA20) -> 0 | AB20: =+H20*SUM(J20:O20) -> 0 | AC20: 44x41x12 | AD20: 80 | AE20: VERDE | AF20: =+SUM(J20:O20)/AD20 -> 0
B21: 16 | C21: RHEEM TRANSFERENCIA | D21: EZO / MIRIAM | E21: 82-104748-69 | F21: 0.5 | G21: 0.028 | J21: 500 | L21: 0 | P21: =+J21+K21+L21+M21+N21+O21-SUM(Q21:AA21) -> 500 | AB21: =+H21*SUM(J21:O21) -> 0 | AC21: 44x41x12 | AD21: 100 | AE21: VERDE | AF21: =+SUM(J21:O21)/AD21 -> 5
B22: 17 | C22: RHEEM TRANSFERENCIA | D22: EZO / MIRIAM | E22: 82-104894-08 | F22: 0.5 | G22: 0.028 | J22: 0 | L22: 0 | P22: =+J22+K22+L22+M22+N22+O22-SUM(Q22:AA22) -> 0 | AB22: =+H22*SUM(J22:O22) -> 0 | AC22: 0 | AD22: 0 | AE22: VERDE | AF22: 0
B23: 18 | C23: RHEEM TRANSFERENCIA | D23: EZO / MIRIAM | E23: 82-104894-02 | F23: 0.5 | G23: 0.028 | J23: 0 | L23: 0 | P23: =+J23+K23+L23+M23+N23+O23-SUM(Q23:AA23) -> 0 | AB23: =+H23*SUM(J23:O23) -> 0 | AC23: 0 | AD23: 0 | AE23: VERDE | AF23: 0
B24: 19 | C24: RHEEM TRANSFERENCIA | D24: EZO / MIRIAM | E24: 82-104895-02 | F24: 0.5 | G24: 0.028 | J24: 0 | L24: 0 | P24: =+J24+K24+L24+M24+N24+O24-SUM(Q24:AA24) -> 0 | AB24: =+H24*SUM(J24:O24) -> 0 | AC24: 0 | AD24: 0 | AE24: VERDE | AF24: 0
B25: 20 | C25: RHEEM TRANSFERENCIA | D25: EZO / MIRIAM | E25: 82-100797-16 | F25: 0.5 | G25: 0.028 | J25: 0 | L25: 0 | P25: =+J25+K25+L25+M25+N25+O25-SUM(Q25:AA25) -> 0 | AB25: =+H25*SUM(J25:O25) -> 0 | AC25: 0 | AD25: 0 | AE25: VERDE | AF25: 0
B26: 21 | C26: RHEEM TRANSFERENCIA | D26: EZO / MIRIAM | E26: 82-104895-06 | F26: 0.5 | G26: 0.028 | J26: 0 | L26: 0 | P26: =+J26+K26+L26+M26+N26+O26-SUM(Q26:AA26) -> 0 | AB26: =+H26*SUM(J26:O26) -> 0 | AC26: 0 | AD26: 0 | AE26: VERDE | AF26: 0
B27: 22 | C27: RHEEM TRANSFERENCIA | D27: EZO / MIRIAM | E27: 82-104894-07 | F27: 0.5 | G27: 0.028 | J27: 0 | L27: 0 | P27: =+J27+K27+L27+M27+N27+O27-SUM(Q27:AA27) -> 0 | AB27: =+H27*SUM(J27:O27) -> 0 | AC27: 0 | AD27: 0 | AE27: VERDE | AF27: 0
B28: 23 | C28: RHEEM TRANSFERENCIA | D28: EZO / MIRIAM | E28: 82-100797-23 | F28: 0.5 | G28: 0.028 | J28: 0 | L28: 0 | P28: =+J28+K28+L28+M28+N28+O28-SUM(Q28:AA28) -> 0 | AB28: =+H28*SUM(J28:O28) -> 0 | AC28: 0 | AD28: 0 | AE28: VERDE | AF28: 0
B29: 24 | C29: RHEEM TRANSFERENCIA | D29: EZO / MIRIAM | E29: 82-104894-10 | F29: 0.5 | G29: 0.028 | J29: 0 | L29: 0 | P29: =+J29+K29+L29+M29+N29+O29-SUM(Q29:AA29) -> 0 | AB29: =+H29*SUM(J29:O29) -> 0 | AC29: 0 | AD29: 0 | AE29: VERDE | AF29: 0
B30: 25 | C30: RHEEM TRANSFERENCIA | D30: EZO / MIRIAM | E30: 82-104895-07 | F30: 0.5 | G30: 0.028 | J30: 0 | L30: 0 | P30: =+J30+K30+L30+M30+N30+O30-SUM(Q30:AA30) -> 0 | AB30: =+H30*SUM(J30:O30) -> 0 | AC30: 0 | AD30: 0 | AE30: VERDE | AF30: 0
B31: 26 | C31: RHEEM TRANSFERENCIA | D31: EZO / MIRIAM | E31: 82-104895-17 | F31: 0.5 | G31: 0.028 | J31: 0 | L31: 0 | P31: =+J31+K31+L31+M31+N31+O31-SUM(Q31:AA31) -> 0 | AB31: =+H31*SUM(J31:O31) -> 0 | AC31: 0 | AD31: 0 | AE31: VERDE | AF31: 0
B32: 27 | C32: RHEEM TRANSFERENCIA | D32: EZO / MIRIAM | E32: 82-104894-13 | F32: 0.5 | G32: 0.028 | J32: 0 | L32: 0 | P32: =+J32+K32+L32+M32+N32+O32-SUM(Q32:AA32) -> 0 | AB32: =+H32*SUM(J32:O32) -> 0 | AC32: 0 | AD32: 0 | AE32: VERDE | AF32: 0
B33: 28 | C33: RHEEM TRANSFERENCIA | D33: EZO / MIRIAM | E33: 82-104894-01 | F33: 0.5 | G33: 0.028 | J33: 0 | L33: 0 | P33: =+J33+K33+L33+M33+N33+O33-SUM(Q33:AA33) -> 0 | AB33: =+H33*SUM(J33:O33) -> 0 | AC33: 0 | AD33: 0 | AE33: VERDE | AF33: 0
... B35: 30 | C35: RHEEM TRANSFERENCIA | D35: EZO / MIRIAM | E35: 82-104894-09 | F35: 0.5 | G35: 0.028 | J35: 0 | L35: 0 | P35: =+J35+K35+L35+M35+N35+O35-SUM(Q35:AA35) -> 0 | AB35: =+H35*SUM(J35:O35) -> 0 | AC35: 0 | AD35: 0 | AE35: VERDE | AF35: 0
B36: 31 | C36: RHEEM TRANSFERENCIA | D36: EZO / MIRIAM | E36: 82-104984-140 | F36: 0.625 | G36: 0.035 | J36: 0 | L36: 0 | P36: =+J36+K36+L36+M36+N36+O36-SUM(Q36:AA36) -> 0 | AB36: =+H36*SUM(J36:O36) -> 0 | AC36: 44x41x12 | AD36: 200 | AE36: VERDE | AF36: =+SUM(J36:O36)/AD36 -> 0
B37: 32 | C37: RHEEM TRANSFERENCIA | D37: EZO / MIRIAM | E37: 82-104984-116 | F37: 0.625 | G37: 0.035 | J37: 0 | L37: 0 | P37: =+J37+K37+L37+M37+N37+O37-SUM(Q37:AA37) -> 0 | AB37: =+H37*SUM(J37:O37) -> 0 | AC37: 44x41x12 | AD37: 100 | AE37: VERDE | AF37: =+SUM(J37:O37)/AD37 -> 0
B38: 33 | C38: RHEEM TRANSFERENCIA | D38: EZO / MIRIAM | E38: 82-104984-142 | F38: 0.625 | G38: 0.035 | J38: 0 | L38: 0 | P38: =+J38+K38+L38+M38+N38+O38-SUM(Q38:AA38) -> 0 | AB38: =+H38*SUM(J38:O38) -> 0 | AC38: 44x41x12 | AD38: 100 | AE38: VERDE | AF38: =+SUM(J38:O38)/AD38 -> 0
B39: 34 | C39: RHEEM TRANSFERENCIA | D39: EZO / MIRIAM | E39: 82-104984-114 | F39: 0.75 | G39: 0.035 | J39: 0 | L39: 0 | P39: =+J39+K39+L39+M39+N39+O39-SUM(Q39:AA39) -> 0 | AB39: =+H39*SUM(J39:O39) -> 0 | AC39: 42X45X20 | AD39: 2000 | AE39: VERDE | AF39: =+SUM(J39:O39)/AD39 -> 0
B40: 35 | C40: RHEEM TRANSFERENCIA | D40: EZO / MIRIAM | E40: 82-104984-147 | F40: 0.75 | G40: 0.035 | J40: 0 | L40: 0 | P40: =+J40+K40+L40+M40+N40+O40-SUM(Q40:AA40) -> 0 | AB40: =+H40*SUM(J40:O40) -> 0 | AC40: 42X45X20 | AD40: 500 | AE40: VERDE | AF40: =+SUM(J40:O40)/AD40 -> 0
B41: 36 | C41: RHEEM TRANSFERENCIA | D41: EZO / MIRIAM | E41: 82-104984-122 | F41: 0.75 | G41: 0.035 | J41: 0 | L41: 0 | P41: =+J41+K41+L41+M41+N41+O41-SUM(Q41:AA41) -> 0 | AB41: =+H41*SUM(J41:O41) -> 0 | AC41: 42X45X20 | AD41: 250 | AE41: VERDE | AF41: =+SUM(J41:O41)/AD41 -> 0
B42: 37 | C42: RHEEM TRANSFERENCIA | D42: EZO / MIRIAM | E42: 82-104984-189 | F42: 0.75 | G42: 0.035 | J42: 0 | L42: 0 | P42: =+J42+K42+L42+M42+N42+O42-SUM(Q42:AA42) -> 0 | AB42: =+H42*SUM(J42:O42) -> 0 | AC42: 42X45X20 | AD42: 300 | AE42: VERDE | AF42: =+SUM(J42:O42)/AD42 -> 0
...

Sheet SEMANA 32
C2: DÍA | D2: TURNO
C3: =TODAY() -> 46308 | D3: A | E3: X | J3: PROGRAMA
D4: B | J4: SEMANA | K4: Convertirlo a horas | Q4: 46237 | S4: 46238 | U4: 46239 | W4: 46240 | Y4: 46241 | AA4: Ag1
C5: CLIENTE | D5: DESTINO | E5: NÚMERO DE PARTE | F5: DIAMETRO | G5: PARED | H5: PESO | I5: PRECIO | J5: 32 | K5: Ag1 | L5: Ag2 | M5: Ag3 | N5: Ag | O5: W31 | P5: BALANCE | Q5: A | R5: B | S5: A | T5: B | U5: A | V5: B | W5: A | X5: B | Y5: A | Z5: B | AA5: AYB | AB5: KG | AC5: CAJA | AD5: CANT. X CAJA | AE5: HOJA COLOR | AF5: TOTAL CAJAS | AH5: Row Labels | AI5: Sum of TOTAL CAJAS
B6: 1 | C6: RHEEM TRANSFERENCIA | D6: EZO / MIRIAM | E6: 82-104987-15 | F6: 0.25 | G6: 0.028 | P6: =+J6+K6+L6+M6+N6+O6-SUM(Q6:AA6) -> -3362 | W6: 3362 | AB6: =+H6*SUM(J6:O6) -> 0 | AC6: 12.5X12.5X12.5 | AD6: 150 | AE6: VERDE | AF6: =+SUM(J6:O6)/AD6 -> 0 | AH6: 0 | AI6: 0
B7: 2 | C7: RHEEM TRANSFERENCIA | D7: EZO / MIRIAM | E7: 82-104987-13 | F7: 0.25 | G7: 0.028 | P7: =+J7+K7+L7+M7+N7+O7-SUM(Q7:AA7) -> -2265 | W7: 1990 | Z7: 275 | AB7: =+H7*SUM(J7:O7) -> 0 | AC7: 12.5X12.5X12.5 | AD7: 200 | AE7: VERDE | AF7: =+SUM(J7:O7)/AD7 -> 0 | AH7: 12.5X12.5X12.5 | AI7: 52
B8: 3 | C8: RHEEM TRANSFERENCIA | D8: EZO / MIRIAM | E8: 82-104987-14 | F8: 0.25 | G8: 0.028 | P8: =+J8+K8+L8+M8+N8+O8-SUM(Q8:AA8) -> -2250 | Y8: 2250 | AB8: =+H8*SUM(J8:O8) -> 0 | AC8: 12.5X12.5X12.5 | AD8: 200 | AE8: VERDE | AF8: =+SUM(J8:O8)/AD8 -> 0 | AH8: 25x20x12.5 | AI8: 0
B9: 4 | C9: RHEEM TRANSFERENCIA | D9: EZO / MIRIAM | E9: 82-104986-88 | F9: 0.375 | G9: 0.028 | P9: =+J9+K9+L9+M9+N9+O9-SUM(Q9:AA9) -> -1308 | Y9: 900 | Z9: 408 | AB9: =+H9*SUM(J9:O9) -> 0 | AC9: 12.5X12.5X12.5 | AD9: 100 | AE9: VERDE | AF9: =+SUM(J9:O9)/AD9 -> 0 | AH9: 30X20X7 | AI9: 116
B10: 5 | C10: RHEEM TRANSFERENCIA | D10: EZO / MIRIAM | E10: 82-104986-61 | F10: 0.375 | G10: 0.028 | P10: =+J10+K10+L10+M10+N10+O10-SUM(Q10:AA10) -> -1930 | X10: 1669 | Y10: 261 | AB10: =+H10*SUM(J10:O10) -> 0 | AC10: 12.5X12.5X12.5 | AD10: 150 | AE10: VERDE | AF10: =+SUM(J10:O10)/AD10 -> 0 | AH10: 42X45X20 | AI10: 2
B11: 6 | C11: RHEEM TRANSFERENCIA | D11: EZO / MIRIAM | E11: 82-104986-59 | F11: 0.375 | G11: 0.028 | P11: =+J11+K11+L11+M11+N11+O11-SUM(Q11:AA11) -> -1497 | W11: 750 | X11: 747 | AB11: =+H11*SUM(J11:O11) -> 0 | AC11: 12.5X12.5X12.5 | AD11: 150 | AE11: VERDE | AF11: =+SUM(J11:O11)/AD11 -> 0 | AH11: 44x41x12 | AI11: 10
B12: 7 | C12: RHEEM TRANSFERENCIA | D12: EZO / MIRIAM | E12: 82-104986-72 | F12: 0.375 | G12: 0.028 | P12: =+J12+K12+L12+M12+N12+O12-SUM(Q12:AA12) -> -900 | X12: 900 | AB12: =+H12*SUM(J12:O12) -> 0 | AC12: 12.5X12.5X12.5 | AD12: 50 | AE12: VERDE | AF12: =+SUM(J12:O12)/AD12 -> 0 | AH12: Grand Total | AI12: 180
B13: 8 | C13: RHEEM TRANSFERENCIA | D13: EZO / MIRIAM | E13: 82-104986-89 | F13: 0.375 | G13: 0.028 | P13: =+J13+K13+L13+M13+N13+O13-SUM(Q13:AA13) -> -800 | Y13: 800 | AB13: =+H13*SUM(J13:O13) -> 0 | AC13: 12.5X12.5X12.5 | AD13: 100 | AE13: VERDE | AF13: =+SUM(J13:O13)/AD13 -> 0
B14: 9 | C14: RHEEM TRANSFERENCIA | D14: EZO / MIRIAM | E14: 82-104986-71 | F14: 0.375 | G14: 0.028 | P14: =+J14+K14+L14+M14+N14+O14-SUM(Q14:AA14) -> -100 | X14: 100 | AB14: =+H14*SUM(J14:O14) -> 0 | AC14: 12.5X12.5X12.5 | AD14: 50 | AE14: VERDE | AF14: =+SUM(J14:O14)/AD14 -> 0
B15: 10 | C15: RHEEM TRANSFERENCIA | D15: EZO / MIRIAM | E15: 82-104986-60 | F15: 0.375 | G15: 0.028 | P15: =+J15+K15+L15+M15+N15+O15-SUM(Q15:AA15) -> 0 | AB15: =+H15*SUM(J15:O15) -> 0 | AC15: 30X20X7 | AD15: 60 | AE15: VERDE | AF15: =+SUM(J15:O15)/AD15 -> 0
B16: 11 | C16: RHEEM TRANSFERENCIA | D16: EZO / MIRIAM | E16: 82-104985-41 | F16: 0.5 | G16: 0.028 | P16: =+J16+K16+L16+M16+N16+O16-SUM(Q16:AA16) -> -3542 | V16: 600 | W16: 928 | X16: 1322 | Y16: 692 | AB16: =+H16*SUM(J16:O16) -> 0 | AC16: 12.5x12.5x12.5 | AD16: 100 | AE16: VERDE | AF16: =+SUM(J16:O16)/AD16 -> 0
